{
  "version": 8,
  "blockIdVersion": 11,
  "anchorX": 0,
  "anchorY": 0,
  "anchorZ": 0,
  "blocks": [
    {
      "x": -11,
      "y": 14,
      "z": -3,
      "name": "Soil_Grass"
    },
    {
      "x": -11,
      "y": 14,
      "z": -2,
      "name": "Soil_Grass"
    },
    {
      "x": -11,
      "y": 14,
      "z": -1,
      "name": "Soil_Grass"
    },
    {
      "x": -11,
      "y": 14,
      "z": 0,
      "name": "Soil_Grass"
    },
    {
      "x": -11,
      "y": 13,
      "z": 1,
      "name": "Plant_Vine",
      "support": 15,
      "rotation": 3
    },
    {
      "x": -11,
      "y": 14,
      "z": 1,
      "name": "Soil_Grass"
    },
    {
      "x": -11,
      "y": 13,
      "z": 2,
      "name": "Plant_Vine",
      "support": 15,
      "rotation": 3
    },
    {
      "x": -11,
      "y": 14,
      "z": 2,
      "name": "Soil_Grass"
    },
    {
      "x": -11,
      "y": 14,
      "z": 3,
      "name": "Soil_Grass"
    },
    {
      "x": -11,
      "y": 14,
      "z": 4,
      "name": "Soil_Grass"
    },
    {
      "x": -11,
      "y": 14,
      "z": 5,
      "name": "Soil_Grass"
    },
    {
      "x": -11,
      "y": 14,
      "z": 6,
      "name": "Soil_Grass"
    },
    {
      "x": -11,
      "y": 14,
      "z": 7,
      "name": "Soil_Grass"
    },
    {
      "x": -11,
      "y": 14,
      "z": 8,
      "name": "Soil_Grass"
    },
    {
      "x": -11,
      "y": 14,
      "z": 9,
      "name": "Soil_Grass"
    },
    {
      "x": -11,
      "y": 14,
      "z": 10,
      "name": "Soil_Grass"
    },
    {
      "x": -10,
      "y": 14,
      "z": -4,
      "name": "Soil_Grass"
    },
    {
      "x": -10,
      "y": 14,
      "z": -3,
      "name": "Soil_Grass"
    },
    {
      "x": -10,
      "y": 14,
      "z": -2,
      "name": "Soil_Grass"
    },
    {
      "x": -10,
      "y": 14,
      "z": -1,
      "name": "Soil_Grass"
    },
    {
      "x": -10,
      "y": 12,
      "z": 0,
      "name": "Plant_Vine",
      "support": 15,
      "rotation": 3
    },
    {
      "x": -10,
      "y": 13,
      "z": 0,
      "name": "Soil_Dirt"
    },
    {
      "x": -10,
      "y": 14,
      "z": 0,
      "name": "Soil_Grass"
    },
    {
      "x": -10,
      "y": 15,
      "z": 0,
      "name": "Plant_Grass_Sharp_Tall",
      "support": 15
    },
    {
      "x": -10,
      "y": 16,
      "z": 0,
      "name": "Plant_Grass_Sharp_Tall",
      "filler": 1024
    },
    {
      "x": -10,
      "y": 12,
      "z": 1,
      "name": "Plant_Vine",
      "support": 15,
      "rotation": 3
    },
    {
      "x": -10,
      "y": 13,
      "z": 1,
      "name": "Soil_Dirt"
    },
    {
      "x": -10,
      "y": 14,
      "z": 1,
      "name": "Soil_Grass"
    },
    {
      "x": -10,
      "y": 12,
      "z": 2,
      "name": "Plant_Vine",
      "support": 15,
      "rotation": 3
    },
    {
      "x": -10,
      "y": 13,
      "z": 2,
      "name": "Soil_Dirt"
    },
    {
      "x": -10,
      "y": 14,
      "z": 2,
      "name": "Soil_Grass"
    },
    {
      "x": -10,
      "y": 15,
      "z": 2,
      "name": "Plant_Grass_Sharp_Wild",
      "support": 15
    },
    {
      "x": -10,
      "y": 16,
      "z": 2,
      "name": "Plant_Grass_Sharp_Wild",
      "filler": 1024
    },
    {
      "x": -10,
      "y": 13,
      "z": 3,
      "name": "Soil_Dirt"
    },
    {
      "x": -10,
      "y": 14,
      "z": 3,
      "name": "Soil_Grass"
    },
    {
      "x": -10,
      "y": 15,
      "z": 3,
      "name": "Plant_Grass_Sharp",
      "support": 15
    },
    {
      "x": -10,
      "y": 13,
      "z": 4,
      "name": "Soil_Dirt"
    },
    {
      "x": -10,
      "y": 14,
      "z": 4,
      "name": "Soil_Grass"
    },
    {
      "x": -10,
      "y": 13,
      "z": 5,
      "name": "Soil_Dirt"
    },
    {
      "x": -10,
      "y": 14,
      "z": 5,
      "name": "Soil_Grass"
    },
    {
      "x": -10,
      "y": 13,
      "z": 6,
      "name": "Soil_Dirt"
    },
    {
      "x": -10,
      "y": 14,
      "z": 6,
      "name": "Soil_Grass"
    },
    {
      "x": -10,
      "y": 15,
      "z": 6,
      "name": "Plant_Grass_Sharp_Tall",
      "support": 15
    },
    {
      "x": -10,
      "y": 16,
      "z": 6,
      "name": "Plant_Grass_Sharp_Tall",
      "filler": 1024
    },
    {
      "x": -10,
      "y": 13,
      "z": 7,
      "name": "Soil_Dirt"
    },
    {
      "x": -10,
      "y": 14,
      "z": 7,
      "name": "Soil_Grass"
    },
    {
      "x": -10,
      "y": 13,
      "z": 8,
      "name": "Soil_Dirt"
    },
    {
      "x": -10,
      "y": 14,
      "z": 8,
      "name": "Soil_Grass"
    },
    {
      "x": -10,
      "y": 15,
      "z": 8,
      "name": "Plant_Grass_Sharp_Wild",
      "support": 15
    },
    {
      "x": -10,
      "y": 16,
      "z": 8,
      "name": "Plant_Grass_Sharp_Wild",
      "filler": 1024
    },
    {
      "x": -10,
      "y": 13,
      "z": 9,
      "name": "Soil_Dirt"
    },
    {
      "x": -10,
      "y": 14,
      "z": 9,
      "name": "Soil_Grass"
    },
    {
      "x": -10,
      "y": 14,
      "z": 10,
      "name": "Soil_Grass"
    },
    {
      "x": -10,
      "y": 23,
      "z": 10,
      "name": "Plant_Leaves_Oak"
    },
    {
      "x": -10,
      "y": 24,
      "z": 10,
      "name": "Plant_Leaves_Oak"
    },
    {
      "x": -10,
      "y": 25,
      "z": 10,
      "name": "Plant_Leaves_Oak"
    },
    {
      "x": -10,
      "y": 14,
      "z": 11,
      "name": "Soil_Grass"
    },
    {
      "x": -9,
      "y": 14,
      "z": -6,
      "name": "Soil_Grass"
    },
    {
      "x": -9,
      "y": 14,
      "z": -5,
      "name": "Soil_Grass"
    },
    {
      "x": -9,
      "y": 14,
      "z": -4,
      "name": "Soil_Grass"
    },
    {
      "x": -9,
      "y": 14,
      "z": -3,
      "name": "Soil_Grass"
    },
    {
      "x": -9,
      "y": 15,
      "z": -3,
      "name": "Plant_Grass_Sharp_Wild",
      "support": 15
    },
    {
      "x": -9,
      "y": 16,
      "z": -3,
      "name": "Plant_Grass_Sharp_Wild",
      "filler": 1024
    },
    {
      "x": -9,
      "y": 13,
      "z": -2,
      "name": "Soil_Dirt"
    },
    {
      "x": -9,
      "y": 14,
      "z": -2,
      "name": "Soil_Grass"
    },
    {
      "x": -9,
      "y": 12,
      "z": -1,
      "name": "Plant_Vine",
      "support": 15,
      "rotation": 2
    },
    {
      "x": -9,
      "y": 13,
      "z": -1,
      "name": "Soil_Dirt"
    },
    {
      "x": -9,
      "y": 14,
      "z": -1,
      "name": "Soil_Grass"
    },
    {
      "x": -9,
      "y": 15,
      "z": -1,
      "name": "Plant_Grass_Sharp",
      "support": 15
    },
    {
      "x": -9,
      "y": 11,
      "z": 0,
      "name": "Plant_Vine",
      "support": 15,
      "rotation": 3
    },
    {
      "x": -9,
      "y": 12,
      "z": 0,
      "name": "Rock_Stone"
    },
    {
      "x": -9,
      "y": 13,
      "z": 0,
      "name": "Soil_Dirt"
    },
    {
      "x": -9,
      "y": 14,
      "z": 0,
      "name": "Soil_Grass"
    },
    {
      "x": -9,
      "y": 11,
      "z": 1,
      "name": "Rock_Stone_Stalactite_Small",
      "rotation": 8
    },
    {
      "x": -9,
      "y": 12,
      "z": 1,
      "name": "Rock_Stone"
    },
    {
      "x": -9,
      "y": 13,
      "z": 1,
      "name": "Soil_Dirt"
    },
    {
      "x": -9,
      "y": 14,
      "z": 1,
      "name": "Soil_Grass"
    },
    {
      "x": -9,
      "y": 11,
      "z": 2,
      "name": "Plant_Vine",
      "support": 15,
      "rotation": 3
    },
    {
      "x": -9,
      "y": 12,
      "z": 2,
      "name": "Rock_Stone"
    },
    {
      "x": -9,
      "y": 13,
      "z": 2,
      "name": "Soil_Dirt"
    },
    {
      "x": -9,
      "y": 14,
      "z": 2,
      "name": "Soil_Grass"
    },
    {
      "x": -9,
      "y": 11,
      "z": 3,
      "name": "Plant_Vine",
      "support": 15,
      "rotation": 3
    },
    {
      "x": -9,
      "y": 12,
      "z": 3,
      "name": "Rock_Stone"
    },
    {
      "x": -9,
      "y": 13,
      "z": 3,
      "name": "Soil_Dirt"
    },
    {
      "x": -9,
      "y": 14,
      "z": 3,
      "name": "Soil_Grass"
    },
    {
      "x": -9,
      "y": 12,
      "z": 4,
      "name": "Rock_Stone"
    },
    {
      "x": -9,
      "y": 13,
      "z": 4,
      "name": "Soil_Dirt"
    },
    {
      "x": -9,
      "y": 14,
      "z": 4,
      "name": "Soil_Grass"
    },
    {
      "x": -9,
      "y": 11,
      "z": 5,
      "name": "Plant_Moss_Wall_Green",
      "support": 15,
      "rotation": 3
    },
    {
      "x": -9,
      "y": 12,
      "z": 5,
      "name": "Rock_Stone"
    },
    {
      "x": -9,
      "y": 13,
      "z": 5,
      "name": "Soil_Dirt"
    },
    {
      "x": -9,
      "y": 14,
      "z": 5,
      "name": "Soil_Grass"
    },
    {
      "x": -9,
      "y": 12,
      "z": 6,
      "name": "Rock_Stone_Mossy"
    },
    {
      "x": -9,
      "y": 13,
      "z": 6,
      "name": "Soil_Dirt"
    },
    {
      "x": -9,
      "y": 14,
      "z": 6,
      "name": "Soil_Grass"
    },
    {
      "x": -9,
      "y": 12,
      "z": 7,
      "name": "Rock_Stone_Mossy"
    },
    {
      "x": -9,
      "y": 13,
      "z": 7,
      "name": "Soil_Dirt"
    },
    {
      "x": -9,
      "y": 14,
      "z": 7,
      "name": "Soil_Grass"
    },
    {
      "x": -9,
      "y": 13,
      "z": 8,
      "name": "Soil_Dirt"
    },
    {
      "x": -9,
      "y": 14,
      "z": 8,
      "name": "Soil_Grass"
    },
    {
      "x": -9,
      "y": 12,
      "z": 9,
      "name": "Plant_Moss_Wall_Green",
      "support": 15,
      "rotation": 3
    },
    {
      "x": -9,
      "y": 13,
      "z": 9,
      "name": "Soil_Dirt"
    },
    {
      "x": -9,
      "y": 14,
      "z": 9,
      "name": "Soil_Grass"
    },
    {
      "x": -9,
      "y": 15,
      "z": 9,
      "name": "Plant_Grass_Sharp",
      "support": 15
    },
    {
      "x": -9,
      "y": 23,
      "z": 9,
      "name": "Plant_Leaves_Oak"
    },
    {
      "x": -9,
      "y": 13,
      "z": 10,
      "name": "Soil_Dirt"
    },
    {
      "x": -9,
      "y": 14,
      "z": 10,
      "name": "Soil_Grass"
    },
    {
      "x": -9,
      "y": 22,
      "z": 10,
      "name": "Plant_Leaves_Oak"
    },
    {
      "x": -9,
      "y": 24,
      "z": 10,
      "name": "Plant_Leaves_Oak"
    },
    {
      "x": -9,
      "y": 25,
      "z": 10,
      "name": "Plant_Leaves_Oak"
    },
    {
      "x": -9,
      "y": 26,
      "z": 10,
      "name": "Plant_Leaves_Oak"
    },
    {
      "x": -9,
      "y": 14,
      "z": 11,
      "name": "Soil_Grass"
    },
    {
      "x": -9,
      "y": 23,
      "z": 11,
      "name": "Plant_Leaves_Oak"
    },
    {
      "x": -9,
      "y": 24,
      "z": 11,
      "name": "Plant_Leaves_Oak"
    },
    {
      "x": -9,
      "y": 25,
      "z": 11,
      "name": "Plant_Leaves_Oak"
    },
    {
      "x": -9,
      "y": 13,
      "z": 12,
      "name": "Plant_Vine_Wall",
      "support": 15,
      "rotation": 3
    },
    {
      "x": -9,
      "y": 14,
      "z": 12,
      "name": "Soil_Grass"
    },
    {
      "x": -8,
      "y": 14,
      "z": -7,
      "name": "Soil_Grass"
    },
    {
      "x": -8,
      "y": 14,
      "z": -6,
      "name": "Soil_Grass"
    },
    {
      "x": -8,
      "y": 14,
      "z": -5,
      "name": "Soil_Grass"
    },
    {
      "x": -8,
      "y": 15,
      "z": -5,
      "name": "Plant_Grass_Sharp",
      "support": 15
    },
    {
      "x": -8,
      "y": 13,
      "z": -4,
      "name": "Soil_Dirt"
    },
    {
      "x": -8,
      "y": 14,
      "z": -4,
      "name": "Soil_Grass"
    },
    {
      "x": -8,
      "y": 13,
      "z": -3,
      "name": "Soil_Dirt"
    },
    {
      "x": -8,
      "y": 14,
      "z": -3,
      "name": "Soil_Grass"
    },
    {
      "x": -8,
      "y": 15,
      "z": -3,
      "name": "Plant_Grass_Sharp_Tall",
      "support": 15
    },
    {
      "x": -8,
      "y": 16,
      "z": -3,
      "name": "Plant_Grass_Sharp_Tall",
      "filler": 1024
    },
    {
      "x": -8,
      "y": 12,
      "z": -2,
      "name": "Rock_Stone"
    },
    {
      "x": -8,
      "y": 13,
      "z": -2,
      "name": "Soil_Dirt"
    },
    {
      "x": -8,
      "y": 14,
      "z": -2,
      "name": "Soil_Grass"
    },
    {
      "x": -8,
      "y": 11,
      "z": -1,
      "name": "Plant_Vine",
      "support": 15,
      "rotation": 2
    },
    {
      "x": -8,
      "y": 12,
      "z": -1,
      "name": "Rock_Stone"
    },
    {
      "x": -8,
      "y": 13,
      "z": -1,
      "name": "Soil_Dirt"
    },
    {
      "x": -8,
      "y": 14,
      "z": -1,
      "name": "Soil_Grass"
    },
    {
      "x": -8,
      "y": 11,
      "z": 0,
      "name": "Rock_Stone"
    },
    {
      "x": -8,
      "y": 12,
      "z": 0,
      "name": "Rock_Stone"
    },
    {
      "x": -8,
      "y": 13,
      "z": 0,
      "name": "Soil_Dirt"
    },
    {
      "x": -8,
      "y": 14,
      "z": 0,
      "name": "Soil_Grass"
    },
    {
      "x": -8,
      "y": 10,
      "z": 1,
      "name": "Plant_Vine",
      "support": 15,
      "rotation": 3
    },
    {
      "x": -8,
      "y": 11,
      "z": 1,
      "name": "Rock_Stone"
    },
    {
      "x": -8,
      "y": 12,
      "z": 1,
      "name": "Rock_Stone"
    },
    {
      "x": -8,
      "y": 13,
      "z": 1,
      "name": "Soil_Dirt"
    },
    {
      "x": -8,
      "y": 14,
      "z": 1,
      "name": "Soil_Grass"
    },
    {
      "x": -8,
      "y": 10,
      "z": 2,
      "name": "Plant_Vine",
      "support": 15,
      "rotation": 3
    },
    {
      "x": -8,
      "y": 11,
      "z": 2,
      "name": "Rock_Stone"
    },
    {
      "x": -8,
      "y": 12,
      "z": 2,
      "name": "Rock_Stone"
    },
    {
      "x": -8,
      "y": 13,
      "z": 2,
      "name": "Soil_Dirt"
    },
    {
      "x": -8,
      "y": 14,
      "z": 2,
      "name": "Soil_Grass"
    },
    {
      "x": -8,
      "y": 15,
      "z": 2,
      "name": "Plant_Grass_Sharp_Tall",
      "support": 15
    },
    {
      "x": -8,
      "y": 16,
      "z": 2,
      "name": "Plant_Grass_Sharp_Tall",
      "filler": 1024
    },
    {
      "x": -8,
      "y": 11,
      "z": 3,
      "name": "Rock_Stone"
    },
    {
      "x": -8,
      "y": 12,
      "z": 3,
      "name": "Rock_Stone"
    },
    {
      "x": -8,
      "y": 13,
      "z": 3,
      "name": "Soil_Dirt"
    },
    {
      "x": -8,
      "y": 14,
      "z": 3,
      "name": "Soil_Grass"
    },
    {
      "x": -8,
      "y": 11,
      "z": 4,
      "name": "Rock_Stone"
    },
    {
      "x": -8,
      "y": 12,
      "z": 4,
      "name": "Rock_Stone"
    },
    {
      "x": -8,
      "y": 13,
      "z": 4,
      "name": "Soil_Dirt"
    },
    {
      "x": -8,
      "y": 14,
      "z": 4,
      "name": "Soil_Grass"
    },
    {
      "x": -8,
      "y": 11,
      "z": 5,
      "name": "Rock_Stone"
    },
    {
      "x": -8,
      "y": 12,
      "z": 5,
      "name": "Rock_Stone"
    },
    {
      "x": -8,
      "y": 13,
      "z": 5,
      "name": "Soil_Dirt"
    },
    {
      "x": -8,
      "y": 14,
      "z": 5,
      "name": "Soil_Grass"
    },
    {
      "x": -8,
      "y": 11,
      "z": 6,
      "name": "Rock_Stone_Mossy"
    },
    {
      "x": -8,
      "y": 12,
      "z": 6,
      "name": "Rock_Stone"
    },
    {
      "x": -8,
      "y": 13,
      "z": 6,
      "name": "Soil_Dirt"
    },
    {
      "x": -8,
      "y": 14,
      "z": 6,
      "name": "Soil_Grass"
    },
    {
      "x": -8,
      "y": 12,
      "z": 7,
      "name": "Rock_Stone_Mossy"
    },
    {
      "x": -8,
      "y": 13,
      "z": 7,
      "name": "Soil_Dirt"
    },
    {
      "x": -8,
      "y": 14,
      "z": 7,
      "name": "Soil_Grass"
    },
    {
      "x": -8,
      "y": 25,
      "z": 7,
      "name": "Plant_Leaves_Oak"
    },
    {
      "x": -8,
      "y": 11,
      "z": 8,
      "name": "Plant_Vine_Wall",
      "support": 15,
      "rotation": 3
    },
    {
      "x": -8,
      "y": 12,
      "z": 8,
      "name": "Rock_Stone"
    },
    {
      "x": -8,
      "y": 13,
      "z": 8,
      "name": "Soil_Dirt"
    },
    {
      "x": -8,
      "y": 14,
      "z": 8,
      "name": "Soil_Grass"
    },
    {
      "x": -8,
      "y": 23,
      "z": 8,
      "name": "Plant_Leaves_Oak"
    },
    {
      "x": -8,
      "y": 24,
      "z": 8,
      "name": "Plant_Leaves_Oak"
    },
    {
      "x": -8,
      "y": 25,
      "z": 8,
      "name": "Plant_Leaves_Oak"
    },
    {
      "x": -8,
      "y": 26,
      "z": 8,
      "name": "Plant_Leaves_Oak"
    },
    {
      "x": -8,
      "y": 12,
      "z": 9,
      "name": "Rock_Stone"
    },
    {
      "x": -8,
      "y": 13,
      "z": 9,
      "name": "Soil_Dirt"
    },
    {
      "x": -8,
      "y": 14,
      "z": 9,
      "name": "Soil_Grass"
    },
    {
      "x": -8,
      "y": 21,
      "z": 9,
      "name": "Plant_Leaves_Oak"
    },
    {
      "x": -8,
      "y": 22,
      "z": 9,
      "name": "Plant_Leaves_Oak"
    },
    {
      "x": -8,
      "y": 26,
      "z": 9,
      "name": "Plant_Leaves_Oak"
    },
    {
      "x": -8,
      "y": 12,
      "z": 10,
      "name": "Plant_Vine_Wall",
      "support": 15,
      "rotation": 3
    },
    {
      "x": -8,
      "y": 13,
      "z": 10,
      "name": "Soil_Dirt"
    },
    {
      "x": -8,
      "y": 14,
      "z": 10,
      "name": "Soil_Grass"
    },
    {
      "x": -8,
      "y": 21,
      "z": 10,
      "name": "Plant_Leaves_Oak"
    },
    {
      "x": -8,
      "y": 22,
      "z": 10,
      "name": "Plant_Leaves_Oak"
    },
    {
      "x": -8,
      "y": 24,
      "z": 10,
      "name": "Wood_Oak_Branch_Long",
      "rotation": 5
    },
    {
      "x": -8,
      "y": 27,
      "z": 10,
      "name": "Plant_Leaves_Oak"
    },
    {
      "x": -8,
      "y": 13,
      "z": 11,
      "name": "Soil_Dirt"
    },
    {
      "x": -8,
      "y": 14,
      "z": 11,
      "name": "Soil_Grass"
    },
    {
      "x": -8,
      "y": 15,
      "z": 11,
      "name": "Plant_Grass_Sharp",
      "support": 15
    },
    {
      "x": -8,
      "y": 22,
      "z": 11,
      "name": "Plant_Leaves_Oak"
    },
    {
      "x": -8,
      "y": 26,
      "z": 11,
      "name": "Plant_Leaves_Oak"
    },
    {
      "x": -8,
      "y": 13,
      "z": 12,
      "name": "Soil_Dirt"
    },
    {
      "x": -8,
      "y": 14,
      "z": 12,
      "name": "Soil_Grass"
    },
    {
      "x": -8,
      "y": 23,
      "z": 12,
      "name": "Plant_Leaves_Oak"
    },
    {
      "x": -8,
      "y": 24,
      "z": 12,
      "name": "Plant_Leaves_Oak"
    },
    {
      "x": -8,
      "y": 25,
      "z": 12,
      "name": "Plant_Leaves_Oak"
    },
    {
      "x": -8,
      "y": 14,
      "z": 13,
      "name": "Soil_Grass"
    },
    {
      "x": -7,
      "y": 14,
      "z": -7,
      "name": "Soil_Grass"
    },
    {
      "x": -7,
      "y": 14,
      "z": -6,
      "name": "Soil_Grass"
    },
    {
      "x": -7,
      "y": 13,
      "z": -5,
      "name": "Soil_Dirt"
    },
    {
      "x": -7,
      "y": 14,
      "z": -5,
      "name": "Soil_Grass"
    },
    {
      "x": -7,
      "y": 13,
      "z": -4,
      "name": "Soil_Dirt"
    },
    {
      "x": -7,
      "y": 14,
      "z": -4,
      "name": "Soil_Grass"
    },
    {
      "x": -7,
      "y": 13,
      "z": -3,
      "name": "Soil_Dirt"
    },
    {
      "x": -7,
      "y": 14,
      "z": -3,
      "name": "Soil_Grass"
    },
    {
      "x": -7,
      "y": 12,
      "z": -2,
      "name": "Rock_Stone"
    },
    {
      "x": -7,
      "y": 13,
      "z": -2,
      "name": "Soil_Dirt"
    },
    {
      "x": -7,
      "y": 14,
      "z": -2,
      "name": "Soil_Grass"
    },
    {
      "x": -7,
      "y": 11,
      "z": -1,
      "name": "Rock_Stone_Mossy"
    },
    {
      "x": -7,
      "y": 12,
      "z": -1,
      "name": "Rock_Stone"
    },
    {
      "x": -7,
      "y": 13,
      "z": -1,
      "name": "Soil_Dirt"
    },
    {
      "x": -7,
      "y": 14,
      "z": -1,
      "name": "Soil_Grass"
    },
    {
      "x": -7,
      "y": 10,
      "z": 0,
      "name": "Rock_Stone_Mossy"
    },
    {
      "x": -7,
      "y": 11,
      "z": 0,
      "name": "Rock_Stone"
    },
    {
      "x": -7,
      "y": 12,
      "z": 0,
      "name": "Rock_Stone"
    },
    {
      "x": -7,
      "y": 13,
      "z": 0,
      "name": "Soil_Dirt"
    },
    {
      "x": -7,
      "y": 14,
      "z": 0,
      "name": "Soil_Grass"
    },
    {
      "x": -7,
      "y": 15,
      "z": 0,
      "name": "Plant_Grass_Sharp",
      "support": 15
    },
    {
      "x": -7,
      "y": 9,
      "z": 1,
      "name": "Plant_Vine",
      "support": 15,
      "rotation": 3
    },
    {
      "x": -7,
      "y": 10,
      "z": 1,
      "name": "Rock_Stone"
    },
    {
      "x": -7,
      "y": 11,
      "z": 1,
      "name": "Rock_Stone"
    },
    {
      "x": -7,
      "y": 12,
      "z": 1,
      "name": "Rock_Stone"
    },
    {
      "x": -7,
      "y": 13,
      "z": 1,
      "name": "Soil_Dirt"
    },
    {
      "x": -7,
      "y": 14,
      "z": 1,
      "name": "Soil_Grass"
    },
    {
      "x": -7,
      "y": 10,
      "z": 2,
      "name": "Rock_Stone"
    },
    {
      "x": -7,
      "y": 11,
      "z": 2,
      "name": "Rock_Stone"
    },
    {
      "x": -7,
      "y": 12,
      "z": 2,
      "name": "Rock_Stone"
    },
    {
      "x": -7,
      "y": 13,
      "z": 2,
      "name": "Soil_Dirt"
    },
    {
      "x": -7,
      "y": 14,
      "z": 2,
      "name": "Soil_Grass"
    },
    {
      "x": -7,
      "y": 10,
      "z": 3,
      "name": "Rock_Stone"
    },
    {
      "x": -7,
      "y": 11,
      "z": 3,
      "name": "Rock_Stone"
    },
    {
      "x": -7,
      "y": 12,
      "z": 3,
      "name": "Rock_Stone"
    },
    {
      "x": -7,
      "y": 13,
      "z": 3,
      "name": "Soil_Dirt"
    },
    {
      "x": -7,
      "y": 14,
      "z": 3,
      "name": "Soil_Grass"
    },
    {
      "x": -7,
      "y": 9,
      "z": 4,
      "name": "Plant_Vine_Wall",
      "support": 15,
      "rotation": 3
    },
    {
      "x": -7,
      "y": 10,
      "z": 4,
      "name": "Rock_Stone"
    },
    {
      "x": -7,
      "y": 11,
      "z": 4,
      "name": "Rock_Stone"
    },
    {
      "x": -7,
      "y": 12,
      "z": 4,
      "name": "Rock_Stone"
    },
    {
      "x": -7,
      "y": 13,
      "z": 4,
      "name": "Soil_Dirt"
    },
    {
      "x": -7,
      "y": 14,
      "z": 4,
      "name": "Soil_Grass"
    },
    {
      "x": -7,
      "y": 15,
      "z": 4,
      "name": "Plant_Grass_Sharp",
      "support": 15
    },
    {
      "x": -7,
      "y": 10,
      "z": 5,
      "name": "Rock_Stone"
    },
    {
      "x": -7,
      "y": 11,
      "z": 5,
      "name": "Rock_Stone"
    },
    {
      "x": -7,
      "y": 12,
      "z": 5,
      "name": "Rock_Stone"
    },
    {
      "x": -7,
      "y": 13,
      "z": 5,
      "name": "Soil_Dirt"
    },
    {
      "x": -7,
      "y": 14,
      "z": 5,
      "name": "Soil_Grass"
    },
    {
      "x": -7,
      "y": 10,
      "z": 6,
      "name": "Rock_Stone_Mossy"
    },
    {
      "x": -7,
      "y": 11,
      "z": 6,
      "name": "Rock_Stone"
    },
    {
      "x": -7,
      "y": 12,
      "z": 6,
      "name": "Rock_Stone"
    },
    {
      "x": -7,
      "y": 13,
      "z": 6,
      "name": "Soil_Dirt"
    },
    {
      "x": -7,
      "y": 14,
      "z": 6,
      "name": "Soil_Grass"
    },
    {
      "x": -7,
      "y": 24,
      "z": 6,
      "name": "Plant_Leaves_Oak"
    },
    {
      "x": -7,
      "y": 25,
      "z": 6,
      "name": "Plant_Leaves_Oak"
    },
    {
      "x": -7,
      "y": 11,
      "z": 7,
      "name": "Rock_Stone_Mossy"
    },
    {
      "x": -7,
      "y": 12,
      "z": 7,
      "name": "Rock_Stone"
    },
    {
      "x": -7,
      "y": 13,
      "z": 7,
      "name": "Soil_Dirt"
    },
    {
      "x": -7,
      "y": 14,
      "z": 7,
      "name": "Soil_Grass"
    },
    {
      "x": -7,
      "y": 15,
      "z": 7,
      "name": "Plant_Grass_Sharp",
      "support": 15
    },
    {
      "x": -7,
      "y": 23,
      "z": 7,
      "name": "Plant_Leaves_Oak"
    },
    {
      "x": -7,
      "y": 24,
      "z": 7,
      "name": "Plant_Leaves_Oak"
    },
    {
      "x": -7,
      "y": 25,
      "z": 7,
      "name": "Plant_Leaves_Oak"
    },
    {
      "x": -7,
      "y": 26,
      "z": 7,
      "name": "Plant_Leaves_Oak"
    },
    {
      "x": -7,
      "y": 9,
      "z": 8,
      "name": "Rock_Stone_Stalactite_Large",
      "filler": 31744,
      "rotation": 8
    },
    {
      "x": -7,
      "y": 10,
      "z": 8,
      "name": "Rock_Stone_Stalactite_Large",
      "rotation": 8
    },
    {
      "x": -7,
      "y": 11,
      "z": 8,
      "name": "Rock_Stone"
    },
    {
      "x": -7,
      "y": 12,
      "z": 8,
      "name": "Rock_Stone"
    },
    {
      "x": -7,
      "y": 13,
      "z": 8,
      "name": "Soil_Dirt"
    },
    {
      "x": -7,
      "y": 14,
      "z": 8,
      "name": "Soil_Grass"
    },
    {
      "x": -7,
      "y": 22,
      "z": 8,
      "name": "Plant_Leaves_Oak"
    },
    {
      "x": -7,
      "y": 23,
      "z": 8,
      "name": "Plant_Leaves_Oak"
    },
    {
      "x": -7,
      "y": 27,
      "z": 8,
      "name": "Plant_Leaves_Oak"
    },
    {
      "x": -7,
      "y": 28,
      "z": 8,
      "name": "Plant_Leaves_Oak"
    },
    {
      "x": -7,
      "y": 12,
      "z": 9,
      "name": "Rock_Stone"
    },
    {
      "x": -7,
      "y": 13,
      "z": 9,
      "name": "Soil_Dirt"
    },
    {
      "x": -7,
      "y": 14,
      "z": 9,
      "name": "Soil_Grass"
    },
    {
      "x": -7,
      "y": 15,
      "z": 9,
      "name": "Plant_Grass_Sharp_Tall",
      "support": 15
    },
    {
      "x": -7,
      "y": 16,
      "z": 9,
      "name": "Plant_Grass_Sharp_Tall",
      "filler": 1024
    },
    {
      "x": -7,
      "y": 27,
      "z": 9,
      "name": "Plant_Leaves_Oak"
    },
    {
      "x": -7,
      "y": 28,
      "z": 9,
      "name": "Plant_Leaves_Oak"
    },
    {
      "x": -7,
      "y": 12,
      "z": 10,
      "name": "Rock_Stone"
    },
    {
      "x": -7,
      "y": 13,
      "z": 10,
      "name": "Soil_Dirt"
    },
    {
      "x": -7,
      "y": 14,
      "z": 10,
      "name": "Soil_Grass"
    },
    {
      "x": -7,
      "y": 15,
      "z": 10,
      "name": "Plant_Grass_Sharp_Tall",
      "support": 15
    },
    {
      "x": -7,
      "y": 16,
      "z": 10,
      "name": "Plant_Grass_Sharp_Tall",
      "filler": 1024
    },
    {
      "x": -7,
      "y": 21,
      "z": 10,
      "name": "Wood_Oak_Branch_Long",
      "rotation": 5
    },
    {
      "x": -7,
      "y": 24,
      "z": 10,
      "name": "Wood_Oak_Trunk_Full"
    },
    {
      "x": -7,
      "y": 26,
      "z": 10,
      "name": "Plant_Leaves_Oak"
    },
    {
      "x": -7,
      "y": 27,
      "z": 10,
      "name": "Plant_Leaves_Oak"
    },
    {
      "x": -7,
      "y": 12,
      "z": 11,
      "name": "Rock_Stone"
    },
    {
      "x": -7,
      "y": 13,
      "z": 11,
      "name": "Soil_Dirt"
    },
    {
      "x": -7,
      "y": 14,
      "z": 11,
      "name": "Wood_Oak_Trunk_Full"
    },
    {
      "x": -7,
      "y": 27,
      "z": 11,
      "name": "Plant_Leaves_Oak"
    },
    {
      "x": -7,
      "y": 28,
      "z": 11,
      "name": "Plant_Leaves_Oak"
    },
    {
      "x": -7,
      "y": 12,
      "z": 12,
      "name": "Rock_Stone"
    },
    {
      "x": -7,
      "y": 13,
      "z": 12,
      "name": "Soil_Dirt"
    },
    {
      "x": -7,
      "y": 14,
      "z": 12,
      "name": "Soil_Grass"
    },
    {
      "x": -7,
      "y": 15,
      "z": 12,
      "name": "Plant_Grass_Sharp_Wild",
      "support": 15
    },
    {
      "x": -7,
      "y": 16,
      "z": 12,
      "name": "Plant_Grass_Sharp_Wild",
      "filler": 1024
    },
    {
      "x": -7,
      "y": 21,
      "z": 12,
      "name": "Plant_Leaves_Oak"
    },
    {
      "x": -7,
      "y": 22,
      "z": 12,
      "name": "Plant_Leaves_Oak"
    },
    {
      "x": -7,
      "y": 26,
      "z": 12,
      "name": "Plant_Leaves_Oak"
    },
    {
      "x": -7,
      "y": 27,
      "z": 12,
      "name": "Plant_Leaves_Oak"
    },
    {
      "x": -7,
      "y": 13,
      "z": 13,
      "name": "Soil_Dirt"
    },
    {
      "x": -7,
      "y": 14,
      "z": 13,
      "name": "Soil_Grass"
    },
    {
      "x": -7,
      "y": 23,
      "z": 13,
      "name": "Plant_Leaves_Oak"
    },
    {
      "x": -7,
      "y": 24,
      "z": 13,
      "name": "Plant_Leaves_Oak"
    },
    {
      "x": -7,
      "y": 26,
      "z": 13,
      "name": "Plant_Leaves_Oak"
    },
    {
      "x": -7,
      "y": 13,
      "z": 14,
      "name": "Plant_Vine_Wall",
      "support": 15
    },
    {
      "x": -7,
      "y": 14,
      "z": 14,
      "name": "Soil_Grass"
    },
    {
      "x": -6,
      "y": 14,
      "z": -8,
      "name": "Soil_Grass"
    },
    {
      "x": -6,
      "y": 14,
      "z": -7,
      "name": "Soil_Grass"
    },
    {
      "x": -6,
      "y": 13,
      "z": -6,
      "name": "Soil_Dirt"
    },
    {
      "x": -6,
      "y": 14,
      "z": -6,
      "name": "Soil_Grass"
    },
    {
      "x": -6,
      "y": 13,
      "z": -5,
      "name": "Soil_Dirt"
    },
    {
      "x": -6,
      "y": 14,
      "z": -5,
      "name": "Soil_Grass"
    },
    {
      "x": -6,
      "y": 15,
      "z": -5,
      "name": "Plant_Grass_Sharp_Wild",
      "support": 15
    },
    {
      "x": -6,
      "y": 16,
      "z": -5,
      "name": "Plant_Grass_Sharp_Wild",
      "filler": 1024
    },
    {
      "x": -6,
      "y": 13,
      "z": -4,
      "name": "Soil_Dirt"
    },
    {
      "x": -6,
      "y": 14,
      "z": -4,
      "name": "Soil_Grass"
    },
    {
      "x": -6,
      "y": 15,
      "z": -4,
      "name": "Plant_Grass_Sharp",
      "support": 15
    },
    {
      "x": -6,
      "y": 12,
      "z": -3,
      "name": "Rock_Stone"
    },
    {
      "x": -6,
      "y": 13,
      "z": -3,
      "name": "Soil_Dirt"
    },
    {
      "x": -6,
      "y": 14,
      "z": -3,
      "name": "Soil_Grass"
    },
    {
      "x": -6,
      "y": 10,
      "z": -2,
      "name": "Plant_Vine_Wall",
      "support": 15,
      "rotation": 2
    },
    {
      "x": -6,
      "y": 11,
      "z": -2,
      "name": "Rock_Stone"
    },
    {
      "x": -6,
      "y": 12,
      "z": -2,
      "name": "Rock_Stone"
    },
    {
      "x": -6,
      "y": 13,
      "z": -2,
      "name": "Soil_Dirt"
    },
    {
      "x": -6,
      "y": 14,
      "z": -2,
      "name": "Soil_Grass"
    },
    {
      "x": -6,
      "y": 10,
      "z": -1,
      "name": "Rock_Stone_Mossy"
    },
    {
      "x": -6,
      "y": 11,
      "z": -1,
      "name": "Rock_Stone"
    },
    {
      "x": -6,
      "y": 12,
      "z": -1,
      "name": "Rock_Stone"
    },
    {
      "x": -6,
      "y": 13,
      "z": -1,
      "name": "Soil_Dirt"
    },
    {
      "x": -6,
      "y": 14,
      "z": -1,
      "name": "Soil_Grass"
    },
    {
      "x": -6,
      "y": 15,
      "z": -1,
      "name": "Plant_Grass_Sharp_Tall",
      "support": 15
    },
    {
      "x": -6,
      "y": 16,
      "z": -1,
      "name": "Plant_Grass_Sharp_Tall",
      "filler": 1024
    },
    {
      "x": -6,
      "y": 7,
      "z": 0,
      "name": "Plant_Moss_Wall_Green",
      "support": 15,
      "rotation": 3
    },
    {
      "x": -6,
      "y": 10,
      "z": 0,
      "name": "Rock_Stone_Mossy"
    },
    {
      "x": -6,
      "y": 11,
      "z": 0,
      "name": "Rock_Stone"
    },
    {
      "x": -6,
      "y": 12,
      "z": 0,
      "name": "Rock_Stone"
    },
    {
      "x": -6,
      "y": 13,
      "z": 0,
      "name": "Soil_Dirt"
    },
    {
      "x": -6,
      "y": 14,
      "z": 0,
      "name": "Soil_Grass"
    },
    {
      "x": -6,
      "y": 9,
      "z": 1,
      "name": "Rock_Stone"
    },
    {
      "x": -6,
      "y": 10,
      "z": 1,
      "name": "Rock_Stone"
    },
    {
      "x": -6,
      "y": 11,
      "z": 1,
      "name": "Rock_Stone"
    },
    {
      "x": -6,
      "y": 12,
      "z": 1,
      "name": "Rock_Stone"
    },
    {
      "x": -6,
      "y": 13,
      "z": 1,
      "name": "Soil_Dirt"
    },
    {
      "x": -6,
      "y": 14,
      "z": 1,
      "name": "Soil_Grass"
    },
    {
      "x": -6,
      "y": 6,
      "z": 2,
      "name": "Plant_Vine_Wall",
      "support": 15,
      "rotation": 3
    },
    {
      "x": -6,
      "y": 9,
      "z": 2,
      "name": "Rock_Stone"
    },
    {
      "x": -6,
      "y": 10,
      "z": 2,
      "name": "Rock_Stone"
    },
    {
      "x": -6,
      "y": 11,
      "z": 2,
      "name": "Rock_Stone"
    },
    {
      "x": -6,
      "y": 12,
      "z": 2,
      "name": "Rock_Stone"
    },
    {
      "x": -6,
      "y": 13,
      "z": 2,
      "name": "Soil_Dirt"
    },
    {
      "x": -6,
      "y": 14,
      "z": 2,
      "name": "Soil_Grass"
    },
    {
      "x": -6,
      "y": 8,
      "z": 3,
      "name": "Rock_Stone"
    },
    {
      "x": -6,
      "y": 9,
      "z": 3,
      "name": "Rock_Stone"
    },
    {
      "x": -6,
      "y": 10,
      "z": 3,
      "name": "Rock_Stone"
    },
    {
      "x": -6,
      "y": 11,
      "z": 3,
      "name": "Rock_Stone"
    },
    {
      "x": -6,
      "y": 12,
      "z": 3,
      "name": "Rock_Stone"
    },
    {
      "x": -6,
      "y": 13,
      "z": 3,
      "name": "Soil_Dirt"
    },
    {
      "x": -6,
      "y": 14,
      "z": 3,
      "name": "Soil_Grass"
    },
    {
      "x": -6,
      "y": 6,
      "z": 4,
      "name": "Rock_Stone_Stalactite_Small",
      "rotation": 8
    },
    {
      "x": -6,
      "y": 7,
      "z": 4,
      "name": "Rock_Stone"
    },
    {
      "x": -6,
      "y": 8,
      "z": 4,
      "name": "Rock_Stone"
    },
    {
      "x": -6,
      "y": 9,
      "z": 4,
      "name": "Rock_Stone"
    },
    {
      "x": -6,
      "y": 10,
      "z": 4,
      "name": "Rock_Stone"
    },
    {
      "x": -6,
      "y": 11,
      "z": 4,
      "name": "Rock_Stone"
    },
    {
      "x": -6,
      "y": 12,
      "z": 4,
      "name": "Rock_Stone"
    },
    {
      "x": -6,
      "y": 13,
      "z": 4,
      "name": "Soil_Dirt"
    },
    {
      "x": -6,
      "y": 14,
      "z": 4,
      "name": "Soil_Grass"
    },
    {
      "x": -6,
      "y": 8,
      "z": 5,
      "name": "Rock_Stone"
    },
    {
      "x": -6,
      "y": 9,
      "z": 5,
      "name": "Rock_Stone"
    },
    {
      "x": -6,
      "y": 10,
      "z": 5,
      "name": "Rock_Stone"
    },
    {
      "x": -6,
      "y": 11,
      "z": 5,
      "name": "Rock_Stone"
    },
    {
      "x": -6,
      "y": 12,
      "z": 5,
      "name": "Rock_Stone"
    },
    {
      "x": -6,
      "y": 13,
      "z": 5,
      "name": "Soil_Dirt"
    },
    {
      "x": -6,
      "y": 14,
      "z": 5,
      "name": "Soil_Grass"
    },
    {
      "x": -6,
      "y": 15,
      "z": 5,
      "name": "Plant_Grass_Sharp_Tall",
      "support": 15
    },
    {
      "x": -6,
      "y": 16,
      "z": 5,
      "name": "Plant_Grass_Sharp_Tall",
      "filler": 1024
    },
    {
      "x": -6,
      "y": 10,
      "z": 6,
      "name": "Rock_Stone_Mossy"
    },
    {
      "x": -6,
      "y": 11,
      "z": 6,
      "name": "Rock_Stone"
    },
    {
      "x": -6,
      "y": 12,
      "z": 6,
      "name": "Rock_Stone"
    },
    {
      "x": -6,
      "y": 13,
      "z": 6,
      "name": "Soil_Dirt"
    },
    {
      "x": -6,
      "y": 14,
      "z": 6,
      "name": "Soil_Grass"
    },
    {
      "x": -6,
      "y": 23,
      "z": 6,
      "name": "Plant_Leaves_Oak"
    },
    {
      "x": -6,
      "y": 25,
      "z": 6,
      "name": "Plant_Leaves_Oak"
    },
    {
      "x": -6,
      "y": 26,
      "z": 6,
      "name": "Plant_Leaves_Oak"
    },
    {
      "x": -6,
      "y": 10,
      "z": 7,
      "name": "Rock_Stone_Mossy"
    },
    {
      "x": -6,
      "y": 11,
      "z": 7,
      "name": "Rock_Stone"
    },
    {
      "x": -6,
      "y": 12,
      "z": 7,
      "name": "Rock_Stone"
    },
    {
      "x": -6,
      "y": 13,
      "z": 7,
      "name": "Soil_Dirt"
    },
    {
      "x": -6,
      "y": 14,
      "z": 7,
      "name": "Soil_Grass"
    },
    {
      "x": -6,
      "y": 21,
      "z": 7,
      "name": "Plant_Leaves_Oak"
    },
    {
      "x": -6,
      "y": 22,
      "z": 7,
      "name": "Plant_Leaves_Oak"
    },
    {
      "x": -6,
      "y": 23,
      "z": 7,
      "name": "Plant_Leaves_Oak"
    },
    {
      "x": -6,
      "y": 25,
      "z": 7,
      "name": "Wood_Oak_Branch_Long",
      "rotation": 4
    },
    {
      "x": -6,
      "y": 26,
      "z": 7,
      "name": "Plant_Leaves_Oak"
    },
    {
      "x": -6,
      "y": 27,
      "z": 7,
      "name": "Plant_Leaves_Oak"
    },
    {
      "x": -6,
      "y": 10,
      "z": 8,
      "name": "Rock_Stone"
    },
    {
      "x": -6,
      "y": 11,
      "z": 8,
      "name": "Rock_Stone"
    },
    {
      "x": -6,
      "y": 12,
      "z": 8,
      "name": "Rock_Stone"
    },
    {
      "x": -6,
      "y": 13,
      "z": 8,
      "name": "Soil_Dirt"
    },
    {
      "x": -6,
      "y": 14,
      "z": 8,
      "name": "Soil_Grass"
    },
    {
      "x": -6,
      "y": 21,
      "z": 8,
      "name": "Plant_Leaves_Oak"
    },
    {
      "x": -6,
      "y": 22,
      "z": 8,
      "name": "Wood_Oak_Branch_Long",
      "rotation": 4
    },
    {
      "x": -6,
      "y": 25,
      "z": 8,
      "name": "Wood_Oak_Branch_Long",
      "rotation": 4
    },
    {
      "x": -6,
      "y": 27,
      "z": 8,
      "name": "Plant_Leaves_Oak"
    },
    {
      "x": -6,
      "y": 10,
      "z": 9,
      "name": "Rock_Stone"
    },
    {
      "x": -6,
      "y": 11,
      "z": 9,
      "name": "Rock_Stone"
    },
    {
      "x": -6,
      "y": 12,
      "z": 9,
      "name": "Rock_Stone"
    },
    {
      "x": -6,
      "y": 13,
      "z": 9,
      "name": "Wood_Oak_Trunk_Full",
      "rotation": 8
    },
    {
      "x": -6,
      "y": 14,
      "z": 9,
      "name": "Wood_Oak_Trunk_Full"
    },
    {
      "x": -6,
      "y": 20,
      "z": 9,
      "name": "Wood_Oak_Branch_Short",
      "rotation": 2
    },
    {
      "x": -6,
      "y": 21,
      "z": 9,
      "name": "Wood_Oak_Branch_Long",
      "rotation": 4
    },
    {
      "x": -6,
      "y": 22,
      "z": 9,
      "name": "Wood_Oak_Trunk_Full"
    },
    {
      "x": -6,
      "y": 25,
      "z": 9,
      "name": "Wood_Oak_Trunk",
      "rotation": 4
    },
    {
      "x": -6,
      "y": 27,
      "z": 9,
      "name": "Plant_Leaves_Oak"
    },
    {
      "x": -6,
      "y": 28,
      "z": 9,
      "name": "Plant_Leaves_Oak"
    },
    {
      "x": -6,
      "y": 10,
      "z": 10,
      "name": "Plant_Vine_Wall",
      "support": 15
    },
    {
      "x": -6,
      "y": 11,
      "z": 10,
      "name": "Rock_Stone"
    },
    {
      "x": -6,
      "y": 12,
      "z": 10,
      "name": "Wood_Oak_Trunk"
    },
    {
      "x": -6,
      "y": 13,
      "z": 10,
      "name": "Wood_Oak_Trunk"
    },
    {
      "x": -6,
      "y": 14,
      "z": 10,
      "name": "Wood_Oak_Trunk"
    },
    {
      "x": -6,
      "y": 15,
      "z": 10,
      "name": "Wood_Oak_Trunk"
    },
    {
      "x": -6,
      "y": 16,
      "z": 10,
      "name": "Wood_Oak_Trunk"
    },
    {
      "x": -6,
      "y": 17,
      "z": 10,
      "name": "Wood_Oak_Trunk"
    },
    {
      "x": -6,
      "y": 18,
      "z": 10,
      "name": "Wood_Oak_Trunk"
    },
    {
      "x": -6,
      "y": 19,
      "z": 10,
      "name": "Wood_Oak_Trunk"
    },
    {
      "x": -6,
      "y": 20,
      "z": 10,
      "name": "Wood_Oak_Trunk"
    },
    {
      "x": -6,
      "y": 21,
      "z": 10,
      "name": "Wood_Oak_Trunk"
    },
    {
      "x": -6,
      "y": 22,
      "z": 10,
      "name": "Wood_Oak_Trunk"
    },
    {
      "x": -6,
      "y": 23,
      "z": 10,
      "name": "Wood_Oak_Trunk"
    },
    {
      "x": -6,
      "y": 24,
      "z": 10,
      "name": "Wood_Oak_Trunk"
    },
    {
      "x": -6,
      "y": 25,
      "z": 10,
      "name": "Wood_Oak_Trunk"
    },
    {
      "x": -6,
      "y": 26,
      "z": 10,
      "name": "Wood_Oak_Trunk_Full"
    },
    {
      "x": -6,
      "y": 27,
      "z": 10,
      "name": "Plant_Leaves_Oak"
    },
    {
      "x": -6,
      "y": 28,
      "z": 10,
      "name": "Plant_Leaves_Oak"
    },
    {
      "x": -6,
      "y": 12,
      "z": 11,
      "name": "Rock_Stone"
    },
    {
      "x": -6,
      "y": 13,
      "z": 11,
      "name": "Soil_Dirt"
    },
    {
      "x": -6,
      "y": 14,
      "z": 11,
      "name": "Soil_Grass"
    },
    {
      "x": -6,
      "y": 19,
      "z": 11,
      "name": "Wood_Oak_Branch_Short"
    },
    {
      "x": -6,
      "y": 22,
      "z": 11,
      "name": "Wood_Oak_Trunk_Full"
    },
    {
      "x": -6,
      "y": 25,
      "z": 11,
      "name": "Wood_Oak_Trunk_Full"
    },
    {
      "x": -6,
      "y": 27,
      "z": 11,
      "name": "Plant_Leaves_Oak"
    },
    {
      "x": -6,
      "y": 12,
      "z": 12,
      "name": "Rock_Stone"
    },
    {
      "x": -6,
      "y": 13,
      "z": 12,
      "name": "Soil_Dirt"
    },
    {
      "x": -6,
      "y": 14,
      "z": 12,
      "name": "Soil_Grass"
    },
    {
      "x": -6,
      "y": 22,
      "z": 12,
      "name": "Wood_Oak_Branch_Long",
      "rotation": 4
    },
    {
      "x": -6,
      "y": 25,
      "z": 12,
      "name": "Wood_Oak_Branch_Long",
      "rotation": 4
    },
    {
      "x": -6,
      "y": 26,
      "z": 12,
      "name": "Plant_Leaves_Oak"
    },
    {
      "x": -6,
      "y": 27,
      "z": 12,
      "name": "Plant_Leaves_Oak"
    },
    {
      "x": -6,
      "y": 12,
      "z": 13,
      "name": "Plant_Vine_Wall",
      "support": 15
    },
    {
      "x": -6,
      "y": 13,
      "z": 13,
      "name": "Soil_Dirt"
    },
    {
      "x": -6,
      "y": 14,
      "z": 13,
      "name": "Soil_Grass"
    },
    {
      "x": -6,
      "y": 22,
      "z": 13,
      "name": "Plant_Leaves_Oak"
    },
    {
      "x": -6,
      "y": 23,
      "z": 13,
      "name": "Plant_Leaves_Oak"
    },
    {
      "x": -6,
      "y": 24,
      "z": 13,
      "name": "Plant_Leaves_Oak"
    },
    {
      "x": -6,
      "y": 25,
      "z": 13,
      "name": "Plant_Leaves_Oak"
    },
    {
      "x": -6,
      "y": 26,
      "z": 13,
      "name": "Plant_Leaves_Oak"
    },
    {
      "x": -6,
      "y": 13,
      "z": 14,
      "name": "Soil_Dirt"
    },
    {
      "x": -6,
      "y": 14,
      "z": 14,
      "name": "Soil_Grass"
    },
    {
      "x": -6,
      "y": 15,
      "z": 14,
      "name": "Plant_Grass_Sharp_Tall",
      "support": 15
    },
    {
      "x": -6,
      "y": 16,
      "z": 14,
      "name": "Plant_Grass_Sharp_Tall",
      "filler": 1024
    },
    {
      "x": -6,
      "y": 13,
      "z": 15,
      "name": "Plant_Vine_Wall",
      "support": 15
    },
    {
      "x": -6,
      "y": 14,
      "z": 15,
      "name": "Soil_Grass"
    },
    {
      "x": -5,
      "y": 13,
      "z": -8,
      "name": "Plant_Vine",
      "support": 15,
      "rotation": 2
    },
    {
      "x": -5,
      "y": 14,
      "z": -8,
      "name": "Soil_Grass"
    },
    {
      "x": -5,
      "y": 13,
      "z": -7,
      "name": "Soil_Dirt"
    },
    {
      "x": -5,
      "y": 14,
      "z": -7,
      "name": "Soil_Grass"
    },
    {
      "x": -5,
      "y": 13,
      "z": -6,
      "name": "Soil_Dirt"
    },
    {
      "x": -5,
      "y": 14,
      "z": -6,
      "name": "Soil_Grass"
    },
    {
      "x": -5,
      "y": 12,
      "z": -5,
      "name": "Rock_Stone"
    },
    {
      "x": -5,
      "y": 13,
      "z": -5,
      "name": "Soil_Dirt"
    },
    {
      "x": -5,
      "y": 14,
      "z": -5,
      "name": "Soil_Grass"
    },
    {
      "x": -5,
      "y": 11,
      "z": -4,
      "name": "Plant_Vine_Wall",
      "support": 15,
      "rotation": 2
    },
    {
      "x": -5,
      "y": 12,
      "z": -4,
      "name": "Rock_Stone"
    },
    {
      "x": -5,
      "y": 13,
      "z": -4,
      "name": "Soil_Dirt"
    },
    {
      "x": -5,
      "y": 14,
      "z": -4,
      "name": "Soil_Grass"
    },
    {
      "x": -5,
      "y": 11,
      "z": -3,
      "name": "Rock_Stone"
    },
    {
      "x": -5,
      "y": 12,
      "z": -3,
      "name": "Rock_Stone"
    },
    {
      "x": -5,
      "y": 13,
      "z": -3,
      "name": "Soil_Dirt"
    },
    {
      "x": -5,
      "y": 14,
      "z": -3,
      "name": "Soil_Grass"
    },
    {
      "x": -5,
      "y": 15,
      "z": -3,
      "name": "Plant_Grass_Sharp",
      "support": 15
    },
    {
      "x": -5,
      "y": 10,
      "z": -2,
      "name": "Rock_Stone"
    },
    {
      "x": -5,
      "y": 11,
      "z": -2,
      "name": "Rock_Stone"
    },
    {
      "x": -5,
      "y": 12,
      "z": -2,
      "name": "Rock_Stone"
    },
    {
      "x": -5,
      "y": 13,
      "z": -2,
      "name": "Soil_Dirt"
    },
    {
      "x": -5,
      "y": 14,
      "z": -2,
      "name": "Soil_Grass"
    },
    {
      "x": -5,
      "y": 7,
      "z": -1,
      "name": "Plant_Vine_Wall",
      "support": 15,
      "rotation": 2
    },
    {
      "x": -5,
      "y": 9,
      "z": -1,
      "name": "Rock_Stone_Mossy"
    },
    {
      "x": -5,
      "y": 10,
      "z": -1,
      "name": "Rock_Stone"
    },
    {
      "x": -5,
      "y": 11,
      "z": -1,
      "name": "Rock_Stone"
    },
    {
      "x": -5,
      "y": 12,
      "z": -1,
      "name": "Rock_Stone"
    },
    {
      "x": -5,
      "y": 13,
      "z": -1,
      "name": "Soil_Dirt"
    },
    {
      "x": -5,
      "y": 14,
      "z": -1,
      "name": "Soil_Grass"
    },
    {
      "x": -5,
      "y": 5,
      "z": 0,
      "name": "Rock_Stone_Stalactite_Large",
      "filler": 31744,
      "rotation": 8
    },
    {
      "x": -5,
      "y": 6,
      "z": 0,
      "name": "Rock_Stone_Stalactite_Large",
      "rotation": 8
    },
    {
      "x": -5,
      "y": 7,
      "z": 0,
      "name": "Rock_Stone"
    },
    {
      "x": -5,
      "y": 8,
      "z": 0,
      "name": "Rock_Stone"
    },
    {
      "x": -5,
      "y": 9,
      "z": 0,
      "name": "Rock_Stone_Mossy"
    },
    {
      "x": -5,
      "y": 10,
      "z": 0,
      "name": "Rock_Stone"
    },
    {
      "x": -5,
      "y": 11,
      "z": 0,
      "name": "Rock_Stone"
    },
    {
      "x": -5,
      "y": 12,
      "z": 0,
      "name": "Rock_Stone"
    },
    {
      "x": -5,
      "y": 13,
      "z": 0,
      "name": "Soil_Dirt"
    },
    {
      "x": -5,
      "y": 14,
      "z": 0,
      "name": "Soil_Grass"
    },
    {
      "x": -5,
      "y": 7,
      "z": 1,
      "name": "Rock_Stone"
    },
    {
      "x": -5,
      "y": 8,
      "z": 1,
      "name": "Rock_Stone"
    },
    {
      "x": -5,
      "y": 9,
      "z": 1,
      "name": "Rock_Stone"
    },
    {
      "x": -5,
      "y": 10,
      "z": 1,
      "name": "Rock_Stone"
    },
    {
      "x": -5,
      "y": 11,
      "z": 1,
      "name": "Rock_Stone"
    },
    {
      "x": -5,
      "y": 12,
      "z": 1,
      "name": "Rock_Stone"
    },
    {
      "x": -5,
      "y": 13,
      "z": 1,
      "name": "Soil_Dirt"
    },
    {
      "x": -5,
      "y": 14,
      "z": 1,
      "name": "Soil_Grass"
    },
    {
      "x": -5,
      "y": 15,
      "z": 1,
      "name": "Plant_Grass_Sharp_Wild",
      "support": 15
    },
    {
      "x": -5,
      "y": 16,
      "z": 1,
      "name": "Plant_Grass_Sharp_Wild",
      "filler": 1024
    },
    {
      "x": -5,
      "y": 6,
      "z": 2,
      "name": "Rock_Stone"
    },
    {
      "x": -5,
      "y": 7,
      "z": 2,
      "name": "Rock_Stone"
    },
    {
      "x": -5,
      "y": 8,
      "z": 2,
      "name": "Rock_Stone"
    },
    {
      "x": -5,
      "y": 9,
      "z": 2,
      "name": "Rock_Stone"
    },
    {
      "x": -5,
      "y": 10,
      "z": 2,
      "name": "Rock_Stone"
    },
    {
      "x": -5,
      "y": 11,
      "z": 2,
      "name": "Rock_Stone"
    },
    {
      "x": -5,
      "y": 12,
      "z": 2,
      "name": "Rock_Stone"
    },
    {
      "x": -5,
      "y": 13,
      "z": 2,
      "name": "Soil_Dirt"
    },
    {
      "x": -5,
      "y": 14,
      "z": 2,
      "name": "Soil_Grass"
    },
    {
      "x": -5,
      "y": 15,
      "z": 2,
      "name": "Plant_Grass_Sharp_Wild",
      "support": 15
    },
    {
      "x": -5,
      "y": 16,
      "z": 2,
      "name": "Plant_Grass_Sharp_Wild",
      "filler": 1024
    },
    {
      "x": -5,
      "y": 19,
      "z": 2,
      "name": "Plant_Moss_Wall_Green",
      "rotation": 3
    },
    {
      "x": -5,
      "y": 6,
      "z": 3,
      "name": "Rock_Stone"
    },
    {
      "x": -5,
      "y": 7,
      "z": 3,
      "name": "Rock_Stone"
    },
    {
      "x": -5,
      "y": 8,
      "z": 3,
      "name": "Rock_Stone"
    },
    {
      "x": -5,
      "y": 9,
      "z": 3,
      "name": "Rock_Stone"
    },
    {
      "x": -5,
      "y": 10,
      "z": 3,
      "name": "Rock_Stone"
    },
    {
      "x": -5,
      "y": 11,
      "z": 3,
      "name": "Rock_Stone"
    },
    {
      "x": -5,
      "y": 12,
      "z": 3,
      "name": "Rock_Stone"
    },
    {
      "x": -5,
      "y": 13,
      "z": 3,
      "name": "Soil_Dirt"
    },
    {
      "x": -5,
      "y": 14,
      "z": 3,
      "name": "Soil_Grass"
    },
    {
      "x": -5,
      "y": 6,
      "z": 4,
      "name": "Rock_Stone"
    },
    {
      "x": -5,
      "y": 7,
      "z": 4,
      "name": "Rock_Stone"
    },
    {
      "x": -5,
      "y": 8,
      "z": 4,
      "name": "Rock_Stone"
    },
    {
      "x": -5,
      "y": 9,
      "z": 4,
      "name": "Rock_Stone"
    },
    {
      "x": -5,
      "y": 10,
      "z": 4,
      "name": "Rock_Stone"
    },
    {
      "x": -5,
      "y": 11,
      "z": 4,
      "name": "Rock_Stone"
    },
    {
      "x": -5,
      "y": 12,
      "z": 4,
      "name": "Rock_Stone"
    },
    {
      "x": -5,
      "y": 13,
      "z": 4,
      "name": "Soil_Dirt"
    },
    {
      "x": -5,
      "y": 14,
      "z": 4,
      "name": "Soil_Grass"
    },
    {
      "x": -5,
      "y": 19,
      "z": 4,
      "name": "Plant_Moss_Wall_Green",
      "rotation": 3
    },
    {
      "x": -5,
      "y": 20,
      "z": 4,
      "name": "Plant_Moss_Wall_Green",
      "rotation": 3
    },
    {
      "x": -5,
      "y": 5,
      "z": 5,
      "name": "Plant_Moss_Wall_Green",
      "support": 15,
      "rotation": 3
    },
    {
      "x": -5,
      "y": 6,
      "z": 5,
      "name": "Rock_Stone_Mossy"
    },
    {
      "x": -5,
      "y": 7,
      "z": 5,
      "name": "Rock_Stone_Mossy"
    },
    {
      "x": -5,
      "y": 8,
      "z": 5,
      "name": "Rock_Stone"
    },
    {
      "x": -5,
      "y": 9,
      "z": 5,
      "name": "Rock_Stone"
    },
    {
      "x": -5,
      "y": 10,
      "z": 5,
      "name": "Rock_Stone"
    },
    {
      "x": -5,
      "y": 11,
      "z": 5,
      "name": "Rock_Stone"
    },
    {
      "x": -5,
      "y": 12,
      "z": 5,
      "name": "Rock_Stone"
    },
    {
      "x": -5,
      "y": 13,
      "z": 5,
      "name": "Soil_Dirt"
    },
    {
      "x": -5,
      "y": 14,
      "z": 5,
      "name": "Soil_Grass"
    },
    {
      "x": -5,
      "y": 6,
      "z": 6,
      "name": "Rock_Stone_Mossy"
    },
    {
      "x": -5,
      "y": 7,
      "z": 6,
      "name": "Rock_Stone_Mossy"
    },
    {
      "x": -5,
      "y": 8,
      "z": 6,
      "name": "Rock_Stone_Mossy"
    },
    {
      "x": -5,
      "y": 9,
      "z": 6,
      "name": "Rock_Stone_Mossy"
    },
    {
      "x": -5,
      "y": 10,
      "z": 6,
      "name": "Rock_Stone"
    },
    {
      "x": -5,
      "y": 11,
      "z": 6,
      "name": "Rock_Stone"
    },
    {
      "x": -5,
      "y": 12,
      "z": 6,
      "name": "Rock_Stone"
    },
    {
      "x": -5,
      "y": 13,
      "z": 6,
      "name": "Soil_Dirt"
    },
    {
      "x": -5,
      "y": 14,
      "z": 6,
      "name": "Soil_Grass"
    },
    {
      "x": -5,
      "y": 22,
      "z": 6,
      "name": "Plant_Leaves_Oak"
    },
    {
      "x": -5,
      "y": 24,
      "z": 6,
      "name": "Plant_Leaves_Oak"
    },
    {
      "x": -5,
      "y": 25,
      "z": 6,
      "name": "Plant_Leaves_Oak"
    },
    {
      "x": -5,
      "y": 7,
      "z": 7,
      "name": "Plant_Vine",
      "support": 15,
      "rotation": 3
    },
    {
      "x": -5,
      "y": 9,
      "z": 7,
      "name": "Rock_Stone_Mossy"
    },
    {
      "x": -5,
      "y": 10,
      "z": 7,
      "name": "Rock_Stone"
    },
    {
      "x": -5,
      "y": 11,
      "z": 7,
      "name": "Rock_Stone"
    },
    {
      "x": -5,
      "y": 12,
      "z": 7,
      "name": "Rock_Stone"
    },
    {
      "x": -5,
      "y": 13,
      "z": 7,
      "name": "Soil_Dirt"
    },
    {
      "x": -5,
      "y": 14,
      "z": 7,
      "name": "Soil_Grass"
    },
    {
      "x": -5,
      "y": 15,
      "z": 7,
      "name": "Plant_Grass_Sharp_Wild",
      "support": 15
    },
    {
      "x": -5,
      "y": 16,
      "z": 7,
      "name": "Plant_Grass_Sharp_Wild",
      "filler": 1024
    },
    {
      "x": -5,
      "y": 21,
      "z": 7,
      "name": "Plant_Leaves_Oak"
    },
    {
      "x": -5,
      "y": 22,
      "z": 7,
      "name": "Plant_Leaves_Oak"
    },
    {
      "x": -5,
      "y": 23,
      "z": 7,
      "name": "Plant_Leaves_Oak"
    },
    {
      "x": -5,
      "y": 26,
      "z": 7,
      "name": "Plant_Leaves_Oak"
    },
    {
      "x": -5,
      "y": 7,
      "z": 8,
      "name": "Plant_Vine",
      "support": 15,
      "rotation": 3
    },
    {
      "x": -5,
      "y": 8,
      "z": 8,
      "name": "Plant_Vine",
      "support": 15,
      "rotation": 3
    },
    {
      "x": -5,
      "y": 9,
      "z": 8,
      "name": "Rock_Stone"
    },
    {
      "x": -5,
      "y": 10,
      "z": 8,
      "name": "Rock_Stone"
    },
    {
      "x": -5,
      "y": 11,
      "z": 8,
      "name": "Rock_Stone"
    },
    {
      "x": -5,
      "y": 12,
      "z": 8,
      "name": "Rock_Stone"
    },
    {
      "x": -5,
      "y": 13,
      "z": 8,
      "name": "Soil_Dirt"
    },
    {
      "x": -5,
      "y": 14,
      "z": 8,
      "name": "Soil_Grass"
    },
    {
      "x": -5,
      "y": 10,
      "z": 9,
      "name": "Rock_Stone"
    },
    {
      "x": -5,
      "y": 11,
      "z": 9,
      "name": "Rock_Stone"
    },
    {
      "x": -5,
      "y": 12,
      "z": 9,
      "name": "Rock_Stone"
    },
    {
      "x": -5,
      "y": 13,
      "z": 9,
      "name": "Soil_Dirt"
    },
    {
      "x": -5,
      "y": 14,
      "z": 9,
      "name": "Soil_Grass"
    },
    {
      "x": -5,
      "y": 15,
      "z": 9,
      "name": "Plant_Grass_Sharp",
      "support": 15
    },
    {
      "x": -5,
      "y": 27,
      "z": 9,
      "name": "Plant_Leaves_Oak"
    },
    {
      "x": -5,
      "y": 10,
      "z": 10,
      "name": "Rock_Stone_Mossy"
    },
    {
      "x": -5,
      "y": 11,
      "z": 10,
      "name": "Rock_Stone"
    },
    {
      "x": -5,
      "y": 12,
      "z": 10,
      "name": "Rock_Stone"
    },
    {
      "x": -5,
      "y": 13,
      "z": 10,
      "name": "Soil_Dirt"
    },
    {
      "x": -5,
      "y": 14,
      "z": 10,
      "name": "Wood_Oak_Trunk_Full"
    },
    {
      "x": -5,
      "y": 15,
      "z": 10,
      "name": "Wood_Oak_Trunk_Full"
    },
    {
      "x": -5,
      "y": 20,
      "z": 10,
      "name": "Wood_Oak_Branch_Short",
      "rotation": 1
    },
    {
      "x": -5,
      "y": 24,
      "z": 10,
      "name": "Wood_Oak_Trunk_Full"
    },
    {
      "x": -5,
      "y": 27,
      "z": 10,
      "name": "Plant_Leaves_Oak"
    },
    {
      "x": -5,
      "y": 28,
      "z": 10,
      "name": "Plant_Leaves_Oak"
    },
    {
      "x": -5,
      "y": 11,
      "z": 11,
      "name": "Rock_Stone"
    },
    {
      "x": -5,
      "y": 12,
      "z": 11,
      "name": "Rock_Stone"
    },
    {
      "x": -5,
      "y": 13,
      "z": 11,
      "name": "Soil_Dirt"
    },
    {
      "x": -5,
      "y": 14,
      "z": 11,
      "name": "Soil_Grass"
    },
    {
      "x": -5,
      "y": 21,
      "z": 11,
      "name": "Plant_Leaves_Oak"
    },
    {
      "x": -5,
      "y": 26,
      "z": 11,
      "name": "Plant_Leaves_Oak"
    },
    {
      "x": -5,
      "y": 12,
      "z": 12,
      "name": "Rock_Stone"
    },
    {
      "x": -5,
      "y": 13,
      "z": 12,
      "name": "Soil_Dirt"
    },
    {
      "x": -5,
      "y": 14,
      "z": 12,
      "name": "Soil_Grass"
    },
    {
      "x": -5,
      "y": 15,
      "z": 12,
      "name": "Plant_Grass_Sharp_Tall",
      "support": 15
    },
    {
      "x": -5,
      "y": 16,
      "z": 12,
      "name": "Plant_Grass_Sharp_Tall",
      "filler": 1024
    },
    {
      "x": -5,
      "y": 22,
      "z": 12,
      "name": "Plant_Leaves_Oak"
    },
    {
      "x": -5,
      "y": 23,
      "z": 12,
      "name": "Plant_Leaves_Oak"
    },
    {
      "x": -5,
      "y": 24,
      "z": 12,
      "name": "Plant_Leaves_Oak"
    },
    {
      "x": -5,
      "y": 12,
      "z": 13,
      "name": "Rock_Stone"
    },
    {
      "x": -5,
      "y": 13,
      "z": 13,
      "name": "Soil_Dirt"
    },
    {
      "x": -5,
      "y": 14,
      "z": 13,
      "name": "Soil_Grass"
    },
    {
      "x": -5,
      "y": 15,
      "z": 13,
      "name": "Plant_Grass_Sharp",
      "support": 15
    },
    {
      "x": -5,
      "y": 22,
      "z": 13,
      "name": "Plant_Leaves_Oak"
    },
    {
      "x": -5,
      "y": 13,
      "z": 14,
      "name": "Soil_Dirt"
    },
    {
      "x": -5,
      "y": 14,
      "z": 14,
      "name": "Soil_Grass"
    },
    {
      "x": -5,
      "y": 14,
      "z": 15,
      "name": "Soil_Grass"
    },
    {
      "x": -4,
      "y": 13,
      "z": -8,
      "name": "Plant_Vine",
      "support": 15,
      "rotation": 2
    },
    {
      "x": -4,
      "y": 14,
      "z": -8,
      "name": "Soil_Grass"
    },
    {
      "x": -4,
      "y": 12,
      "z": -7,
      "name": "Plant_Vine",
      "support": 15,
      "rotation": 2
    },
    {
      "x": -4,
      "y": 13,
      "z": -7,
      "name": "Soil_Dirt"
    },
    {
      "x": -4,
      "y": 14,
      "z": -7,
      "name": "Soil_Grass"
    },
    {
      "x": -4,
      "y": 12,
      "z": -6,
      "name": "Rock_Stone"
    },
    {
      "x": -4,
      "y": 13,
      "z": -6,
      "name": "Soil_Dirt"
    },
    {
      "x": -4,
      "y": 14,
      "z": -6,
      "name": "Soil_Grass"
    },
    {
      "x": -4,
      "y": 11,
      "z": -5,
      "name": "Plant_Vine",
      "support": 15,
      "rotation": 3
    },
    {
      "x": -4,
      "y": 12,
      "z": -5,
      "name": "Rock_Stone"
    },
    {
      "x": -4,
      "y": 13,
      "z": -5,
      "name": "Soil_Dirt"
    },
    {
      "x": -4,
      "y": 14,
      "z": -5,
      "name": "Soil_Grass"
    },
    {
      "x": -4,
      "y": 11,
      "z": -4,
      "name": "Rock_Stone"
    },
    {
      "x": -4,
      "y": 12,
      "z": -4,
      "name": "Rock_Stone"
    },
    {
      "x": -4,
      "y": 13,
      "z": -4,
      "name": "Soil_Dirt"
    },
    {
      "x": -4,
      "y": 14,
      "z": -4,
      "name": "Soil_Grass"
    },
    {
      "x": -4,
      "y": 9,
      "z": -3,
      "name": "Rock_Stone_Stalactite_Small",
      "rotation": 8
    },
    {
      "x": -4,
      "y": 10,
      "z": -3,
      "name": "Rock_Stone"
    },
    {
      "x": -4,
      "y": 11,
      "z": -3,
      "name": "Rock_Stone"
    },
    {
      "x": -4,
      "y": 12,
      "z": -3,
      "name": "Rock_Stone"
    },
    {
      "x": -4,
      "y": 13,
      "z": -3,
      "name": "Soil_Dirt"
    },
    {
      "x": -4,
      "y": 14,
      "z": -3,
      "name": "Soil_Grass"
    },
    {
      "x": -4,
      "y": 9,
      "z": -2,
      "name": "Rock_Stone_Mossy"
    },
    {
      "x": -4,
      "y": 10,
      "z": -2,
      "name": "Rock_Stone"
    },
    {
      "x": -4,
      "y": 11,
      "z": -2,
      "name": "Rock_Stone"
    },
    {
      "x": -4,
      "y": 12,
      "z": -2,
      "name": "Rock_Stone"
    },
    {
      "x": -4,
      "y": 13,
      "z": -2,
      "name": "Soil_Dirt"
    },
    {
      "x": -4,
      "y": 14,
      "z": -2,
      "name": "Soil_Grass"
    },
    {
      "x": -4,
      "y": 8,
      "z": -1,
      "name": "Rock_Stone_Mossy"
    },
    {
      "x": -4,
      "y": 9,
      "z": -1,
      "name": "Rock_Stone"
    },
    {
      "x": -4,
      "y": 10,
      "z": -1,
      "name": "Rock_Stone"
    },
    {
      "x": -4,
      "y": 11,
      "z": -1,
      "name": "Rock_Stone"
    },
    {
      "x": -4,
      "y": 12,
      "z": -1,
      "name": "Rock_Stone"
    },
    {
      "x": -4,
      "y": 13,
      "z": -1,
      "name": "Soil_Dirt"
    },
    {
      "x": -4,
      "y": 14,
      "z": -1,
      "name": "Soil_Grass"
    },
    {
      "x": -4,
      "y": 6,
      "z": 0,
      "name": "Rock_Stone"
    },
    {
      "x": -4,
      "y": 7,
      "z": 0,
      "name": "Rock_Stone"
    },
    {
      "x": -4,
      "y": 8,
      "z": 0,
      "name": "Rock_Stone"
    },
    {
      "x": -4,
      "y": 9,
      "z": 0,
      "name": "Rock_Stone"
    },
    {
      "x": -4,
      "y": 10,
      "z": 0,
      "name": "Rock_Stone"
    },
    {
      "x": -4,
      "y": 11,
      "z": 0,
      "name": "Soil_Dirt"
    },
    {
      "x": -4,
      "y": 12,
      "z": 0,
      "name": "Soil_Dirt"
    },
    {
      "x": -4,
      "y": 13,
      "z": 0,
      "name": "Soil_Dirt"
    },
    {
      "x": -4,
      "y": 14,
      "z": 0,
      "name": "Soil_Dirt"
    },
    {
      "x": -4,
      "y": 15,
      "z": 0,
      "name": "Rubble_Stone_Mossy_Medium",
      "support": 15
    },
    {
      "x": -4,
      "y": 17,
      "z": 0,
      "name": "Plant_Vine_Wall",
      "rotation": 2
    },
    {
      "x": -4,
      "y": 5,
      "z": 1,
      "name": "Rock_Stone"
    },
    {
      "x": -4,
      "y": 6,
      "z": 1,
      "name": "Rock_Stone"
    },
    {
      "x": -4,
      "y": 7,
      "z": 1,
      "name": "Rock_Stone"
    },
    {
      "x": -4,
      "y": 8,
      "z": 1,
      "name": "Rock_Stone"
    },
    {
      "x": -4,
      "y": 9,
      "z": 1,
      "name": "Rock_Stone"
    },
    {
      "x": -4,
      "y": 10,
      "z": 1,
      "name": "Rock_Stone"
    },
    {
      "x": -4,
      "y": 11,
      "z": 1,
      "name": "Rock_Stone_Cobble_Mossy"
    },
    {
      "x": -4,
      "y": 12,
      "z": 1,
      "name": "Rock_Stone_Cobble_Mossy"
    },
    {
      "x": -4,
      "y": 13,
      "z": 1,
      "name": "Rock_Stone_Cobble_Mossy"
    },
    {
      "x": -4,
      "y": 14,
      "z": 1,
      "name": "Rock_Stone_Cobble"
    },
    {
      "x": -4,
      "y": 15,
      "z": 1,
      "name": "Rock_Stone_Cobble"
    },
    {
      "x": -4,
      "y": 16,
      "z": 1,
      "name": "Rock_Stone_Cobble_Mossy"
    },
    {
      "x": -4,
      "y": 17,
      "z": 1,
      "name": "Rock_Stone_Cobble_Mossy"
    },
    {
      "x": -4,
      "y": 18,
      "z": 1,
      "name": "Rock_Stone_Cobble"
    },
    {
      "x": -4,
      "y": 19,
      "z": 1,
      "name": "Rubble_Stone_Medium",
      "support": 15
    },
    {
      "x": -4,
      "y": 5,
      "z": 2,
      "name": "Rock_Stone"
    },
    {
      "x": -4,
      "y": 6,
      "z": 2,
      "name": "Rock_Stone"
    },
    {
      "x": -4,
      "y": 7,
      "z": 2,
      "name": "Rock_Stone"
    },
    {
      "x": -4,
      "y": 8,
      "z": 2,
      "name": "Rock_Stone"
    },
    {
      "x": -4,
      "y": 9,
      "z": 2,
      "name": "Rock_Stone"
    },
    {
      "x": -4,
      "y": 10,
      "z": 2,
      "name": "Rock_Stone"
    },
    {
      "x": -4,
      "y": 11,
      "z": 2,
      "name": "Rock_Stone_Cobble_Mossy"
    },
    {
      "x": -4,
      "y": 12,
      "z": 2,
      "name": "Rock_Stone_Cobble"
    },
    {
      "x": -4,
      "y": 13,
      "z": 2,
      "name": "Rock_Stone_Cobble"
    },
    {
      "x": -4,
      "y": 14,
      "z": 2,
      "name": "Rock_Stone_Cobble"
    },
    {
      "x": -4,
      "y": 15,
      "z": 2,
      "name": "Rock_Stone_Cobble"
    },
    {
      "x": -4,
      "y": 16,
      "z": 2,
      "name": "Rock_Stone_Cobble_Mossy"
    },
    {
      "x": -4,
      "y": 17,
      "z": 2,
      "name": "Rock_Stone_Cobble"
    },
    {
      "x": -4,
      "y": 18,
      "z": 2,
      "name": "Rock_Stone_Cobble"
    },
    {
      "x": -4,
      "y": 19,
      "z": 2,
      "name": "Rock_Stone_Cobble"
    },
    {
      "x": -4,
      "y": 20,
      "z": 2,
      "name": "Plant_Moss_Rug_Green"
    },
    {
      "x": -4,
      "y": 5,
      "z": 3,
      "name": "Rock_Stone"
    },
    {
      "x": -4,
      "y": 6,
      "z": 3,
      "name": "Rock_Stone"
    },
    {
      "x": -4,
      "y": 7,
      "z": 3,
      "name": "Rock_Stone"
    },
    {
      "x": -4,
      "y": 8,
      "z": 3,
      "name": "Rock_Stone"
    },
    {
      "x": -4,
      "y": 9,
      "z": 3,
      "name": "Rock_Stone"
    },
    {
      "x": -4,
      "y": 10,
      "z": 3,
      "name": "Rock_Stone"
    },
    {
      "x": -4,
      "y": 11,
      "z": 3,
      "name": "Rock_Stone_Cobble"
    },
    {
      "x": -4,
      "y": 12,
      "z": 3,
      "name": "Rock_Stone_Cobble"
    },
    {
      "x": -4,
      "y": 13,
      "z": 3,
      "name": "Rock_Stone_Cobble"
    },
    {
      "x": -4,
      "y": 14,
      "z": 3,
      "name": "Rock_Stone_Cobble"
    },
    {
      "x": -4,
      "y": 15,
      "z": 3,
      "name": "Rock_Stone_Cobble"
    },
    {
      "x": -4,
      "y": 16,
      "z": 3,
      "name": "Rock_Stone_Cobble"
    },
    {
      "x": -4,
      "y": 17,
      "z": 3,
      "name": "Rock_Stone_Cobble"
    },
    {
      "x": -4,
      "y": 18,
      "z": 3,
      "name": "Rock_Stone_Cobble"
    },
    {
      "x": -4,
      "y": 19,
      "z": 3,
      "name": "Rock_Stone_Cobble_Mossy"
    },
    {
      "x": -4,
      "y": 20,
      "z": 3,
      "name": "Rock_Stone_Cobble_Mossy"
    },
    {
      "x": -4,
      "y": 21,
      "z": 3,
      "name": "Rubble_Stone_Mossy",
      "support": 15
    },
    {
      "x": -4,
      "y": 3,
      "z": 4,
      "name": "Plant_Vine_Wall",
      "support": 15,
      "rotation": 3
    },
    {
      "x": -4,
      "y": 5,
      "z": 4,
      "name": "Rock_Stone"
    },
    {
      "x": -4,
      "y": 6,
      "z": 4,
      "name": "Rock_Stone"
    },
    {
      "x": -4,
      "y": 7,
      "z": 4,
      "name": "Rock_Stone"
    },
    {
      "x": -4,
      "y": 8,
      "z": 4,
      "name": "Rock_Stone"
    },
    {
      "x": -4,
      "y": 9,
      "z": 4,
      "name": "Rock_Stone"
    },
    {
      "x": -4,
      "y": 10,
      "z": 4,
      "name": "Rock_Stone"
    },
    {
      "x": -4,
      "y": 11,
      "z": 4,
      "name": "Rock_Stone_Cobble"
    },
    {
      "x": -4,
      "y": 12,
      "z": 4,
      "name": "Rock_Stone_Cobble"
    },
    {
      "x": -4,
      "y": 13,
      "z": 4,
      "name": "Rock_Stone_Cobble"
    },
    {
      "x": -4,
      "y": 14,
      "z": 4,
      "name": "Rock_Stone_Cobble_Mossy"
    },
    {
      "x": -4,
      "y": 15,
      "z": 4,
      "name": "Rock_Stone_Cobble"
    },
    {
      "x": -4,
      "y": 16,
      "z": 4,
      "name": "Rock_Stone_Cobble"
    },
    {
      "x": -4,
      "y": 17,
      "z": 4,
      "name": "Rock_Stone_Cobble"
    },
    {
      "x": -4,
      "y": 18,
      "z": 4,
      "name": "Rock_Stone_Cobble"
    },
    {
      "x": -4,
      "y": 19,
      "z": 4,
      "name": "Rock_Stone_Cobble"
    },
    {
      "x": -4,
      "y": 20,
      "z": 4,
      "name": "Rock_Stone_Cobble_Mossy"
    },
    {
      "x": -4,
      "y": 21,
      "z": 4,
      "name": "Plant_Moss_Rug_Green"
    },
    {
      "x": -4,
      "y": 5,
      "z": 5,
      "name": "Rock_Stone"
    },
    {
      "x": -4,
      "y": 6,
      "z": 5,
      "name": "Rock_Stone"
    },
    {
      "x": -4,
      "y": 7,
      "z": 5,
      "name": "Rock_Stone"
    },
    {
      "x": -4,
      "y": 8,
      "z": 5,
      "name": "Rock_Stone"
    },
    {
      "x": -4,
      "y": 9,
      "z": 5,
      "name": "Rock_Stone"
    },
    {
      "x": -4,
      "y": 10,
      "z": 5,
      "name": "Rock_Stone"
    },
    {
      "x": -4,
      "y": 11,
      "z": 5,
      "name": "Rock_Stone_Cobble"
    },
    {
      "x": -4,
      "y": 12,
      "z": 5,
      "name": "Rock_Stone_Cobble"
    },
    {
      "x": -4,
      "y": 13,
      "z": 5,
      "name": "Rock_Stone_Cobble"
    },
    {
      "x": -4,
      "y": 14,
      "z": 5,
      "name": "Rock_Stone_Cobble"
    },
    {
      "x": -4,
      "y": 15,
      "z": 5,
      "name": "Rock_Stone_Cobble"
    },
    {
      "x": -4,
      "y": 16,
      "z": 5,
      "name": "Rock_Stone_Cobble"
    },
    {
      "x": -4,
      "y": 17,
      "z": 5,
      "name": "Rock_Stone_Cobble"
    },
    {
      "x": -4,
      "y": 18,
      "z": 5,
      "name": "Rock_Stone_Cobble_Mossy"
    },
    {
      "x": -4,
      "y": 19,
      "z": 5,
      "name": "Rock_Stone_Cobble_Mossy_Half",
      "rotation": 4
    },
    {
      "x": -4,
      "y": 5,
      "z": 6,
      "name": "Rock_Stone"
    },
    {
      "x": -4,
      "y": 6,
      "z": 6,
      "name": "Rock_Stone_Mossy"
    },
    {
      "x": -4,
      "y": 7,
      "z": 6,
      "name": "Rock_Stone"
    },
    {
      "x": -4,
      "y": 8,
      "z": 6,
      "name": "Rock_Stone"
    },
    {
      "x": -4,
      "y": 9,
      "z": 6,
      "name": "Rock_Stone"
    },
    {
      "x": -4,
      "y": 10,
      "z": 6,
      "name": "Rock_Stone"
    },
    {
      "x": -4,
      "y": 11,
      "z": 6,
      "name": "Rock_Stone_Cobble"
    },
    {
      "x": -4,
      "y": 12,
      "z": 6,
      "name": "Rock_Stone_Cobble"
    },
    {
      "x": -4,
      "y": 13,
      "z": 6,
      "name": "Rock_Stone_Cobble"
    },
    {
      "x": -4,
      "y": 14,
      "z": 6,
      "name": "Rock_Stone_Cobble_Mossy"
    },
    {
      "x": -4,
      "y": 15,
      "z": 6,
      "name": "Rock_Stone_Cobble_Mossy"
    },
    {
      "x": -4,
      "y": 16,
      "z": 6,
      "name": "Rock_Stone_Cobble"
    },
    {
      "x": -4,
      "y": 17,
      "z": 6,
      "name": "Rock_Stone_Cobble"
    },
    {
      "x": -4,
      "y": 18,
      "z": 6,
      "name": "Rubble_Stone_Medium",
      "support": 15
    },
    {
      "x": -4,
      "y": 7,
      "z": 7,
      "name": "Rock_Stone"
    },
    {
      "x": -4,
      "y": 8,
      "z": 7,
      "name": "Rock_Stone"
    },
    {
      "x": -4,
      "y": 9,
      "z": 7,
      "name": "Rock_Stone"
    },
    {
      "x": -4,
      "y": 10,
      "z": 7,
      "name": "Rock_Stone"
    },
    {
      "x": -4,
      "y": 11,
      "z": 7,
      "name": "Rock_Stone_Cobble"
    },
    {
      "x": -4,
      "y": 12,
      "z": 7,
      "name": "Rock_Stone_Cobble_Mossy"
    },
    {
      "x": -4,
      "y": 13,
      "z": 7,
      "name": "Rock_Stone_Cobble_Mossy"
    },
    {
      "x": -4,
      "y": 14,
      "z": 7,
      "name": "Rock_Stone_Cobble_Mossy"
    },
    {
      "x": -4,
      "y": 15,
      "z": 7,
      "name": "Rock_Stone_Cobble_Mossy"
    },
    {
      "x": -4,
      "y": 16,
      "z": 7,
      "name": "Rock_Stone_Cobble_Mossy"
    },
    {
      "x": -4,
      "y": 17,
      "z": 7,
      "name": "Plant_Moss_Rug_Green"
    },
    {
      "x": -4,
      "y": 22,
      "z": 7,
      "name": "Plant_Leaves_Oak"
    },
    {
      "x": -4,
      "y": 24,
      "z": 7,
      "name": "Plant_Leaves_Oak"
    },
    {
      "x": -4,
      "y": 6,
      "z": 8,
      "name": "Rock_Stone_Stalactite_Small",
      "rotation": 8
    },
    {
      "x": -4,
      "y": 7,
      "z": 8,
      "name": "Rock_Stone"
    },
    {
      "x": -4,
      "y": 8,
      "z": 8,
      "name": "Rock_Stone"
    },
    {
      "x": -4,
      "y": 9,
      "z": 8,
      "name": "Rock_Stone"
    },
    {
      "x": -4,
      "y": 10,
      "z": 8,
      "name": "Rock_Stone"
    },
    {
      "x": -4,
      "y": 11,
      "z": 8,
      "name": "Rock_Stone"
    },
    {
      "x": -4,
      "y": 12,
      "z": 8,
      "name": "Soil_Dirt"
    },
    {
      "x": -4,
      "y": 13,
      "z": 8,
      "name": "Soil_Dirt"
    },
    {
      "x": -4,
      "y": 14,
      "z": 8,
      "name": "Soil_Dirt"
    },
    {
      "x": -4,
      "y": 15,
      "z": 8,
      "name": "Rubble_Stone_Mossy_Medium",
      "support": 15
    },
    {
      "x": -4,
      "y": 21,
      "z": 8,
      "name": "Plant_Leaves_Oak"
    },
    {
      "x": -4,
      "y": 23,
      "z": 8,
      "name": "Plant_Leaves_Oak"
    },
    {
      "x": -4,
      "y": 24,
      "z": 8,
      "name": "Plant_Leaves_Oak"
    },
    {
      "x": -4,
      "y": 25,
      "z": 8,
      "name": "Plant_Leaves_Oak"
    },
    {
      "x": -4,
      "y": 8,
      "z": 9,
      "name": "Plant_Vine",
      "support": 15
    },
    {
      "x": -4,
      "y": 9,
      "z": 9,
      "name": "Rock_Stone"
    },
    {
      "x": -4,
      "y": 10,
      "z": 9,
      "name": "Rock_Stone"
    },
    {
      "x": -4,
      "y": 11,
      "z": 9,
      "name": "Rock_Stone"
    },
    {
      "x": -4,
      "y": 12,
      "z": 9,
      "name": "Rock_Stone"
    },
    {
      "x": -4,
      "y": 13,
      "z": 9,
      "name": "Soil_Dirt"
    },
    {
      "x": -4,
      "y": 14,
      "z": 9,
      "name": "Soil_Grass"
    },
    {
      "x": -4,
      "y": 21,
      "z": 9,
      "name": "Plant_Leaves_Oak"
    },
    {
      "x": -4,
      "y": 22,
      "z": 9,
      "name": "Plant_Leaves_Oak"
    },
    {
      "x": -4,
      "y": 25,
      "z": 9,
      "name": "Plant_Leaves_Oak"
    },
    {
      "x": -4,
      "y": 26,
      "z": 9,
      "name": "Plant_Leaves_Oak"
    },
    {
      "x": -4,
      "y": 27,
      "z": 9,
      "name": "Plant_Leaves_Oak"
    },
    {
      "x": -4,
      "y": 9,
      "z": 10,
      "name": "Plant_Vine_Wall",
      "support": 15
    },
    {
      "x": -4,
      "y": 10,
      "z": 10,
      "name": "Rock_Stone_Mossy"
    },
    {
      "x": -4,
      "y": 11,
      "z": 10,
      "name": "Rock_Stone"
    },
    {
      "x": -4,
      "y": 12,
      "z": 10,
      "name": "Rock_Stone"
    },
    {
      "x": -4,
      "y": 13,
      "z": 10,
      "name": "Soil_Dirt"
    },
    {
      "x": -4,
      "y": 14,
      "z": 10,
      "name": "Soil_Grass"
    },
    {
      "x": -4,
      "y": 21,
      "z": 10,
      "name": "Plant_Leaves_Oak"
    },
    {
      "x": -4,
      "y": 24,
      "z": 10,
      "name": "Wood_Oak_Branch_Long",
      "rotation": 5
    },
    {
      "x": -4,
      "y": 26,
      "z": 10,
      "name": "Plant_Leaves_Oak"
    },
    {
      "x": -4,
      "y": 10,
      "z": 11,
      "name": "Rock_Stone_Mossy"
    },
    {
      "x": -4,
      "y": 11,
      "z": 11,
      "name": "Rock_Stone"
    },
    {
      "x": -4,
      "y": 12,
      "z": 11,
      "name": "Rock_Stone"
    },
    {
      "x": -4,
      "y": 13,
      "z": 11,
      "name": "Soil_Dirt"
    },
    {
      "x": -4,
      "y": 14,
      "z": 11,
      "name": "Soil_Grass"
    },
    {
      "x": -4,
      "y": 15,
      "z": 11,
      "name": "Plant_Grass_Sharp",
      "support": 15
    },
    {
      "x": -4,
      "y": 21,
      "z": 11,
      "name": "Plant_Leaves_Oak"
    },
    {
      "x": -4,
      "y": 24,
      "z": 11,
      "name": "Plant_Leaves_Oak"
    },
    {
      "x": -4,
      "y": 25,
      "z": 11,
      "name": "Plant_Leaves_Oak"
    },
    {
      "x": -4,
      "y": 26,
      "z": 11,
      "name": "Plant_Leaves_Oak"
    },
    {
      "x": -4,
      "y": 12,
      "z": 12,
      "name": "Rock_Stone"
    },
    {
      "x": -4,
      "y": 13,
      "z": 12,
      "name": "Soil_Dirt"
    },
    {
      "x": -4,
      "y": 14,
      "z": 12,
      "name": "Soil_Grass"
    },
    {
      "x": -4,
      "y": 23,
      "z": 12,
      "name": "Plant_Leaves_Oak"
    },
    {
      "x": -4,
      "y": 24,
      "z": 12,
      "name": "Plant_Leaves_Oak"
    },
    {
      "x": -4,
      "y": 25,
      "z": 12,
      "name": "Plant_Leaves_Oak"
    },
    {
      "x": -4,
      "y": 12,
      "z": 13,
      "name": "Rock_Stone"
    },
    {
      "x": -4,
      "y": 13,
      "z": 13,
      "name": "Soil_Dirt"
    },
    {
      "x": -4,
      "y": 14,
      "z": 13,
      "name": "Soil_Grass"
    },
    {
      "x": -4,
      "y": 13,
      "z": 14,
      "name": "Soil_Dirt"
    },
    {
      "x": -4,
      "y": 14,
      "z": 14,
      "name": "Soil_Grass"
    },
    {
      "x": -4,
      "y": 14,
      "z": 15,
      "name": "Soil_Grass"
    },
    {
      "x": -3,
      "y": 13,
      "z": -8,
      "name": "Plant_Vine",
      "support": 15,
      "rotation": 2
    },
    {
      "x": -3,
      "y": 14,
      "z": -8,
      "name": "Soil_Grass"
    },
    {
      "x": -3,
      "y": 12,
      "z": -7,
      "name": "Plant_Vine",
      "support": 15,
      "rotation": 2
    },
    {
      "x": -3,
      "y": 13,
      "z": -7,
      "name": "Soil_Dirt"
    },
    {
      "x": -3,
      "y": 14,
      "z": -7,
      "name": "Soil_Grass"
    },
    {
      "x": -3,
      "y": 15,
      "z": -7,
      "name": "Plant_Grass_Sharp_Tall",
      "support": 15
    },
    {
      "x": -3,
      "y": 16,
      "z": -7,
      "name": "Plant_Grass_Sharp_Tall",
      "filler": 1024
    },
    {
      "x": -3,
      "y": 11,
      "z": -6,
      "name": "Plant_Vine",
      "support": 15,
      "rotation": 2
    },
    {
      "x": -3,
      "y": 12,
      "z": -6,
      "name": "Rock_Stone"
    },
    {
      "x": -3,
      "y": 13,
      "z": -6,
      "name": "Soil_Dirt"
    },
    {
      "x": -3,
      "y": 14,
      "z": -6,
      "name": "Soil_Grass"
    },
    {
      "x": -3,
      "y": 11,
      "z": -5,
      "name": "Rock_Stone"
    },
    {
      "x": -3,
      "y": 12,
      "z": -5,
      "name": "Rock_Stone"
    },
    {
      "x": -3,
      "y": 13,
      "z": -5,
      "name": "Soil_Dirt"
    },
    {
      "x": -3,
      "y": 14,
      "z": -5,
      "name": "Soil_Grass"
    },
    {
      "x": -3,
      "y": 15,
      "z": -5,
      "name": "Plant_Grass_Sharp_Tall",
      "support": 15
    },
    {
      "x": -3,
      "y": 16,
      "z": -5,
      "name": "Plant_Grass_Sharp_Tall",
      "filler": 1024
    },
    {
      "x": -3,
      "y": 11,
      "z": -4,
      "name": "Rock_Stone"
    },
    {
      "x": -3,
      "y": 12,
      "z": -4,
      "name": "Rock_Stone"
    },
    {
      "x": -3,
      "y": 13,
      "z": -4,
      "name": "Soil_Dirt"
    },
    {
      "x": -3,
      "y": 14,
      "z": -4,
      "name": "Soil_Grass"
    },
    {
      "x": -3,
      "y": 10,
      "z": -3,
      "name": "Rock_Stone"
    },
    {
      "x": -3,
      "y": 11,
      "z": -3,
      "name": "Rock_Stone"
    },
    {
      "x": -3,
      "y": 12,
      "z": -3,
      "name": "Rock_Stone"
    },
    {
      "x": -3,
      "y": 13,
      "z": -3,
      "name": "Soil_Dirt"
    },
    {
      "x": -3,
      "y": 14,
      "z": -3,
      "name": "Soil_Grass"
    },
    {
      "x": -3,
      "y": 9,
      "z": -2,
      "name": "Rock_Stone"
    },
    {
      "x": -3,
      "y": 10,
      "z": -2,
      "name": "Rock_Stone"
    },
    {
      "x": -3,
      "y": 11,
      "z": -2,
      "name": "Rock_Stone"
    },
    {
      "x": -3,
      "y": 12,
      "z": -2,
      "name": "Rock_Stone"
    },
    {
      "x": -3,
      "y": 13,
      "z": -2,
      "name": "Soil_Dirt"
    },
    {
      "x": -3,
      "y": 14,
      "z": -2,
      "name": "Soil_Grass"
    },
    {
      "x": -3,
      "y": 7,
      "z": -1,
      "name": "Rock_Stone_Mossy"
    },
    {
      "x": -3,
      "y": 8,
      "z": -1,
      "name": "Rock_Stone_Mossy"
    },
    {
      "x": -3,
      "y": 9,
      "z": -1,
      "name": "Rock_Stone"
    },
    {
      "x": -3,
      "y": 10,
      "z": -1,
      "name": "Rock_Stone"
    },
    {
      "x": -3,
      "y": 11,
      "z": -1,
      "name": "Rock_Stone"
    },
    {
      "x": -3,
      "y": 12,
      "z": -1,
      "name": "Rock_Stone"
    },
    {
      "x": -3,
      "y": 13,
      "z": -1,
      "name": "Soil_Dirt"
    },
    {
      "x": -3,
      "y": 14,
      "z": -1,
      "name": "Soil_Grass"
    },
    {
      "x": -3,
      "y": 5,
      "z": 0,
      "name": "Rock_Stone"
    },
    {
      "x": -3,
      "y": 6,
      "z": 0,
      "name": "Rock_Stone"
    },
    {
      "x": -3,
      "y": 7,
      "z": 0,
      "name": "Rock_Stone"
    },
    {
      "x": -3,
      "y": 8,
      "z": 0,
      "name": "Rock_Stone"
    },
    {
      "x": -3,
      "y": 9,
      "z": 0,
      "name": "Rock_Stone"
    },
    {
      "x": -3,
      "y": 10,
      "z": 0,
      "name": "Rock_Stone"
    },
    {
      "x": -3,
      "y": 11,
      "z": 0,
      "name": "Soil_Dirt"
    },
    {
      "x": -3,
      "y": 12,
      "z": 0,
      "name": "Soil_Dirt"
    },
    {
      "x": -3,
      "y": 13,
      "z": 0,
      "name": "Soil_Dirt"
    },
    {
      "x": -3,
      "y": 14,
      "z": 0,
      "name": "Soil_Dirt"
    },
    {
      "x": -3,
      "y": 15,
      "z": 0,
      "name": "Plant_Grass_Sharp_Wild",
      "support": 15
    },
    {
      "x": -3,
      "y": 16,
      "z": 0,
      "name": "Plant_Grass_Sharp_Wild",
      "filler": 1024
    },
    {
      "x": -3,
      "y": 4,
      "z": 1,
      "name": "Rock_Stone"
    },
    {
      "x": -3,
      "y": 5,
      "z": 1,
      "name": "Rock_Stone"
    },
    {
      "x": -3,
      "y": 6,
      "z": 1,
      "name": "Rock_Stone"
    },
    {
      "x": -3,
      "y": 7,
      "z": 1,
      "name": "Rock_Stone"
    },
    {
      "x": -3,
      "y": 8,
      "z": 1,
      "name": "Rock_Stone"
    },
    {
      "x": -3,
      "y": 9,
      "z": 1,
      "name": "Rock_Stone"
    },
    {
      "x": -3,
      "y": 10,
      "z": 1,
      "name": "Rock_Stone"
    },
    {
      "x": -3,
      "y": 11,
      "z": 1,
      "name": "Deco_Bone_Pile"
    },
    {
      "x": -3,
      "y": 14,
      "z": 1,
      "name": "Deco_SpiderWeb",
      "support": 15,
      "rotation": 10
    },
    {
      "x": -3,
      "y": 15,
      "z": 1,
      "name": "Soil_Grass"
    },
    {
      "x": -3,
      "y": 17,
      "z": 1,
      "name": "Plant_Vine_Wall",
      "rotation": 1
    },
    {
      "x": -3,
      "y": 18,
      "z": 1,
      "name": "Plant_Vine",
      "rotation": 1
    },
    {
      "x": -3,
      "y": 3,
      "z": 2,
      "name": "Plant_Vine_Wall",
      "support": 15,
      "rotation": 3
    },
    {
      "x": -3,
      "y": 4,
      "z": 2,
      "name": "Rock_Stone"
    },
    {
      "x": -3,
      "y": 5,
      "z": 2,
      "name": "Rock_Stone"
    },
    {
      "x": -3,
      "y": 6,
      "z": 2,
      "name": "Rock_Stone"
    },
    {
      "x": -3,
      "y": 7,
      "z": 2,
      "name": "Rock_Stone"
    },
    {
      "x": -3,
      "y": 8,
      "z": 2,
      "name": "Rock_Stone"
    },
    {
      "x": -3,
      "y": 9,
      "z": 2,
      "name": "Rock_Stone"
    },
    {
      "x": -3,
      "y": 10,
      "z": 2,
      "name": "Rock_Stone"
    },
    {
      "x": -3,
      "y": 15,
      "z": 2,
      "name": "Soil_Dirt"
    },
    {
      "x": -3,
      "y": 18,
      "z": 2,
      "name": "Wood_Softwood_Stairs",
      "rotation": 10
    },
    {
      "x": -3,
      "y": 19,
      "z": 2,
      "name": "Wood_Softwood_Roof",
      "rotation": 2
    },
    {
      "x": -3,
      "y": 3,
      "z": 3,
      "name": "Rock_Stone"
    },
    {
      "x": -3,
      "y": 4,
      "z": 3,
      "name": "Rock_Stone"
    },
    {
      "x": -3,
      "y": 5,
      "z": 3,
      "name": "Rock_Stone"
    },
    {
      "x": -3,
      "y": 6,
      "z": 3,
      "name": "Rock_Stone"
    },
    {
      "x": -3,
      "y": 7,
      "z": 3,
      "name": "Rock_Stone"
    },
    {
      "x": -3,
      "y": 8,
      "z": 3,
      "name": "Rock_Stone"
    },
    {
      "x": -3,
      "y": 9,
      "z": 3,
      "name": "Rock_Stone"
    },
    {
      "x": -3,
      "y": 10,
      "z": 3,
      "name": "Rock_Stone"
    },
    {
      "x": -3,
      "y": 12,
      "z": 3,
      "name": "Wood_Torch_Wall",
      "rotation": 1
    },
    {
      "x": -3,
      "y": 15,
      "z": 3,
      "name": "Soil_Dirt"
    },
    {
      "x": -3,
      "y": 19,
      "z": 3,
      "name": "Wood_Softwood_Stairs",
      "rotation": 10
    },
    {
      "x": -3,
      "y": 20,
      "z": 3,
      "name": "Wood_Softwood_Roof",
      "rotation": 2
    },
    {
      "x": -3,
      "y": 3,
      "z": 4,
      "name": "Rock_Stone"
    },
    {
      "x": -3,
      "y": 4,
      "z": 4,
      "name": "Rock_Stone"
    },
    {
      "x": -3,
      "y": 5,
      "z": 4,
      "name": "Rock_Stone"
    },
    {
      "x": -3,
      "y": 6,
      "z": 4,
      "name": "Rock_Stone"
    },
    {
      "x": -3,
      "y": 7,
      "z": 4,
      "name": "Rock_Stone"
    },
    {
      "x": -3,
      "y": 8,
      "z": 4,
      "name": "Rock_Stone"
    },
    {
      "x": -3,
      "y": 9,
      "z": 4,
      "name": "Rock_Stone"
    },
    {
      "x": -3,
      "y": 10,
      "z": 4,
      "name": "Rock_Stone"
    },
    {
      "x": -3,
      "y": 11,
      "z": 4,
      "name": "Plant_Moss_Rug_Green"
    },
    {
      "x": -3,
      "y": 14,
      "z": 4,
      "name": "Plant_Moss_Cave_Green",
      "rotation": 8
    },
    {
      "x": -3,
      "y": 15,
      "z": 4,
      "name": "Wood_Softwood_Planks_Half"
    },
    {
      "x": -3,
      "y": 20,
      "z": 4,
      "name": "Wood_Softwood_Planks"
    },
    {
      "x": -3,
      "y": 21,
      "z": 4,
      "name": "Wood_Softwood_Roof_Flat"
    },
    {
      "x": -3,
      "y": 3,
      "z": 5,
      "name": "Plant_Vine",
      "support": 15,
      "rotation": 3
    },
    {
      "x": -3,
      "y": 4,
      "z": 5,
      "name": "Rock_Stone"
    },
    {
      "x": -3,
      "y": 5,
      "z": 5,
      "name": "Rock_Stone"
    },
    {
      "x": -3,
      "y": 6,
      "z": 5,
      "name": "Rock_Stone"
    },
    {
      "x": -3,
      "y": 7,
      "z": 5,
      "name": "Rock_Stone"
    },
    {
      "x": -3,
      "y": 8,
      "z": 5,
      "name": "Rock_Stone"
    },
    {
      "x": -3,
      "y": 9,
      "z": 5,
      "name": "Rock_Stone"
    },
    {
      "x": -3,
      "y": 10,
      "z": 5,
      "name": "Rock_Stone"
    },
    {
      "x": -3,
      "y": 11,
      "z": 5,
      "name": "Plant_Moss_Rug_Green"
    },
    {
      "x": -3,
      "y": 19,
      "z": 5,
      "name": "Wood_Softwood_Beam",
      "rotation": 5
    },
    {
      "x": -3,
      "y": 3,
      "z": 6,
      "name": "Plant_Vine",
      "support": 15,
      "rotation": 3
    },
    {
      "x": -3,
      "y": 4,
      "z": 6,
      "name": "Rock_Stone_Mossy"
    },
    {
      "x": -3,
      "y": 5,
      "z": 6,
      "name": "Rock_Stone"
    },
    {
      "x": -3,
      "y": 6,
      "z": 6,
      "name": "Rock_Stone"
    },
    {
      "x": -3,
      "y": 7,
      "z": 6,
      "name": "Rock_Stone"
    },
    {
      "x": -3,
      "y": 8,
      "z": 6,
      "name": "Rock_Stone"
    },
    {
      "x": -3,
      "y": 9,
      "z": 6,
      "name": "Rock_Stone"
    },
    {
      "x": -3,
      "y": 10,
      "z": 6,
      "name": "Rock_Stone"
    },
    {
      "x": -3,
      "y": 14,
      "z": 6,
      "name": "Plant_Moss_Wall_Green",
      "rotation": 1
    },
    {
      "x": -3,
      "y": 4,
      "z": 7,
      "name": "Rock_Stone_Mossy"
    },
    {
      "x": -3,
      "y": 5,
      "z": 7,
      "name": "Rock_Stone_Mossy"
    },
    {
      "x": -3,
      "y": 6,
      "z": 7,
      "name": "Rock_Stone_Mossy"
    },
    {
      "x": -3,
      "y": 7,
      "z": 7,
      "name": "Rock_Stone"
    },
    {
      "x": -3,
      "y": 8,
      "z": 7,
      "name": "Rock_Stone"
    },
    {
      "x": -3,
      "y": 9,
      "z": 7,
      "name": "Rock_Stone"
    },
    {
      "x": -3,
      "y": 10,
      "z": 7,
      "name": "Rock_Stone"
    },
    {
      "x": -3,
      "y": 11,
      "z": 7,
      "name": "Furniture_Crude_Wardrobe",
      "rotation": 2
    },
    {
      "x": -3,
      "y": 12,
      "z": 7,
      "name": "Furniture_Crude_Wardrobe",
      "filler": 1024,
      "rotation": 2
    },
    {
      "x": -3,
      "y": 13,
      "z": 7,
      "name": "Plant_Moss_Rug_Green"
    },
    {
      "x": -3,
      "y": 15,
      "z": 7,
      "name": "Plant_Moss_Wall_Green",
      "rotation": 1
    },
    {
      "x": -3,
      "y": 16,
      "z": 7,
      "name": "Plant_Moss_Wall_Green",
      "rotation": 1
    },
    {
      "x": -3,
      "y": 6,
      "z": 8,
      "name": "Rock_Stone"
    },
    {
      "x": -3,
      "y": 7,
      "z": 8,
      "name": "Rock_Stone"
    },
    {
      "x": -3,
      "y": 8,
      "z": 8,
      "name": "Rock_Stone"
    },
    {
      "x": -3,
      "y": 9,
      "z": 8,
      "name": "Rock_Stone"
    },
    {
      "x": -3,
      "y": 10,
      "z": 8,
      "name": "Rock_Stone"
    },
    {
      "x": -3,
      "y": 11,
      "z": 8,
      "name": "Rock_Stone"
    },
    {
      "x": -3,
      "y": 12,
      "z": 8,
      "name": "Rock_Stone"
    },
    {
      "x": -3,
      "y": 13,
      "z": 8,
      "name": "Rock_Stone"
    },
    {
      "x": -3,
      "y": 14,
      "z": 8,
      "name": "Rock_Stone"
    },
    {
      "x": -3,
      "y": 7,
      "z": 9,
      "name": "Plant_Vine",
      "support": 15
    },
    {
      "x": -3,
      "y": 8,
      "z": 9,
      "name": "Plant_Vine",
      "support": 15
    },
    {
      "x": -3,
      "y": 9,
      "z": 9,
      "name": "Rock_Stone"
    },
    {
      "x": -3,
      "y": 10,
      "z": 9,
      "name": "Rock_Stone"
    },
    {
      "x": -3,
      "y": 11,
      "z": 9,
      "name": "Rock_Stone"
    },
    {
      "x": -3,
      "y": 12,
      "z": 9,
      "name": "Rock_Stone"
    },
    {
      "x": -3,
      "y": 13,
      "z": 9,
      "name": "Soil_Dirt"
    },
    {
      "x": -3,
      "y": 14,
      "z": 9,
      "name": "Soil_Grass"
    },
    {
      "x": -3,
      "y": 23,
      "z": 9,
      "name": "Plant_Leaves_Oak"
    },
    {
      "x": -3,
      "y": 24,
      "z": 9,
      "name": "Plant_Leaves_Oak"
    },
    {
      "x": -3,
      "y": 25,
      "z": 9,
      "name": "Plant_Leaves_Oak"
    },
    {
      "x": -3,
      "y": 9,
      "z": 10,
      "name": "Rock_Stone"
    },
    {
      "x": -3,
      "y": 10,
      "z": 10,
      "name": "Rock_Stone"
    },
    {
      "x": -3,
      "y": 11,
      "z": 10,
      "name": "Rock_Stone"
    },
    {
      "x": -3,
      "y": 12,
      "z": 10,
      "name": "Rock_Stone"
    },
    {
      "x": -3,
      "y": 13,
      "z": 10,
      "name": "Soil_Dirt"
    },
    {
      "x": -3,
      "y": 14,
      "z": 10,
      "name": "Soil_Grass"
    },
    {
      "x": -3,
      "y": 21,
      "z": 10,
      "name": "Plant_Leaves_Oak"
    },
    {
      "x": -3,
      "y": 22,
      "z": 10,
      "name": "Plant_Leaves_Oak"
    },
    {
      "x": -3,
      "y": 23,
      "z": 10,
      "name": "Plant_Leaves_Oak"
    },
    {
      "x": -3,
      "y": 24,
      "z": 10,
      "name": "Plant_Leaves_Oak"
    },
    {
      "x": -3,
      "y": 25,
      "z": 10,
      "name": "Plant_Leaves_Oak"
    },
    {
      "x": -3,
      "y": 8,
      "z": 11,
      "name": "Rock_Stone_Stalactite_Large",
      "filler": 31744,
      "rotation": 8
    },
    {
      "x": -3,
      "y": 9,
      "z": 11,
      "name": "Rock_Stone_Stalactite_Large",
      "rotation": 8
    },
    {
      "x": -3,
      "y": 10,
      "z": 11,
      "name": "Rock_Stone"
    },
    {
      "x": -3,
      "y": 11,
      "z": 11,
      "name": "Rock_Stone"
    },
    {
      "x": -3,
      "y": 12,
      "z": 11,
      "name": "Rock_Stone"
    },
    {
      "x": -3,
      "y": 13,
      "z": 11,
      "name": "Soil_Dirt"
    },
    {
      "x": -3,
      "y": 14,
      "z": 11,
      "name": "Soil_Grass"
    },
    {
      "x": -3,
      "y": 22,
      "z": 11,
      "name": "Plant_Leaves_Oak"
    },
    {
      "x": -3,
      "y": 23,
      "z": 11,
      "name": "Plant_Leaves_Oak"
    },
    {
      "x": -3,
      "y": 11,
      "z": 12,
      "name": "Rock_Stone"
    },
    {
      "x": -3,
      "y": 12,
      "z": 12,
      "name": "Rock_Stone"
    },
    {
      "x": -3,
      "y": 13,
      "z": 12,
      "name": "Soil_Dirt"
    },
    {
      "x": -3,
      "y": 14,
      "z": 12,
      "name": "Soil_Grass"
    },
    {
      "x": -3,
      "y": 12,
      "z": 13,
      "name": "Rock_Stone"
    },
    {
      "x": -3,
      "y": 13,
      "z": 13,
      "name": "Soil_Dirt"
    },
    {
      "x": -3,
      "y": 14,
      "z": 13,
      "name": "Soil_Grass"
    },
    {
      "x": -3,
      "y": 12,
      "z": 14,
      "name": "Plant_Vine",
      "support": 15
    },
    {
      "x": -3,
      "y": 13,
      "z": 14,
      "name": "Soil_Dirt"
    },
    {
      "x": -3,
      "y": 14,
      "z": 14,
      "name": "Soil_Grass"
    },
    {
      "x": -3,
      "y": 13,
      "z": 15,
      "name": "Plant_Vine",
      "support": 15
    },
    {
      "x": -3,
      "y": 14,
      "z": 15,
      "name": "Soil_Grass"
    },
    {
      "x": -3,
      "y": 15,
      "z": 15,
      "name": "Plant_Grass_Sharp",
      "support": 15
    },
    {
      "x": -2,
      "y": 14,
      "z": -8,
      "name": "Soil_Grass"
    },
    {
      "x": -2,
      "y": 13,
      "z": -7,
      "name": "Soil_Dirt"
    },
    {
      "x": -2,
      "y": 14,
      "z": -7,
      "name": "Soil_Grass"
    },
    {
      "x": -2,
      "y": 12,
      "z": -6,
      "name": "Rock_Stone"
    },
    {
      "x": -2,
      "y": 13,
      "z": -6,
      "name": "Soil_Dirt"
    },
    {
      "x": -2,
      "y": 14,
      "z": -6,
      "name": "Soil_Grass"
    },
    {
      "x": -2,
      "y": 11,
      "z": -5,
      "name": "Rock_Stone"
    },
    {
      "x": -2,
      "y": 12,
      "z": -5,
      "name": "Rock_Stone"
    },
    {
      "x": -2,
      "y": 13,
      "z": -5,
      "name": "Soil_Dirt"
    },
    {
      "x": -2,
      "y": 14,
      "z": -5,
      "name": "Soil_Grass"
    },
    {
      "x": -2,
      "y": 10,
      "z": -4,
      "name": "Rock_Stone"
    },
    {
      "x": -2,
      "y": 11,
      "z": -4,
      "name": "Rock_Stone"
    },
    {
      "x": -2,
      "y": 12,
      "z": -4,
      "name": "Rock_Stone"
    },
    {
      "x": -2,
      "y": 13,
      "z": -4,
      "name": "Soil_Dirt"
    },
    {
      "x": -2,
      "y": 14,
      "z": -4,
      "name": "Soil_Grass"
    },
    {
      "x": -2,
      "y": 8,
      "z": -3,
      "name": "Plant_Vine_Wall",
      "support": 15,
      "rotation": 2
    },
    {
      "x": -2,
      "y": 9,
      "z": -3,
      "name": "Rock_Stone"
    },
    {
      "x": -2,
      "y": 10,
      "z": -3,
      "name": "Rock_Stone"
    },
    {
      "x": -2,
      "y": 11,
      "z": -3,
      "name": "Rock_Stone"
    },
    {
      "x": -2,
      "y": 12,
      "z": -3,
      "name": "Rock_Stone"
    },
    {
      "x": -2,
      "y": 13,
      "z": -3,
      "name": "Soil_Dirt"
    },
    {
      "x": -2,
      "y": 14,
      "z": -3,
      "name": "Soil_Grass"
    },
    {
      "x": -2,
      "y": 15,
      "z": -3,
      "name": "Plant_Grass_Sharp",
      "support": 15
    },
    {
      "x": -2,
      "y": 8,
      "z": -2,
      "name": "Rock_Stone"
    },
    {
      "x": -2,
      "y": 9,
      "z": -2,
      "name": "Rock_Stone"
    },
    {
      "x": -2,
      "y": 10,
      "z": -2,
      "name": "Rock_Stone"
    },
    {
      "x": -2,
      "y": 11,
      "z": -2,
      "name": "Rock_Stone"
    },
    {
      "x": -2,
      "y": 12,
      "z": -2,
      "name": "Rock_Stone"
    },
    {
      "x": -2,
      "y": 13,
      "z": -2,
      "name": "Soil_Dirt"
    },
    {
      "x": -2,
      "y": 14,
      "z": -2,
      "name": "Soil_Grass"
    },
    {
      "x": -2,
      "y": 4,
      "z": -1,
      "name": "Rock_Stone_Stalactite_Large",
      "filler": 31744,
      "rotation": 8
    },
    {
      "x": -2,
      "y": 5,
      "z": -1,
      "name": "Rock_Stone_Stalactite_Large",
      "rotation": 8
    },
    {
      "x": -2,
      "y": 6,
      "z": -1,
      "name": "Rock_Stone"
    },
    {
      "x": -2,
      "y": 7,
      "z": -1,
      "name": "Rock_Stone"
    },
    {
      "x": -2,
      "y": 8,
      "z": -1,
      "name": "Rock_Stone"
    },
    {
      "x": -2,
      "y": 9,
      "z": -1,
      "name": "Rock_Stone"
    },
    {
      "x": -2,
      "y": 10,
      "z": -1,
      "name": "Rock_Stone"
    },
    {
      "x": -2,
      "y": 11,
      "z": -1,
      "name": "Rock_Stone"
    },
    {
      "x": -2,
      "y": 12,
      "z": -1,
      "name": "Rock_Stone"
    },
    {
      "x": -2,
      "y": 13,
      "z": -1,
      "name": "Soil_Dirt"
    },
    {
      "x": -2,
      "y": 14,
      "z": -1,
      "name": "Soil_Grass"
    },
    {
      "x": -2,
      "y": 5,
      "z": 0,
      "name": "Rock_Stone"
    },
    {
      "x": -2,
      "y": 6,
      "z": 0,
      "name": "Rock_Stone"
    },
    {
      "x": -2,
      "y": 7,
      "z": 0,
      "name": "Rock_Stone"
    },
    {
      "x": -2,
      "y": 8,
      "z": 0,
      "name": "Rock_Stone"
    },
    {
      "x": -2,
      "y": 9,
      "z": 0,
      "name": "Rock_Stone"
    },
    {
      "x": -2,
      "y": 10,
      "z": 0,
      "name": "Rock_Stone"
    },
    {
      "x": -2,
      "y": 11,
      "z": 0,
      "name": "Soil_Dirt"
    },
    {
      "x": -2,
      "y": 12,
      "z": 0,
      "name": "Soil_Dirt"
    },
    {
      "x": -2,
      "y": 13,
      "z": 0,
      "name": "Soil_Dirt"
    },
    {
      "x": -2,
      "y": 14,
      "z": 0,
      "name": "Soil_Dirt"
    },
    {
      "x": -2,
      "y": 15,
      "z": 0,
      "name": "Plant_Grass_Sharp_Wild",
      "support": 15
    },
    {
      "x": -2,
      "y": 16,
      "z": 0,
      "name": "Plant_Grass_Sharp_Wild",
      "filler": 1024
    },
    {
      "x": -2,
      "y": 1,
      "z": 1,
      "name": "Rock_Stone_Stalactite_Large",
      "filler": 31744,
      "rotation": 8
    },
    {
      "x": -2,
      "y": 2,
      "z": 1,
      "name": "Rock_Stone_Stalactite_Large",
      "rotation": 8
    },
    {
      "x": -2,
      "y": 3,
      "z": 1,
      "name": "Rock_Stone"
    },
    {
      "x": -2,
      "y": 4,
      "z": 1,
      "name": "Rock_Stone"
    },
    {
      "x": -2,
      "y": 5,
      "z": 1,
      "name": "Rock_Stone"
    },
    {
      "x": -2,
      "y": 6,
      "z": 1,
      "name": "Rock_Stone"
    },
    {
      "x": -2,
      "y": 7,
      "z": 1,
      "name": "Rock_Stone"
    },
    {
      "x": -2,
      "y": 8,
      "z": 1,
      "name": "Rock_Stone"
    },
    {
      "x": -2,
      "y": 9,
      "z": 1,
      "name": "Rock_Stone"
    },
    {
      "x": -2,
      "y": 10,
      "z": 1,
      "name": "Rock_Stone"
    },
    {
      "x": -2,
      "y": 11,
      "z": 1,
      "name": "Deco_Bone_Skulls"
    },
    {
      "x": -2,
      "y": 15,
      "z": 1,
      "name": "Soil_Grass"
    },
    {
      "x": -2,
      "y": 3,
      "z": 2,
      "name": "Rock_Stone"
    },
    {
      "x": -2,
      "y": 4,
      "z": 2,
      "name": "Rock_Stone"
    },
    {
      "x": -2,
      "y": 5,
      "z": 2,
      "name": "Rock_Stone"
    },
    {
      "x": -2,
      "y": 6,
      "z": 2,
      "name": "Rock_Stone"
    },
    {
      "x": -2,
      "y": 7,
      "z": 2,
