{
  "version": 8,
  "blockIdVersion": 11,
  "anchorX": 0,
  "anchorY": 0,
  "anchorZ": 0,
  "blocks": [
    {
      "x": -17,
      "y": 13,
      "z": 1,
      "name": "Plant_Vine_Wall",
      "support": 15,
      "rotation": 3
    },
    {
      "x": -17,
      "y": 14,
      "z": 1,
      "name": "Plant_Vine",
      "support": 15,
      "rotation": 3
    },
    {
      "x": -16,
      "y": 14,
      "z": -6,
      "name": "Plant_Vine_Wall",
      "support": 15,
      "rotation": 3
    },
    {
      "x": -16,
      "y": 13,
      "z": -3,
      "name": "Plant_Vine_Wall",
      "support": 15,
      "rotation": 3
    },
    {
      "x": -16,
      "y": 14,
      "z": -3,
      "name": "Plant_Vine",
      "support": 15,
      "rotation": 3
    },
    {
      "x": -16,
      "y": 13,
      "z": -2,
      "name": "Rock_Stone_Mossy"
    },
    {
      "x": -16,
      "y": 14,
      "z": -2,
      "name": "Rock_Stone_Mossy"
    },
    {
      "x": -16,
      "y": 13,
      "z": -1,
      "name": "Rock_Stone"
    },
    {
      "x": -16,
      "y": 14,
      "z": -1,
      "name": "Rock_Stone_Mossy"
    },
    {
      "x": -16,
      "y": 15,
      "z": -1,
      "name": "Rubble_Stone_Mossy",
      "support": 15
    },
    {
      "x": -16,
      "y": 13,
      "z": 0,
      "name": "Rock_Stone"
    },
    {
      "x": -16,
      "y": 14,
      "z": 0,
      "name": "Rock_Stone"
    },
    {
      "x": -16,
      "y": 12,
      "z": 1,
      "name": "Rock_Stone_Stalactite_Small",
      "rotation": 8
    },
    {
      "x": -16,
      "y": 13,
      "z": 1,
      "name": "Rock_Stone"
    },
    {
      "x": -16,
      "y": 14,
      "z": 1,
      "name": "Rock_Stone"
    },
    {
      "x": -16,
      "y": 13,
      "z": 2,
      "name": "Rock_Stone"
    },
    {
      "x": -16,
      "y": 14,
      "z": 2,
      "name": "Rock_Stone"
    },
    {
      "x": -16,
      "y": 13,
      "z": 5,
      "name": "Plant_Vine_Wall",
      "support": 15,
      "rotation": 3
    },
    {
      "x": -16,
      "y": 14,
      "z": 5,
      "name": "Plant_Vine",
      "support": 15,
      "rotation": 3
    },
    {
      "x": -15,
      "y": 13,
      "z": -6,
      "name": "Rock_Stone"
    },
    {
      "x": -15,
      "y": 14,
      "z": -6,
      "name": "Rock_Stone"
    },
    {
      "x": -15,
      "y": 13,
      "z": -5,
      "name": "Rock_Stone"
    },
    {
      "x": -15,
      "y": 14,
      "z": -5,
      "name": "Rock_Stone"
    },
    {
      "x": -15,
      "y": 11,
      "z": -4,
      "name": "Rock_Stone_Stalactite_Large",
      "filler": 31744,
      "rotation": 8
    },
    {
      "x": -15,
      "y": 12,
      "z": -4,
      "name": "Rock_Stone_Stalactite_Large",
      "rotation": 8
    },
    {
      "x": -15,
      "y": 13,
      "z": -4,
      "name": "Rock_Stone"
    },
    {
      "x": -15,
      "y": 14,
      "z": -4,
      "name": "Rock_Stone"
    },
    {
      "x": -15,
      "y": 13,
      "z": -3,
      "name": "Rock_Stone"
    },
    {
      "x": -15,
      "y": 14,
      "z": -3,
      "name": "Rock_Stone"
    },
    {
      "x": -15,
      "y": 13,
      "z": -2,
      "name": "Rock_Stone_Mossy"
    },
    {
      "x": -15,
      "y": 14,
      "z": -2,
      "name": "Rock_Stone"
    },
    {
      "x": -15,
      "y": 11,
      "z": -1,
      "name": "Plant_Vine_Wall",
      "support": 15,
      "rotation": 3
    },
    {
      "x": -15,
      "y": 12,
      "z": -1,
      "name": "Plant_Vine",
      "support": 15,
      "rotation": 3
    },
    {
      "x": -15,
      "y": 13,
      "z": -1,
      "name": "Rock_Stone"
    },
    {
      "x": -15,
      "y": 14,
      "z": -1,
      "name": "Soil_Grass"
    },
    {
      "x": -15,
      "y": 13,
      "z": 0,
      "name": "Rock_Stone"
    },
    {
      "x": -15,
      "y": 14,
      "z": 0,
      "name": "Soil_Grass"
    },
    {
      "x": -15,
      "y": 13,
      "z": 1,
      "name": "Rock_Stone"
    },
    {
      "x": -15,
      "y": 14,
      "z": 1,
      "name": "Soil_Grass"
    },
    {
      "x": -15,
      "y": 15,
      "z": 1,
      "name": "Plant_Grass_Sharp_Short",
      "support": 15
    },
    {
      "x": -15,
      "y": 13,
      "z": 2,
      "name": "Rock_Stone"
    },
    {
      "x": -15,
      "y": 14,
      "z": 2,
      "name": "Rock_Stone"
    },
    {
      "x": -15,
      "y": 12,
      "z": 3,
      "name": "Plant_Vine_Wall",
      "support": 15,
      "rotation": 3
    },
    {
      "x": -15,
      "y": 13,
      "z": 3,
      "name": "Rock_Stone_Mossy"
    },
    {
      "x": -15,
      "y": 14,
      "z": 3,
      "name": "Rock_Stone_Mossy"
    },
    {
      "x": -15,
      "y": 13,
      "z": 4,
      "name": "Rock_Stone_Mossy"
    },
    {
      "x": -15,
      "y": 14,
      "z": 4,
      "name": "Rock_Stone"
    },
    {
      "x": -15,
      "y": 11,
      "z": 5,
      "name": "Rock_Stone_Stalactite_Large",
      "filler": 31744,
      "rotation": 8
    },
    {
      "x": -15,
      "y": 12,
      "z": 5,
      "name": "Rock_Stone_Stalactite_Large",
      "rotation": 8
    },
    {
      "x": -15,
      "y": 13,
      "z": 5,
      "name": "Rock_Stone"
    },
    {
      "x": -15,
      "y": 14,
      "z": 5,
      "name": "Rock_Stone"
    },
    {
      "x": -15,
      "y": 13,
      "z": 6,
      "name": "Rock_Stone"
    },
    {
      "x": -15,
      "y": 14,
      "z": 6,
      "name": "Rock_Stone"
    },
    {
      "x": -14,
      "y": 13,
      "z": -9,
      "name": "Plant_Vine_Wall",
      "support": 15,
      "rotation": 2
    },
    {
      "x": -14,
      "y": 14,
      "z": -9,
      "name": "Plant_Vine",
      "support": 15,
      "rotation": 2
    },
    {
      "x": -14,
      "y": 11,
      "z": -8,
      "name": "Rock_Stone_Stalactite_Large",
      "filler": 31744,
      "rotation": 8
    },
    {
      "x": -14,
      "y": 12,
      "z": -8,
      "name": "Rock_Stone_Stalactite_Large",
      "rotation": 8
    },
    {
      "x": -14,
      "y": 13,
      "z": -8,
      "name": "Rock_Stone"
    },
    {
      "x": -14,
      "y": 14,
      "z": -8,
      "name": "Rock_Stone"
    },
    {
      "x": -14,
      "y": 13,
      "z": -7,
      "name": "Rock_Stone"
    },
    {
      "x": -14,
      "y": 14,
      "z": -7,
      "name": "Rock_Stone"
    },
    {
      "x": -14,
      "y": 13,
      "z": -6,
      "name": "Rock_Stone"
    },
    {
      "x": -14,
      "y": 14,
      "z": -6,
      "name": "Rock_Stone"
    },
    {
      "x": -14,
      "y": 12,
      "z": -5,
      "name": "Plant_Vine_Wall",
      "support": 15,
      "rotation": 3
    },
    {
      "x": -14,
      "y": 13,
      "z": -5,
      "name": "Rock_Stone"
    },
    {
      "x": -14,
      "y": 14,
      "z": -5,
      "name": "Soil_Grass"
    },
    {
      "x": -14,
      "y": 13,
      "z": -4,
      "name": "Rock_Stone"
    },
    {
      "x": -14,
      "y": 14,
      "z": -4,
      "name": "Soil_Grass"
    },
    {
      "x": -14,
      "y": 11,
      "z": -3,
      "name": "Rock_Stone_Mossy"
    },
    {
      "x": -14,
      "y": 12,
      "z": -3,
      "name": "Rock_Stone"
    },
    {
      "x": -14,
      "y": 13,
      "z": -3,
      "name": "Rock_Stone"
    },
    {
      "x": -14,
      "y": 14,
      "z": -3,
      "name": "Soil_Grass"
    },
    {
      "x": -14,
      "y": 11,
      "z": -2,
      "name": "Rock_Stone_Mossy"
    },
    {
      "x": -14,
      "y": 12,
      "z": -2,
      "name": "Rock_Stone_Mossy"
    },
    {
      "x": -14,
      "y": 13,
      "z": -2,
      "name": "Rock_Stone"
    },
    {
      "x": -14,
      "y": 14,
      "z": -2,
      "name": "Soil_Grass"
    },
    {
      "x": -14,
      "y": 15,
      "z": -2,
      "name": "Plant_Grass_Sharp_Short",
      "support": 15
    },
    {
      "x": -14,
      "y": 9,
      "z": -1,
      "name": "Rock_Stone_Stalactite_Large",
      "filler": 31744,
      "rotation": 8
    },
    {
      "x": -14,
      "y": 10,
      "z": -1,
      "name": "Rock_Stone_Stalactite_Large",
      "rotation": 8
    },
    {
      "x": -14,
      "y": 11,
      "z": -1,
      "name": "Rock_Stone"
    },
    {
      "x": -14,
      "y": 12,
      "z": -1,
      "name": "Rock_Stone"
    },
    {
      "x": -14,
      "y": 13,
      "z": -1,
      "name": "Rock_Stone"
    },
    {
      "x": -14,
      "y": 14,
      "z": -1,
      "name": "Soil_Grass"
    },
    {
      "x": -14,
      "y": 15,
      "z": -1,
      "name": "Plant_Flower_Tall_Yellow"
    },
    {
      "x": -14,
      "y": 11,
      "z": 0,
      "name": "Rock_Stone"
    },
    {
      "x": -14,
      "y": 12,
      "z": 0,
      "name": "Rock_Stone"
    },
    {
      "x": -14,
      "y": 13,
      "z": 0,
      "name": "Rock_Stone"
    },
    {
      "x": -14,
      "y": 14,
      "z": 0,
      "name": "Soil_Grass"
    },
    {
      "x": -14,
      "y": 11,
      "z": 1,
      "name": "Rock_Stone"
    },
    {
      "x": -14,
      "y": 12,
      "z": 1,
      "name": "Rock_Stone"
    },
    {
      "x": -14,
      "y": 13,
      "z": 1,
      "name": "Rock_Stone"
    },
    {
      "x": -14,
      "y": 14,
      "z": 1,
      "name": "Soil_Grass"
    },
    {
      "x": -14,
      "y": 11,
      "z": 2,
      "name": "Rock_Stone"
    },
    {
      "x": -14,
      "y": 12,
      "z": 2,
      "name": "Rock_Stone"
    },
    {
      "x": -14,
      "y": 13,
      "z": 2,
      "name": "Rock_Stone"
    },
    {
      "x": -14,
      "y": 14,
      "z": 2,
      "name": "Soil_Grass"
    },
    {
      "x": -14,
      "y": 10,
      "z": 3,
      "name": "Rock_Stone_Stalactite_Small",
      "rotation": 8
    },
    {
      "x": -14,
      "y": 11,
      "z": 3,
      "name": "Rock_Stone"
    },
    {
      "x": -14,
      "y": 12,
      "z": 3,
      "name": "Rock_Stone"
    },
    {
      "x": -14,
      "y": 13,
      "z": 3,
      "name": "Rock_Stone"
    },
    {
      "x": -14,
      "y": 14,
      "z": 3,
      "name": "Soil_Grass"
    },
    {
      "x": -14,
      "y": 13,
      "z": 4,
      "name": "Rock_Stone_Mossy"
    },
    {
      "x": -14,
      "y": 14,
      "z": 4,
      "name": "Soil_Grass"
    },
    {
      "x": -14,
      "y": 13,
      "z": 5,
      "name": "Rock_Stone"
    },
    {
      "x": -14,
      "y": 14,
      "z": 5,
      "name": "Soil_Grass"
    },
    {
      "x": -14,
      "y": 11,
      "z": 6,
      "name": "Plant_Vine_Wall",
      "support": 15,
      "rotation": 3
    },
    {
      "x": -14,
      "y": 12,
      "z": 6,
      "name": "Plant_Vine",
      "support": 15,
      "rotation": 3
    },
    {
      "x": -14,
      "y": 13,
      "z": 6,
      "name": "Rock_Stone"
    },
    {
      "x": -14,
      "y": 14,
      "z": 6,
      "name": "Rock_Stone"
    },
    {
      "x": -14,
      "y": 13,
      "z": 7,
      "name": "Rock_Stone"
    },
    {
      "x": -14,
      "y": 14,
      "z": 7,
      "name": "Rock_Stone"
    },
    {
      "x": -14,
      "y": 13,
      "z": 8,
      "name": "Rock_Stone"
    },
    {
      "x": -14,
      "y": 14,
      "z": 8,
      "name": "Rock_Stone"
    },
    {
      "x": -14,
      "y": 15,
      "z": 8,
      "name": "Rubble_Stone",
      "support": 15
    },
    {
      "x": -13,
      "y": 13,
      "z": -9,
      "name": "Rock_Stone"
    },
    {
      "x": -13,
      "y": 14,
      "z": -9,
      "name": "Rock_Stone"
    },
    {
      "x": -13,
      "y": 13,
      "z": -8,
      "name": "Rock_Stone"
    },
    {
      "x": -13,
      "y": 14,
      "z": -8,
      "name": "Rock_Stone"
    },
    {
      "x": -13,
      "y": 13,
      "z": -7,
      "name": "Rock_Stone"
    },
    {
      "x": -13,
      "y": 14,
      "z": -7,
      "name": "Soil_Grass"
    },
    {
      "x": -13,
      "y": 11,
      "z": -6,
      "name": "Rock_Stone"
    },
    {
      "x": -13,
      "y": 12,
      "z": -6,
      "name": "Rock_Stone"
    },
    {
      "x": -13,
      "y": 13,
      "z": -6,
      "name": "Rock_Stone"
    },
    {
      "x": -13,
      "y": 14,
      "z": -6,
      "name": "Soil_Grass"
    },
    {
      "x": -13,
      "y": 10,
      "z": -5,
      "name": "Rock_Stone_Stalactite_Small",
      "rotation": 8
    },
    {
      "x": -13,
      "y": 11,
      "z": -5,
      "name": "Rock_Stone"
    },
    {
      "x": -13,
      "y": 12,
      "z": -5,
      "name": "Rock_Stone"
    },
    {
      "x": -13,
      "y": 13,
      "z": -5,
      "name": "Rock_Stone"
    },
    {
      "x": -13,
      "y": 14,
      "z": -5,
      "name": "Soil_Grass"
    },
    {
      "x": -13,
      "y": 11,
      "z": -4,
      "name": "Rock_Stone_Mossy"
    },
    {
      "x": -13,
      "y": 12,
      "z": -4,
      "name": "Rock_Stone"
    },
    {
      "x": -13,
      "y": 13,
      "z": -4,
      "name": "Rock_Stone"
    },
    {
      "x": -13,
      "y": 14,
      "z": -4,
      "name": "Soil_Grass"
    },
    {
      "x": -13,
      "y": 15,
      "z": -4,
      "name": "Plant_Grass_Sharp_Short",
      "support": 15
    },
    {
      "x": -13,
      "y": 11,
      "z": -3,
      "name": "Rock_Stone"
    },
    {
      "x": -13,
      "y": 12,
      "z": -3,
      "name": "Rock_Stone"
    },
    {
      "x": -13,
      "y": 13,
      "z": -3,
      "name": "Rock_Stone"
    },
    {
      "x": -13,
      "y": 14,
      "z": -3,
      "name": "Soil_Grass"
    },
    {
      "x": -13,
      "y": 10,
      "z": -2,
      "name": "Plant_Vine_Wall",
      "support": 15,
      "rotation": 3
    },
    {
      "x": -13,
      "y": 11,
      "z": -2,
      "name": "Rock_Stone"
    },
    {
      "x": -13,
      "y": 12,
      "z": -2,
      "name": "Rock_Stone"
    },
    {
      "x": -13,
      "y": 13,
      "z": -2,
      "name": "Rock_Stone"
    },
    {
      "x": -13,
      "y": 14,
      "z": -2,
      "name": "Soil_Grass"
    },
    {
      "x": -13,
      "y": 11,
      "z": -1,
      "name": "Rock_Stone"
    },
    {
      "x": -13,
      "y": 12,
      "z": -1,
      "name": "Rock_Stone"
    },
    {
      "x": -13,
      "y": 13,
      "z": -1,
      "name": "Rock_Stone"
    },
    {
      "x": -13,
      "y": 14,
      "z": -1,
      "name": "Soil_Grass"
    },
    {
      "x": -13,
      "y": 11,
      "z": 0,
      "name": "Rock_Stone"
    },
    {
      "x": -13,
      "y": 12,
      "z": 0,
      "name": "Rock_Stone"
    },
    {
      "x": -13,
      "y": 13,
      "z": 0,
      "name": "Rock_Stone"
    },
    {
      "x": -13,
      "y": 14,
      "z": 0,
      "name": "Soil_Grass"
    },
    {
      "x": -13,
      "y": 15,
      "z": 0,
      "name": "Plant_Grass_Sharp_Short",
      "support": 15
    },
    {
      "x": -13,
      "y": 11,
      "z": 1,
      "name": "Rock_Stone"
    },
    {
      "x": -13,
      "y": 12,
      "z": 1,
      "name": "Rock_Stone"
    },
    {
      "x": -13,
      "y": 13,
      "z": 1,
      "name": "Rock_Stone"
    },
    {
      "x": -13,
      "y": 14,
      "z": 1,
      "name": "Soil_Grass"
    },
    {
      "x": -13,
      "y": 15,
      "z": 1,
      "name": "Plant_Grass_Sharp_Tall",
      "support": 15
    },
    {
      "x": -13,
      "y": 16,
      "z": 1,
      "name": "Plant_Grass_Sharp_Tall",
      "filler": 1024
    },
    {
      "x": -13,
      "y": 11,
      "z": 2,
      "name": "Rock_Stone"
    },
    {
      "x": -13,
      "y": 12,
      "z": 2,
      "name": "Rock_Stone"
    },
    {
      "x": -13,
      "y": 13,
      "z": 2,
      "name": "Rock_Stone"
    },
    {
      "x": -13,
      "y": 14,
      "z": 2,
      "name": "Soil_Grass"
    },
    {
      "x": -13,
      "y": 9,
      "z": 3,
      "name": "Plant_Vine_Wall",
      "support": 15,
      "rotation": 3
    },
    {
      "x": -13,
      "y": 10,
      "z": 3,
      "name": "Plant_Vine",
      "support": 15,
      "rotation": 3
    },
    {
      "x": -13,
      "y": 11,
      "z": 3,
      "name": "Rock_Stone"
    },
    {
      "x": -13,
      "y": 12,
      "z": 3,
      "name": "Rock_Stone"
    },
    {
      "x": -13,
      "y": 13,
      "z": 3,
      "name": "Rock_Stone"
    },
    {
      "x": -13,
      "y": 14,
      "z": 3,
      "name": "Soil_Grass"
    },
    {
      "x": -13,
      "y": 15,
      "z": 3,
      "name": "Plant_Grass_Sharp_Short",
      "support": 15
    },
    {
      "x": -13,
      "y": 11,
      "z": 4,
      "name": "Rock_Stone_Mossy"
    },
    {
      "x": -13,
      "y": 12,
      "z": 4,
      "name": "Rock_Stone_Mossy"
    },
    {
      "x": -13,
      "y": 13,
      "z": 4,
      "name": "Rock_Stone"
    },
    {
      "x": -13,
      "y": 14,
      "z": 4,
      "name": "Soil_Grass"
    },
    {
      "x": -13,
      "y": 15,
      "z": 4,
      "name": "Plant_Grass_Sharp",
      "support": 15
    },
    {
      "x": -13,
      "y": 11,
      "z": 5,
      "name": "Rock_Stone_Mossy"
    },
    {
      "x": -13,
      "y": 12,
      "z": 5,
      "name": "Rock_Stone"
    },
    {
      "x": -13,
      "y": 13,
      "z": 5,
      "name": "Rock_Stone"
    },
    {
      "x": -13,
      "y": 14,
      "z": 5,
      "name": "Soil_Grass"
    },
    {
      "x": -13,
      "y": 11,
      "z": 6,
      "name": "Rock_Stone"
    },
    {
      "x": -13,
      "y": 12,
      "z": 6,
      "name": "Rock_Stone"
    },
    {
      "x": -13,
      "y": 13,
      "z": 6,
      "name": "Rock_Stone"
    },
    {
      "x": -13,
      "y": 14,
      "z": 6,
      "name": "Soil_Grass"
    },
    {
      "x": -13,
      "y": 12,
      "z": 7,
      "name": "Plant_Vine_Wall",
      "support": 15
    },
    {
      "x": -13,
      "y": 13,
      "z": 7,
      "name": "Rock_Stone"
    },
    {
      "x": -13,
      "y": 14,
      "z": 7,
      "name": "Soil_Grass"
    },
    {
      "x": -13,
      "y": 13,
      "z": 8,
      "name": "Rock_Stone"
    },
    {
      "x": -13,
      "y": 14,
      "z": 8,
      "name": "Rock_Stone"
    },
    {
      "x": -13,
      "y": 13,
      "z": 9,
      "name": "Rock_Stone"
    },
    {
      "x": -13,
      "y": 14,
      "z": 9,
      "name": "Rock_Stone"
    },
    {
      "x": -12,
      "y": 14,
      "z": -11,
      "name": "Plant_Vine_Wall",
      "support": 15,
      "rotation": 3
    },
    {
      "x": -12,
      "y": 13,
      "z": -10,
      "name": "Rock_Stone"
    },
    {
      "x": -12,
      "y": 14,
      "z": -10,
      "name": "Rock_Stone"
    },
    {
      "x": -12,
      "y": 21,
      "z": -10,
      "name": "Plant_Leaves_Oak",
      "support": 1
    },
    {
      "x": -12,
      "y": 13,
      "z": -9,
      "name": "Rock_Stone"
    },
    {
      "x": -12,
      "y": 14,
      "z": -9,
      "name": "Rock_Stone"
    },
    {
      "x": -12,
      "y": 12,
      "z": -8,
      "name": "Plant_Vine_Wall",
      "support": 15,
      "rotation": 3
    },
    {
      "x": -12,
      "y": 13,
      "z": -8,
      "name": "Rock_Stone"
    },
    {
      "x": -12,
      "y": 14,
      "z": -8,
      "name": "Soil_Grass"
    },
    {
      "x": -12,
      "y": 11,
      "z": -7,
      "name": "Rock_Stone"
    },
    {
      "x": -12,
      "y": 12,
      "z": -7,
      "name": "Rock_Stone"
    },
    {
      "x": -12,
      "y": 13,
      "z": -7,
      "name": "Rock_Stone"
    },
    {
      "x": -12,
      "y": 14,
      "z": -7,
      "name": "Soil_Grass"
    },
    {
      "x": -12,
      "y": 9,
      "z": -6,
      "name": "Plant_Vine_Wall",
      "support": 15,
      "rotation": 3
    },
    {
      "x": -12,
      "y": 10,
      "z": -6,
      "name": "Plant_Vine",
      "support": 15,
      "rotation": 3
    },
    {
      "x": -12,
      "y": 11,
      "z": -6,
      "name": "Rock_Stone"
    },
    {
      "x": -12,
      "y": 12,
      "z": -6,
      "name": "Rock_Stone"
    },
    {
      "x": -12,
      "y": 13,
      "z": -6,
      "name": "Rock_Stone"
    },
    {
      "x": -12,
      "y": 14,
      "z": -6,
      "name": "Soil_Grass"
    },
    {
      "x": -12,
      "y": 15,
      "z": -6,
      "name": "Plant_Grass_Sharp_Tall",
      "support": 15
    },
    {
      "x": -12,
      "y": 16,
      "z": -6,
      "name": "Plant_Grass_Sharp_Tall",
      "filler": 1024
    },
    {
      "x": -12,
      "y": 11,
      "z": -5,
      "name": "Rock_Stone"
    },
    {
      "x": -12,
      "y": 12,
      "z": -5,
      "name": "Rock_Stone"
    },
    {
      "x": -12,
      "y": 13,
      "z": -5,
      "name": "Rock_Stone"
    },
    {
      "x": -12,
      "y": 14,
      "z": -5,
      "name": "Soil_Grass"
    },
    {
      "x": -12,
      "y": 11,
      "z": -4,
      "name": "Rock_Stone_Mossy"
    },
    {
      "x": -12,
      "y": 12,
      "z": -4,
      "name": "Rock_Stone"
    },
    {
      "x": -12,
      "y": 13,
      "z": -4,
      "name": "Rock_Stone"
    },
    {
      "x": -12,
      "y": 14,
      "z": -4,
      "name": "Soil_Grass"
    },
    {
      "x": -12,
      "y": 9,
      "z": -3,
      "name": "Rock_Stone"
    },
    {
      "x": -12,
      "y": 10,
      "z": -3,
      "name": "Rock_Stone"
    },
    {
      "x": -12,
      "y": 11,
      "z": -3,
      "name": "Rock_Stone"
    },
    {
      "x": -12,
      "y": 12,
      "z": -3,
      "name": "Rock_Stone"
    },
    {
      "x": -12,
      "y": 13,
      "z": -3,
      "name": "Rock_Stone"
    },
    {
      "x": -12,
      "y": 14,
      "z": -3,
      "name": "Soil_Grass"
    },
    {
      "x": -12,
      "y": 7,
      "z": -2,
      "name": "Rock_Stone_Stalactite_Large",
      "filler": 31744,
      "rotation": 8
    },
    {
      "x": -12,
      "y": 8,
      "z": -2,
      "name": "Rock_Stone_Stalactite_Large",
      "rotation": 8
    },
    {
      "x": -12,
      "y": 9,
      "z": -2,
      "name": "Rock_Stone"
    },
    {
      "x": -12,
      "y": 10,
      "z": -2,
      "name": "Rock_Stone"
    },
    {
      "x": -12,
      "y": 11,
      "z": -2,
      "name": "Rock_Stone"
    },
    {
      "x": -12,
      "y": 12,
      "z": -2,
      "name": "Rock_Stone"
    },
    {
      "x": -12,
      "y": 13,
      "z": -2,
      "name": "Rock_Stone"
    },
    {
      "x": -12,
      "y": 14,
      "z": -2,
      "name": "Soil_Grass"
    },
    {
      "x": -12,
      "y": 15,
      "z": -2,
      "name": "Plant_Grass_Sharp",
      "support": 15
    },
    {
      "x": -12,
      "y": 9,
      "z": -1,
      "name": "Rock_Stone"
    },
    {
      "x": -12,
      "y": 10,
      "z": -1,
      "name": "Rock_Stone"
    },
    {
      "x": -12,
      "y": 11,
      "z": -1,
      "name": "Rock_Stone"
    },
    {
      "x": -12,
      "y": 12,
      "z": -1,
      "name": "Rock_Stone"
    },
    {
      "x": -12,
      "y": 13,
      "z": -1,
      "name": "Rock_Stone"
    },
    {
      "x": -12,
      "y": 14,
      "z": -1,
      "name": "Soil_Grass"
    },
    {
      "x": -12,
      "y": 9,
      "z": 0,
      "name": "Rock_Stone"
    },
    {
      "x": -12,
      "y": 10,
      "z": 0,
      "name": "Rock_Stone"
    },
    {
      "x": -12,
      "y": 11,
      "z": 0,
      "name": "Rock_Stone"
    },
    {
      "x": -12,
      "y": 12,
      "z": 0,
      "name": "Rock_Stone"
    },
    {
      "x": -12,
      "y": 13,
      "z": 0,
      "name": "Rock_Stone"
    },
    {
      "x": -12,
      "y": 14,
      "z": 0,
      "name": "Soil_Grass"
    },
    {
      "x": -12,
      "y": 9,
      "z": 1,
      "name": "Rock_Stone"
    },
    {
      "x": -12,
      "y": 10,
      "z": 1,
      "name": "Rock_Stone"
    },
    {
      "x": -12,
      "y": 11,
      "z": 1,
      "name": "Rock_Stone"
    },
    {
      "x": -12,
      "y": 12,
      "z": 1,
      "name": "Rock_Stone"
    },
    {
      "x": -12,
      "y": 13,
      "z": 1,
      "name": "Rock_Stone"
    },
    {
      "x": -12,
      "y": 14,
      "z": 1,
      "name": "Soil_Grass"
    },
    {
      "x": -12,
      "y": 8,
      "z": 2,
      "name": "Rock_Stone_Stalactite_Small",
      "rotation": 8
    },
    {
      "x": -12,
      "y": 9,
      "z": 2,
      "name": "Rock_Stone"
    },
    {
      "x": -12,
      "y": 10,
      "z": 2,
      "name": "Rock_Stone"
    },
    {
      "x": -12,
      "y": 11,
      "z": 2,
      "name": "Rock_Stone"
    },
    {
      "x": -12,
      "y": 12,
      "z": 2,
      "name": "Rock_Stone"
    },
    {
      "x": -12,
      "y": 13,
      "z": 2,
      "name": "Rock_Stone"
    },
    {
      "x": -12,
      "y": 14,
      "z": 2,
      "name": "Soil_Grass"
    },
    {
      "x": -12,
      "y": 15,
      "z": 2,
      "name": "Plant_Grass_Sharp",
      "support": 15
    },
    {
      "x": -12,
      "y": 9,
      "z": 3,
      "name": "Rock_Stone"
    },
    {
      "x": -12,
      "y": 10,
      "z": 3,
      "name": "Rock_Stone"
    },
    {
      "x": -12,
      "y": 11,
      "z": 3,
      "name": "Rock_Stone"
    },
    {
      "x": -12,
      "y": 12,
      "z": 3,
      "name": "Rock_Stone"
    },
    {
      "x": -12,
      "y": 13,
      "z": 3,
      "name": "Rock_Stone"
    },
    {
      "x": -12,
      "y": 14,
      "z": 3,
      "name": "Soil_Grass"
    },
    {
      "x": -12,
      "y": 10,
      "z": 4,
      "name": "Plant_Vine_Wall",
      "support": 15
    },
    {
      "x": -12,
      "y": 11,
      "z": 4,
      "name": "Rock_Stone"
    },
    {
      "x": -12,
      "y": 12,
      "z": 4,
      "name": "Rock_Stone"
    },
    {
      "x": -12,
      "y": 13,
      "z": 4,
      "name": "Rock_Stone"
    },
    {
      "x": -12,
      "y": 14,
      "z": 4,
      "name": "Soil_Grass"
    },
    {
      "x": -12,
      "y": 11,
      "z": 5,
      "name": "Rock_Stone_Mossy"
    },
    {
      "x": -12,
      "y": 12,
      "z": 5,
      "name": "Rock_Stone"
    },
    {
      "x": -12,
      "y": 13,
      "z": 5,
      "name": "Rock_Stone"
    },
    {
      "x": -12,
      "y": 14,
      "z": 5,
      "name": "Soil_Grass"
    },
    {
      "x": -12,
      "y": 15,
      "z": 5,
      "name": "Plant_Grass_Sharp_Tall",
      "support": 15
    },
    {
      "x": -12,
      "y": 16,
      "z": 5,
      "name": "Plant_Grass_Sharp_Tall",
      "filler": 1024
    },
    {
      "x": -12,
      "y": 9,
      "z": 6,
      "name": "Rock_Stone_Stalactite_Large",
      "filler": 31744,
      "rotation": 8
    },
    {
      "x": -12,
      "y": 10,
      "z": 6,
      "name": "Rock_Stone_Stalactite_Large",
      "rotation": 8
    },
    {
      "x": -12,
      "y": 11,
      "z": 6,
      "name": "Rock_Stone"
    },
    {
      "x": -12,
      "y": 12,
      "z": 6,
      "name": "Rock_Stone"
    },
    {
      "x": -12,
      "y": 13,
      "z": 6,
      "name": "Rock_Stone"
    },
    {
      "x": -12,
      "y": 14,
      "z": 6,
      "name": "Soil_Grass"
    },
    {
      "x": -12,
      "y": 11,
      "z": 7,
      "name": "Rock_Stone"
    },
    {
      "x": -12,
      "y": 12,
      "z": 7,
      "name": "Rock_Stone"
    },
    {
      "x": -12,
      "y": 13,
      "z": 7,
      "name": "Rock_Stone"
    },
    {
      "x": -12,
      "y": 14,
      "z": 7,
      "name": "Soil_Grass"
    },
    {
      "x": -12,
      "y": 15,
      "z": 7,
      "name": "Plant_Flower_Common_Pink"
    },
    {
      "x": -12,
      "y": 16,
      "z": 7,
      "name": "Plant_Flower_Common_Pink",
      "filler": 1024
    },
    {
      "x": -12,
      "y": 12,
      "z": 8,
      "name": "Rock_Stone_Stalactite_Small",
      "rotation": 8
    },
    {
      "x": -12,
      "y": 13,
      "z": 8,
      "name": "Rock_Stone"
    },
    {
      "x": -12,
      "y": 14,
      "z": 8,
      "name": "Soil_Grass"
    },
    {
      "x": -12,
      "y": 13,
      "z": 9,
      "name": "Rock_Stone"
    },
    {
      "x": -12,
      "y": 14,
      "z": 9,
      "name": "Rock_Stone"
    },
    {
      "x": -12,
      "y": 13,
      "z": 10,
      "name": "Rock_Stone"
    },
    {
      "x": -12,
      "y": 14,
      "z": 10,
      "name": "Rock_Stone"
    },
    {
      "x": -12,
      "y": 14,
      "z": 11,
      "name": "Plant_Vine_Wall",
      "support": 15
    },
    {
      "x": -11,
      "y": 12,
      "z": -11,
      "name": "Rock_Stone_Stalactite_Small",
      "rotation": 8
    },
    {
      "x": -11,
      "y": 13,
      "z": -11,
      "name": "Rock_Stone"
    },
    {
      "x": -11,
      "y": 14,
      "z": -11,
      "name": "Rock_Stone"
    },
    {
      "x": -11,
      "y": 21,
      "z": -11,
      "name": "Plant_Leaves_Oak",
      "support": 1
    },
    {
      "x": -11,
      "y": 24,
      "z": -11,
      "name": "Plant_Leaves_Oak",
      "support": 2
    },
    {
      "x": -11,
      "y": 11,
      "z": -10,
      "name": "Plant_Vine_Wall",
      "support": 15,
      "rotation": 2
    },
    {
      "x": -11,
      "y": 12,
      "z": -10,
      "name": "Plant_Vine",
      "support": 15,
      "rotation": 2
    },
    {
      "x": -11,
      "y": 13,
      "z": -10,
      "name": "Rock_Stone"
    },
    {
      "x": -11,
      "y": 14,
      "z": -10,
      "name": "Rock_Stone"
    },
    {
      "x": -11,
      "y": 15,
      "z": -10,
      "name": "Rubble_Stone",
      "support": 15
    },
    {
      "x": -11,
      "y": 20,
      "z": -10,
      "name": "Plant_Leaves_Oak",
      "support": 1
    },
    {
      "x": -11,
      "y": 21,
      "z": -10,
      "name": "Plant_Leaves_Oak"
    },
    {
      "x": -11,
      "y": 22,
      "z": -10,
      "name": "Plant_Leaves_Oak",
      "support": 1
    },
    {
      "x": -11,
      "y": 9,
      "z": -9,
      "name": "Rock_Stone_Stalactite_Large",
      "filler": 31744,
      "rotation": 8
    },
    {
      "x": -11,
      "y": 10,
      "z": -9,
      "name": "Rock_Stone_Stalactite_Large",
      "rotation": 8
    },
    {
      "x": -11,
      "y": 11,
      "z": -9,
      "name": "Rock_Stone"
    },
    {
      "x": -11,
      "y": 12,
      "z": -9,
      "name": "Rock_Stone"
    },
    {
      "x": -11,
      "y": 13,
      "z": -9,
      "name": "Rock_Stone"
    },
    {
      "x": -11,
      "y": 14,
      "z": -9,
      "name": "Soil_Grass"
    },
    {
      "x": -11,
      "y": 21,
      "z": -9,
      "name": "Plant_Leaves_Oak",
      "support": 1
    },
    {
      "x": -11,
      "y": 22,
      "z": -9,
      "name": "Plant_Leaves_Oak",
      "support": 2
    },
    {
      "x": -11,
      "y": 24,
      "z": -9,
      "name": "Plant_Leaves_Oak",
      "support": 2
    },
    {
      "x": -11,
      "y": 11,
      "z": -8,
      "name": "Rock_Stone"
    },
    {
      "x": -11,
      "y": 12,
      "z": -8,
      "name": "Rock_Stone"
    },
    {
      "x": -11,
      "y": 13,
      "z": -8,
      "name": "Rock_Stone"
    },
    {
      "x": -11,
      "y": 14,
      "z": -8,
      "name": "Soil_Grass"
    },
    {
      "x": -11,
      "y": 15,
      "z": -8,
      "name": "Plant_Grass_Sharp_Short",
      "support": 15
    },
    {
      "x": -11,
      "y": 21,
      "z": -8,
      "name": "Plant_Leaves_Oak",
      "support": 2
    },
    {
      "x": -11,
      "y": 11,
      "z": -7,
      "name": "Rock_Stone"
    },
    {
      "x": -11,
      "y": 12,
      "z": -7,
      "name": "Rock_Stone"
    },
    {
      "x": -11,
      "y": 13,
      "z": -7,
      "name": "Rock_Stone"
    },
    {
      "x": -11,
      "y": 14,
      "z": -7,
      "name": "Soil_Grass"
    },
    {
      "x": -11,
      "y": 9,
      "z": -6,
      "name": "Rock_Stone"
    },
    {
      "x": -11,
      "y": 10,
      "z": -6,
      "name": "Rock_Stone"
    },
    {
      "x": -11,
      "y": 11,
      "z": -6,
      "name": "Rock_Stone"
    },
    {
      "x": -11,
      "y": 12,
      "z": -6,
      "name": "Rock_Stone"
    },
    {
      "x": -11,
      "y": 13,
      "z": -6,
      "name": "Rock_Stone"
    },
    {
      "x": -11,
      "y": 14,
      "z": -6,
      "name": "Soil_Grass"
    },
    {
      "x": -11,
      "y": 9,
      "z": -5,
      "name": "Rock_Stone_Mossy"
    },
    {
      "x": -11,
      "y": 10,
      "z": -5,
      "name": "Rock_Stone"
    },
    {
      "x": -11,
      "y": 11,
      "z": -5,
      "name": "Rock_Stone"
    },
    {
      "x": -11,
      "y": 12,
      "z": -5,
      "name": "Rock_Stone"
    },
    {
      "x": -11,
      "y": 13,
      "z": -5,
      "name": "Rock_Stone"
    },
    {
      "x": -11,
      "y": 14,
      "z": -5,
      "name": "Soil_Grass"
    },
    {
      "x": -11,
      "y": 9,
      "z": -4,
      "name": "Rock_Stone_Mossy"
    },
    {
      "x": -11,
      "y": 10,
      "z": -4,
      "name": "Rock_Stone_Mossy"
    },
    {
      "x": -11,
      "y": 11,
      "z": -4,
      "name": "Rock_Stone"
    },
    {
      "x": -11,
      "y": 12,
      "z": -4,
      "name": "Rock_Stone"
    },
    {
      "x": -11,
      "y": 13,
      "z": -4,
      "name": "Rock_Stone"
    },
    {
      "x": -11,
      "y": 14,
      "z": -4,
      "name": "Soil_Grass"
    },
    {
      "x": -11,
      "y": 15,
      "z": -4,
      "name": "Plant_Grass_Sharp",
      "support": 15
    },
    {
      "x": -11,
      "y": 9,
      "z": -3,
      "name": "Rock_Stone"
    },
    {
      "x": -11,
      "y": 10,
      "z": -3,
      "name": "Rock_Stone"
    },
    {
      "x": -11,
      "y": 11,
      "z": -3,
      "name": "Rock_Stone"
    },
    {
      "x": -11,
      "y": 12,
      "z": -3,
      "name": "Rock_Stone"
    },
    {
      "x": -11,
      "y": 13,
      "z": -3,
      "name": "Rock_Stone"
    },
    {
      "x": -11,
      "y": 14,
      "z": -3,
      "name": "Soil_Grass"
    },
    {
      "x": -11,
      "y": 9,
      "z": -2,
      "name": "Rock_Stone"
    },
    {
      "x": -11,
      "y": 10,
      "z": -2,
      "name": "Rock_Stone"
    },
    {
      "x": -11,
      "y": 11,
      "z": -2,
      "name": "Rock_Stone"
    },
    {
      "x": -11,
      "y": 12,
      "z": -2,
      "name": "Rock_Stone"
    },
    {
      "x": -11,
      "y": 13,
      "z": -2,
      "name": "Rock_Stone"
    },
    {
      "x": -11,
      "y": 14,
      "z": -2,
      "name": "Soil_Grass"
    },
    {
      "x": -11,
      "y": 9,
      "z": -1,
      "name": "Rock_Stone"
    },
    {
      "x": -11,
      "y": 10,
      "z": -1,
      "name": "Rock_Stone"
    },
    {
      "x": -11,
      "y": 11,
      "z": -1,
      "name": "Rock_Stone"
    },
    {
      "x": -11,
      "y": 12,
      "z": -1,
      "name": "Rock_Stone"
    },
    {
      "x": -11,
      "y": 13,
      "z": -1,
      "name": "Rock_Stone"
    },
    {
      "x": -11,
      "y": 14,
      "z": -1,
      "name": "Soil_Grass"
    },
    {
      "x": -11,
      "y": 7,
      "z": 0,
      "name": "Plant_Vine_Wall",
      "support": 15,
      "rotation": 3
    },
    {
      "x": -11,
      "y": 8,
      "z": 0,
      "name": "Plant_Vine",
      "support": 15,
      "rotation": 3
    },
    {
      "x": -11,
      "y": 9,
      "z": 0,
      "name": "Rock_Stone"
    },
    {
      "x": -11,
      "y": 10,
      "z": 0,
      "name": "Rock_Stone"
    },
    {
      "x": -11,
      "y": 11,
      "z": 0,
      "name": "Rock_Stone"
    },
    {
      "x": -11,
      "y": 12,
      "z": 0,
      "name": "Rock_Stone"
    },
    {
      "x": -11,
      "y": 13,
      "z": 0,
      "name": "Rock_Stone"
    },
    {
      "x": -11,
      "y": 14,
      "z": 0,
      "name": "Soil_Grass"
    },
    {
      "x": -11,
      "y": 15,
      "z": 0,
      "name": "Plant_Grass_Sharp_Tall",
      "support": 15
    },
    {
      "x": -11,
      "y": 16,
      "z": 0,
      "name": "Plant_Grass_Sharp_Tall",
      "filler": 1024
    },
    {
      "x": -11,
      "y": 9,
      "z": 1,
      "name": "Rock_Stone"
    },
    {
      "x": -11,
      "y": 10,
      "z": 1,
      "name": "Rock_Stone"
    },
    {
      "x": -11,
      "y": 11,
      "z": 1,
      "name": "Rock_Stone"
    },
    {
      "x": -11,
      "y": 12,
      "z": 1,
      "name": "Rock_Stone"
    },
    {
      "x": -11,
      "y": 13,
      "z": 1,
      "name": "Rock_Stone"
    },
    {
      "x": -11,
      "y": 14,
      "z": 1,
      "name": "Soil_Grass"
    },
    {
      "x": -11,
      "y": 9,
      "z": 2,
      "name": "Rock_Stone"
    },
    {
      "x": -11,
      "y": 10,
      "z": 2,
      "name": "Rock_Stone"
    },
    {
      "x": -11,
      "y": 11,
      "z": 2,
      "name": "Rock_Stone"
    },
    {
      "x": -11,
      "y": 12,
      "z": 2,
      "name": "Rock_Stone"
    },
    {
      "x": -11,
      "y": 13,
      "z": 2,
      "name": "Rock_Stone"
    },
    {
      "x": -11,
      "y": 14,
      "z": 2,
      "name": "Soil_Grass"
    },
    {
      "x": -11,
      "y": 9,
      "z": 3,
      "name": "Rock_Stone_Mossy"
    },
    {
      "x": -11,
      "y": 10,
      "z": 3,
      "name": "Rock_Stone"
    },
    {
      "x": -11,
      "y": 11,
      "z": 3,
      "name": "Rock_Stone"
    },
    {
      "x": -11,
      "y": 12,
      "z": 3,
      "name": "Rock_Stone"
    },
    {
      "x": -11,
      "y": 13,
      "z": 3,
      "name": "Rock_Stone"
    },
    {
      "x": -11,
      "y": 14,
      "z": 3,
      "name": "Soil_Grass"
    },
    {
      "x": -11,
      "y": 15,
      "z": 3,
      "name": "Plant_Grass_Sharp_Short",
      "support": 15
    },
    {
      "x": -11,
      "y": 9,
      "z": 4,
      "name": "Rock_Stone_Mossy"
    },
    {
      "x": -11,
      "y": 10,
      "z": 4,
      "name": "Rock_Stone"
    },
    {
      "x": -11,
      "y": 11,
      "z": 4,
      "name": "Rock_Stone"
    },
    {
      "x": -11,
      "y": 12,
      "z": 4,
      "name": "Rock_Stone"
    },
    {
      "x": -11,
      "y": 13,
      "z": 4,
      "name": "Rock_Stone"
    },
    {
      "x": -11,
      "y": 14,
      "z": 4,
      "name": "Soil_Grass"
    },
    {
      "x": -11,
      "y": 9,
      "z": 5,
      "name": "Rock_Stone_Mossy"
    },
    {
      "x": -11,
      "y": 10,
      "z": 5,
      "name": "Rock_Stone_Mossy"
    },
    {
      "x": -11,
      "y": 11,
      "z": 5,
      "name": "Rock_Stone"
    },
    {
      "x": -11,
      "y": 12,
      "z": 5,
      "name": "Rock_Stone"
    },
    {
      "x": -11,
      "y": 13,
      "z": 5,
      "name": "Rock_Stone"
    },
    {
      "x": -11,
      "y": 14,
      "z": 5,
      "name": "Soil_Grass"
    },
    {
      "x": -11,
      "y": 9,
      "z": 6,
      "name": "Rock_Stone"
    },
    {
      "x": -11,
      "y": 10,
      "z": 6,
      "name": "Rock_Stone"
    },
    {
      "x": -11,
      "y": 11,
      "z": 6,
      "name": "Rock_Stone"
    },
    {
      "x": -11,
      "y": 12,
      "z": 6,
      "name": "Rock_Stone"
    },
    {
      "x": -11,
      "y": 13,
      "z": 6,
      "name": "Rock_Stone"
    },
    {
      "x": -11,
      "y": 14,
      "z": 6,
      "name": "Soil_Grass"
    },
    {
      "x": -11,
      "y": 15,
      "z": 6,
      "name": "Plant_Grass_Sharp",
      "support": 15
    },
    {
      "x": -11,
      "y": 9,
      "z": 7,
      "name": "Plant_Vine_Wall",
      "support": 15
    },
    {
      "x": -11,
      "y": 10,
      "z": 7,
      "name": "Plant_Vine",
      "support": 15
    },
    {
      "x": -11,
      "y": 11,
      "z": 7,
      "name": "Rock_Stone"
    },
    {
      "x": -11,
      "y": 12,
      "z": 7,
      "name": "Rock_Stone"
    },
    {
      "x": -11,
      "y": 13,
      "z": 7,
      "name": "Rock_Stone"
    },
    {
      "x": -11,
      "y": 14,
      "z": 7,
      "name": "Soil_Grass"
    },
    {
      "x": -11,
      "y": 11,
      "z": 8,
      "name": "Rock_Stone"
    },
    {
      "x": -11,
      "y": 12,
      "z": 8,
      "name": "Rock_Stone"
    },
    {
      "x": -11,
      "y": 13,
      "z": 8,
      "name": "Rock_Stone"
    },
    {
      "x": -11,
      "y": 14,
      "z": 8,
      "name": "Soil_Grass"
    },
    {
      "x": -11,
      "y": 15,
      "z": 8,
      "name": "Plant_Grass_Sharp_Short",
      "support": 15
    },
    {
      "x": -11,
      "y": 11,
      "z": 9,
      "name": "Rock_Stone"
    },
    {
      "x": -11,
      "y": 12,
      "z": 9,
      "name": "Rock_Stone"
    },
    {
      "x": -11,
      "y": 13,
      "z": 9,
      "name": "Rock_Stone"
    },
    {
      "x": -11,
      "y": 14,
      "z": 9,
      "name": "Soil_Grass"
    },
    {
      "x": -11,
      "y": 11,
      "z": 10,
      "name": "Plant_Vine_Wall",
      "support": 15,
      "rotation": 3
    },
    {
      "x": -11,
      "y": 12,
      "z": 10,
      "name": "Plant_Vine",
      "support": 15,
      "rotation": 3
    },
    {
      "x": -11,
      "y": 13,
      "z": 10,
      "name": "Rock_Stone"
    },
    {
      "x": -11,
      "y": 14,
      "z": 10,
      "name": "Rock_Stone"
    },
    {
      "x": -11,
      "y": 13,
      "z": 11,
      "name": "Rock_Stone"
    },
    {
      "x": -11,
      "y": 14,
      "z": 11,
      "name": "Rock_Stone"
    },
    {
      "x": -11,
      "y": 13,
      "z": 12,
      "name": "Plant_Vine_Wall",
      "support": 15,
      "rotation": 3
    },
    {
      "x": -11,
      "y": 14,
      "z": 12,
      "name": "Plant_Vine",
      "support": 15,
      "rotation": 3
    },
    {
      "x": -10,
      "y": 13,
      "z": -12,
      "name": "Rock_Stone"
    },
    {
      "x": -10,
      "y": 14,
      "z": -12,
      "name": "Rock_Stone"
    },
    {
      "x": -10,
      "y": 21,
      "z": -12,
      "name": "Plant_Leaves_Oak",
      "support": 1
    },
    {
      "x": -10,
      "y": 13,
      "z": -11,
      "name": "Rock_Stone"
    },
    {
      "x": -10,
      "y": 14,
      "z": -11,
      "name": "Rock_Stone"
    },
    {
      "x": -10,
      "y": 21,
      "z": -11,
      "name": "Plant_Leaves_Oak"
    },
    {
      "x": -10,
      "y": 22,
      "z": -11,
      "name": "Plant_Leaves_Oak",
      "support": 1
    },
    {
      "x": -10,
      "y": 24,
      "z": -11,
      "name": "Plant_Leaves_Oak",
      "support": 1
    },
    {
      "x": -10,
      "y": 25,
      "z": -11,
      "name": "Plant_Leaves_Oak",
      "support": 2
    },
    {
      "x": -10,
      "y": 11,
      "z": -10,
      "name": "Rock_Stone"
    },
    {
      "x": -10,
      "y": 12,
      "z": -10,
      "name": "Rock_Stone"
    },
    {
      "x": -10,
      "y": 13,
      "z": -10,
      "name": "Rock_Stone"
    },
    {
      "x": -10,
      "y": 14,
      "z": -10,
      "name": "Soil_Grass"
    },
    {
      "x": -10,
      "y": 19,
      "z": -10,
      "name": "Plant_Leaves_Oak",
      "support": 2
    },
    {
      "x": -10,
      "y": 21,
      "z": -10,
      "name": "Wood_Oak_Branch_Corner",
      "support": 2,
      "rotation": 3
    },
    {
      "x": -10,
      "y": 22,
      "z": -10,
      "name": "Plant_Leaves_Oak"
    },
    {
      "x": -10,
      "y": 24,
      "z": -10,
      "name": "Plant_Leaves_Oak"
    },
    {
      "x": -10,
      "y": 25,
      "z": -10,
      "name": "Plant_Leaves_Oak",
      "support": 1
    },
    {
      "x": -10,
      "y": 11,
      "z": -9,
      "name": "Rock_Stone"
    },
    {
      "x": -10,
      "y": 12,
      "z": -9,
      "name": "Rock_Stone"
    },
    {
      "x": -10,
      "y": 13,
      "z": -9,
      "name": "Rock_Stone"
    },
    {
      "x": -10,
      "y": 14,
      "z": -9,
      "name": "Soil_Grass"
    },
    {
      "x": -10,
      "y": 20,
      "z": -9,
      "name": "Plant_Leaves_Oak",
      "support": 1
    },
    {
      "x": -10,
      "y": 21,
      "z": -9,
      "name": "Plant_Leaves_Oak"
    },
    {
      "x": -10,
      "y": 24,
      "z": -9,
      "name": "Plant_Leaves_Oak",
      "support": 1
    },
    {
      "x": -10,
      "y": 11,
      "z": -8,
      "name": "Rock_Stone"
    },
    {
      "x": -10,
      "y": 12,
      "z": -8,
      "name": "Rock_Stone"
    },
    {
      "x": -10,
      "y": 13,
      "z": -8,
      "name": "Rock_Stone"
    },
    {
      "x": -10,
      "y": 14,
      "z": -8,
      "name": "Soil_Grass"
    },
    {
      "x": -10,
      "y": 22,
      "z": -8,
      "name": "Plant_Leaves_Oak",
      "support": 3
    },
    {
      "x": -10,
      "y": 23,
      "z": -8,
      "name": "Plant_Leaves_Oak",
      "support": 4
    },
    {
      "x": -10,
      "y": 7,
      "z": -7,
      "name": "Rock_Stone_Stalactite_Large",
      "filler": 31744,
      "rotation": 8
    },
    {
      "x": -10,
      "y": 8,
      "z": -7,
      "name": "Rock_Stone_Stalactite_Large",
      "rotation": 8
    },
    {
      "x": -10,
      "y": 9,
      "z": -7,
      "name": "Rock_Stone"
    },
    {
      "x": -10,
      "y": 10,
      "z": -7,
      "name": "Rock_Stone"
    },
    {
      "x": -10,
      "y": 11,
      "z": -7,
      "name": "Rock_Stone"
    },
    {
      "x": -10,
      "y": 12,
      "z": -7,
      "name": "Rock_Stone"
    },
    {
      "x": -10,
      "y": 13,
      "z": -7,
      "name": "Rock_Stone"
    },
    {
      "x": -10,
      "y": 14,
      "z": -7,
      "name": "Soil_Grass"
    },
    {
      "x": -10,
      "y": 15,
      "z": -7,
      "name": "Plant_Flower_Common_Pink"
    },
    {
      "x": -10,
      "y": 16,
      "z": -7,
      "name": "Plant_Flower_Common_Pink",
      "filler": 1024
    },
    {
      "x": -10,
      "y": 9,
      "z": -6,
      "name": "Rock_Stone_Mossy"
    },
    {
      "x": -10,
      "y": 10,
      "z": -6,
      "name": "Rock_Stone"
    },
    {
      "x": -10,
      "y": 11,
      "z": -6,
      "name": "Rock_Stone"
    },
    {
      "x": -10,
      "y": 12,
      "z": -6,
      "name": "Rock_Stone"
    },
    {
      "x": -10,
      "y": 13,
      "z": -6,
      "name": "Rock_Stone"
    },
    {
      "x": -10,
      "y": 14,
      "z": -6,
      "name": "Soil_Grass"
    },
    {
      "x": -10,
      "y": 9,
      "z": -5,
      "name": "Rock_Stone_Mossy"
    },
    {
      "x": -10,
      "y": 10,
      "z": -5,
      "name": "Rock_Stone"
    },
    {
      "x": -10,
      "y": 11,
      "z": -5,
      "name": "Rock_Stone"
    },
    {
      "x": -10,
      "y": 12,
      "z": -5,
      "name": "Rock_Stone"
    },
    {
      "x": -10,
      "y": 13,
      "z": -5,
      "name": "Rock_Stone"
    },
    {
      "x": -10,
      "y": 14,
      "z": -5,
      "name": "Soil_Grass"
    },
    {
      "x": -10,
      "y": 15,
      "z": -5,
      "name": "Plant_Grass_Sharp",
      "support": 15
    },
    {
      "x": -10,
      "y": 7,
      "z": -4,
      "name": "Plant_Vine_Wall",
      "support": 15,
      "rotation": 2
    },
    {
      "x": -10,
      "y": 8,
      "z": -4,
      "name": "Plant_Vine",
      "support": 15,
      "rotation": 2
    },
    {
      "x": -10,
      "y": 9,
      "z": -4,
      "name": "Rock_Stone"
    },
    {
      "x": -10,
      "y": 10,
      "z": -4,
      "name": "Rock_Stone"
    },
    {
      "x": -10,
      "y": 11,
      "z": -4,
      "name": "Rock_Stone"
    },
    {
      "x": -10,
      "y": 12,
      "z": -4,
      "name": "Rock_Stone"
    },
    {
      "x": -10,
      "y": 13,
      "z": -4,
      "name": "Rock_Stone"
    },
    {
      "x": -10,
      "y": 14,
      "z": -4,
      "name": "Soil_Grass"
    },
    {
      "x": -10,
      "y": 7,
      "z": -3,
      "name": "Rock_Stone"
    },
    {
      "x": -10,
      "y": 8,
      "z": -3,
      "name": "Rock_Stone"
    },
    {
      "x": -10,
      "y": 9,
      "z": -3,
      "name": "Rock_Stone"
    },
    {
      "x": -10,
      "y": 10,
      "z": -3,
      "name": "Rock_Stone"
    },
    {
      "x": -10,
      "y": 11,
      "z": -3,
      "name": "Rock_Stone"
    },
    {
      "x": -10,
      "y": 12,
      "z": -3,
      "name": "Rock_Stone"
    },
    {
      "x": -10,
      "y": 13,
      "z": -3,
      "name": "Rock_Stone"
    },
    {
      "x": -10,
      "y": 14,
      "z": -3,
      "name": "Soil_Grass"
    },
    {
      "x": -10,
      "y": 15,
      "z": -3,
      "name": "Plant_Grass_Sharp_Short",
      "support": 15
    },
    {
      "x": -10,
      "y": 7,
      "z": -2,
      "name": "Rock_Stone"
    },
    {
      "x": -10,
      "y": 8,
      "z": -2,
      "name": "Rock_Stone"
    },
    {
      "x": -10,
      "y": 9,
      "z": -2,
      "name": "Rock_Stone"
    },
    {
      "x": -10,
      "y": 10,
      "z": -2,
      "name": "Rock_Stone"
    },
    {
      "x": -10,
      "y": 11,
      "z": -2,
      "name": "Rock_Stone"
    },
    {
      "x": -10,
      "y": 12,
      "z": -2,
      "name": "Rock_Stone"
    },
    {
      "x": -10,
      "y": 13,
      "z": -2,
      "name": "Rock_Stone"
    },
    {
      "x": -10,
      "y": 14,
      "z": -2,
      "name": "Soil_Grass"
    },
    {
      "x": -10,
      "y": 7,
      "z": -1,
      "name": "Rock_Stone"
    },
    {
      "x": -10,
      "y": 8,
      "z": -1,
      "name": "Rock_Stone"
    },
    {
      "x": -10,
      "y": 9,
      "z": -1,
      "name": "Rock_Stone"
    },
    {
      "x": -10,
      "y": 10,
      "z": -1,
      "name": "Rock_Stone"
    },
    {
      "x": -10,
      "y": 11,
      "z": -1,
      "name": "Rock_Stone"
    },
    {
      "x": -10,
      "y": 12,
      "z": -1,
      "name": "Rock_Stone"
    },
    {
      "x": -10,
      "y": 13,
      "z": -1,
      "name": "Rock_Stone"
    },
    {
      "x": -10,
      "y": 14,
      "z": -1,
      "name": "Soil_Grass"
    },
    {
      "x": -10,
      "y": 7,
      "z": 0,
      "name": "Rock_Stone"
    },
    {
      "x": -10,
      "y": 8,
      "z": 0,
      "name": "Rock_Stone"
    },
    {
      "x": -10,
      "y": 9,
      "z": 0,
      "name": "Rock_Stone"
    },
    {
      "x": -10,
      "y": 10,
      "z": 0,
      "name": "Rock_Stone"
    },
    {
      "x": -10,
      "y": 11,
      "z": 0,
      "name": "Rock_Stone"
    },
    {
      "x": -10,
      "y": 12,
      "z": 0,
      "name": "Rock_Stone"
    },
    {
      "x": -10,
      "y": 13,
      "z": 0,
      "name": "Rock_Stone"
    },
    {
      "x": -10,
      "y": 14,
      "z": 0,
      "name": "Soil_Grass"
    },
    {
      "x": -10,
      "y": 7,
      "z": 1,
      "name": "Rock_Stone"
    },
    {
      "x": -10,
      "y": 8,
      "z": 1,
      "name": "Rock_Stone"
    },
    {
      "x": -10,
      "y": 9,
      "z": 1,
      "name": "Rock_Stone"
    },
    {
      "x": -10,
      "y": 10,
      "z": 1,
      "name": "Rock_Stone"
    },
    {
      "x": -10,
      "y": 11,
      "z": 1,
      "name": "Rock_Stone"
    },
    {
      "x": -10,
      "y": 12,
      "z": 1,
      "name": "Rock_Stone"
    },
    {
      "x": -10,
      "y": 13,
      "z": 1,
      "name": "Rock_Stone"
    },
    {
      "x": -10,
      "y": 14,
      "z": 1,
      "name": "Soil_Grass"
    },
    {
      "x": -10,
      "y": 7,
      "z": 2,
      "name": "Rock_Stone"
    },
    {
      "x": -10,
      "y": 8,
      "z": 2,
      "name": "Rock_Stone"
    },
    {
      "x": -10,
      "y": 9,
      "z": 2,
      "name": "Rock_Stone"
    },
    {
      "x": -10,
      "y": 10,
      "z": 2,
      "name": "Rock_Stone"
    },
    {
      "x": -10,
      "y": 11,
      "z": 2,
      "name": "Rock_Stone"
    },
    {
      "x": -10,
      "y": 12,
      "z": 2,
      "name": "Rock_Stone"
    },
    {
      "x": -10,
      "y": 13,
      "z": 2,
      "name": "Rock_Stone"
    },
    {
      "x": -10,
      "y": 14,
      "z": 2,
      "name": "Soil_Grass"
    },
    {
      "x": -10,
      "y": 7,
      "z": 3,
      "name": "Rock_Stone_Mossy"
    },
    {
      "x": -10,
      "y": 8,
      "z": 3,
      "name": "Rock_Stone_Mossy"
    },
    {
      "x": -10,
      "y": 9,
      "z": 3,
      "name": "Rock_Stone"
    },
    {
      "x": -10,
      "y": 10,
      "z": 3,
      "name": "Rock_Stone"
    },
    {
      "x": -10,
      "y": 11,
      "z": 3,
      "name": "Rock_Stone"
    },
    {
      "x": -10,
      "y": 12,
      "z": 3,
      "name": "Rock_Stone"
    },
    {
      "x": -10,
      "y": 13,
      "z": 3,
      "name": "Rock_Stone"
    },
    {
      "x": -10,
      "y": 14,
      "z": 3,
      "name": "Soil_Grass"
    },
    {
      "x": -10,
      "y": 15,
      "z": 3,
      "name": "Plant_Grass_Sharp",
      "support": 15
    },
    {
      "x": -10,
      "y": 8,
      "z": 4,
      "name": "Rock_Stone_Stalactite_Small",
      "rotation": 8
    },
    {
      "x": -10,
      "y": 9,
      "z": 4,
      "name": "Rock_Stone"
    },
    {
      "x": -10,
      "y": 10,
      "z": 4,
      "name": "Rock_Stone"
    },
    {
      "x": -10,
      "y": 11,
      "z": 4,
      "name": "Rock_Stone"
    },
    {
      "x": -10,
      "y": 12,
      "z": 4,
      "name": "Rock_Stone"
    },
    {
      "x": -10,
      "y": 13,
      "z": 4,
      "name": "Rock_Stone"
    },
    {
      "x": -10,
      "y": 14,
      "z": 4,
      "name": "Soil_Grass"
    },
    {
      "x": -10,
      "y": 8,
      "z": 5,
      "name": "Plant_Vine_Wall",
      "support": 15,
      "rotation": 3
    },
    {
      "x": -10,
      "y": 9,
      "z": 5,
      "name": "Rock_Stone"
    },
    {
      "x": -10,
      "y": 10,
      "z": 5,
      "name": "Rock_Stone"
    },
    {
      "x": -10,
      "y": 11,
      "z": 5,
      "name": "Rock_Stone"
    },
    {
      "x": -10,
      "y": 12,
      "z": 5,
      "name": "Rock_Stone"
    },
    {
      "x": -10,
      "y": 13,
      "z": 5,
      "name": "Rock_Stone"
    },
    {
      "x": -10,
      "y": 14,
      "z": 5,
      "name": "Soil_Grass"
    },
    {
      "x": -10,
      "y": 15,
      "z": 5,
      "name": "Plant_Grass_Sharp",
      "support": 15
    },
    {
      "x": -10,
      "y": 9,
      "z": 6,
      "name": "Rock_Stone"
    },
    {
      "x": -10,
      "y": 10,
      "z": 6,
      "name": "Rock_Stone"
    },
    {
      "x": -10,
      "y": 11,
      "z": 6,
      "name": "Rock_Stone"
    },
    {
      "x": -10,
      "y": 12,
      "z": 6,
      "name": "Rock_Stone"
    },
    {
      "x": -10,
      "y": 13,
      "z": 6,
      "name": "Rock_Stone"
    },
    {
      "x": -10,
      "y": 14,
      "z": 6,
      "name": "Soil_Grass"
    },
    {
      "x": -10,
      "y": 9,
      "z": 7,
      "name": "Rock_Stone"
    },
    {
      "x": -10,
      "y": 10,
      "z": 7,
      "name": "Rock_Stone"
    },
    {
      "x": -10,
      "y": 11,
      "z": 7,
      "name": "Rock_Stone"
    },
    {
      "x": -10,
      "y": 12,
      "z": 7,
      "name": "Rock_Stone"
    },
    {
      "x": -10,
      "y": 13,
      "z": 7,
      "name": "Rock_Stone"
    },
    {
      "x": -10,
      "y": 14,
      "z": 7,
      "name": "Soil_Grass"
    },
    {
      "x": -10,
      "y": 11,
      "z": 8,
      "name": "Rock_Stone"
    },
    {
      "x": -10,
      "y": 12,
      "z": 8,
      "name": "Rock_Stone"
    },
    {
      "x": -10,
      "y": 13,
      "z": 8,
      "name": "Rock_Stone"
    },
    {
      "x": -10,
      "y": 14,
      "z": 8,
      "name": "Soil_Grass"
    },
    {
      "x": -10,
      "y": 11,
      "z": 9,
      "name": "Rock_Stone"
    },
    {
      "x": -10,
      "y": 12,
      "z": 9,
      "name": "Rock_Stone"
    },
    {
      "x": -10,
      "y": 13,
      "z": 9,
      "name": "Rock_Stone"
    },
    {
      "x": -10,
      "y": 14,
      "z": 9,
      "name": "Soil_Grass"
    },
    {
      "x": -10,
      "y": 15,
      "z": 9,
      "name": "Plant_Grass_Sharp_Tall",
      "support": 15
    },
    {
      "x": -10,
      "y": 16,
      "z": 9,
      "name": "Plant_Grass_Sharp_Tall",
      "filler": 1024
    },
    {
      "x": -10,
      "y": 9,
      "z": 10,
      "name": "Rock_Stone_Stalactite_Large",
      "filler": 31744,
      "rotation": 8
    },
    {
      "x": -10,
      "y": 10,
      "z": 10,
      "name": "Rock_Stone_Stalactite_Large",
      "rotation": 8
    },
    {
      "x": -10,
      "y": 11,
      "z": 10,
      "name": "Rock_Stone"
    },
    {
      "x": -10,
      "y": 12,
      "z": 10,
      "name": "Rock_Stone"
    },
    {
      "x": -10,
      "y": 13,
      "z": 10,
      "name": "Rock_Stone"
    },
    {
      "x": -10,
      "y": 14,
      "z": 10,
      "name": "Soil_Grass"
    },
    {
      "x": -10,
      "y": 13,
      "z": 11,
      "name": "Rock_Stone"
    },
    {
      "x": -10,
      "y": 14,
      "z": 11,
      "name": "Rock_Stone"
    },
    {
      "x": -10,
      "y": 11,
      "z": 12,
      "name": "Rock_Stone_Stalactite_Large",
      "filler": 31744,
      "rotation": 8
    },
    {
      "x": -10,
      "y": 12,
      "z": 12,
      "name": "Rock_Stone_Stalactite_Large",
      "rotation": 8
    },
    {
      "x": -10,
      "y": 13,
      "z": 12,
      "name": "Rock_Stone"
    },
    {
      "x": -10,
      "y": 14,
      "z": 12,
      "name": "Rock_Stone"
    },
    {
      "x": -10,
      "y": 0,
      "z": 13,
      "name": "Empty"
    },
    {
      "x": -10,
      "y": 1,
      "z": 13,
      "name": "Empty"
    },
    {
      "x": -10,
      "y": 2,
      "z": 13,
      "name": "Empty"
    },
    {
      "x": -10,
      "y": 3,
      "z": 13,
      "name": "Empty"
    },
    {
      "x": -10,
      "y": 4,
      "z": 13,
      "name": "Empty"
    },
    {
      "x": -10,
      "y": 5,
      "z": 13,
      "name": "Empty"
    },
    {
      "x": -10,
      "y": 6,
      "z": 13,
      "name": "Empty"
    },
    {
      "x": -10,
      "y": 7,
      "z": 13,
      "name": "Empty"
    },
    {
      "x": -10,
      "y": 8,
      "z": 13,
      "name": "Empty"
    },
    {
      "x": -10,
      "y": 9,
      "z": 13,
      "name": "Empty"
    },
    {
      "x": -10,
      "y": 10,
      "z": 13,
      "name": "Empty"
    },
    {
      "x": -10,
      "y": 11,
      "z": 13,
      "name": "Empty"
    },
    {
      "x": -10,
      "y": 12,
      "z": 13,
      "name": "Empty"
    },
    {
      "x": -10,
      "y": 13,
      "z": 13,
      "name": "Empty"
    },
    {
      "x": -10,
      "y": 14,
      "z": 13,
      "name": "Empty"
    },
    {
      "x": -9,
      "y": 13,
      "z": -14,
      "name": "Plant_Vine_Wall",
      "support": 15,
      "rotation": 2
    },
    {
      "x": -9,
      "y": 14,
      "z": -14,
      "name": "Plant_Vine",
      "support": 15,
      "rotation": 2
    },
    {
      "x": -9,
      "y": 13,
      "z": -13,
      "name": "Rock_Stone"
    },
    {
      "x": -9,
      "y": 14,
      "z": -13,
      "name": "Rock_Stone"
    },
    {
      "x": -9,
      "y": 21,
      "z": -13,
      "name": "Plant_Leaves_Oak",
      "support": 2
    },
    {
      "x": -9,
      "y": 13,
      "z": -12,
      "name": "Rock_Stone"
    },
    {
      "x": -9,
      "y": 14,
      "z": -12,
      "name": "Rock_Stone"
    },
    {
      "x": -9,
      "y": 21,
      "z": -12,
      "name": "Plant_Leaves_Oak",
      "support": 1
    },
    {
      "x": -9,
      "y": 24,
      "z": -12,
      "name": "Plant_Leaves_Oak",
      "support": 1
    },
    {
      "x": -9,
      "y": 11,
      "z": -11,
      "name": "Rock_Stone"
    },
    {
      "x": -9,
      "y": 12,
      "z": -11,
      "name": "Rock_Stone"
    },
    {
      "x": -9,
      "y": 13,
      "z": -11,
      "name": "Rock_Stone"
    },
    {
      "x": -9,
      "y": 14,
      "z": -11,
      "name": "Soil_Grass"
    },
    {
      "x": -9,
      "y": 24,
      "z": -11,
      "name": "Plant_Leaves_Oak"
    },
    {
      "x": -9,
      "y": 11,
      "z": -10,
      "name": "Rock_Stone"
    },
    {
      "x": -9,
      "y": 12,
      "z": -10,
      "name": "Rock_Stone"
    },
    {
      "x": -9,
      "y": 13,
      "z": -10,
      "name": "Rock_Stone"
    },
    {
      "x": -9,
      "y": 14,
      "z": -10,
      "name": "Soil_Grass"
    },
    {
      "x": -9,
      "y": 19,
      "z": -10,
      "name": "Plant_Leaves_Oak",
      "support": 1
    },
    {
      "x": -9,
      "y": 20,
      "z": -10,
      "name": "Plant_Leaves_Oak"
    },
    {
      "x": -9,
      "y": 21,
      "z": -10,
      "name": "Wood_Oak_Branch_Long",
      "support": 1,
      "rotation": 5
    },
    {
      "x": -9,
      "y": 23,
      "z": -10,
      "name": "Plant_Leaves_Oak"
    },
    {
      "x": -9,
      "y": 24,
      "z": -10,
      "name": "Wood_Oak_Branch_Long",
      "support": 1,
      "rotation": 5
    },
    {
      "x": -9,
      "y": 25,
      "z": -10,
      "name": "Plant_Leaves_Oak"
    },
    {
      "x": -9,
      "y": 26,
      "z": -10,
      "name": "Plant_Leaves_Oak",
      "support": 1
    },
    {
      "x": -9,
      "y": 10,
      "z": -9,
      "name": "Plant_Vine_Wall",
      "support": 15,
      "rotation": 3
    },
    {
      "x": -9,
      "y": 11,
      "z": -9,
      "name": "Rock_Stone"
    },
    {
      "x": -9,
      "y": 12,
      "z": -9,
      "name": "Rock_Stone"
    },
    {
      "x": -9,
      "y": 13,
      "z": -9,
      "name": "Rock_Stone"
    },
    {
      "x": -9,
      "y": 14,
      "z": -9,
      "name": "Soil_Grass"
    },
    {
      "x": -9,
      "y": 15,
      "z": -9,
      "name": "Plant_Grass_Sharp_Short",
      "support": 15
    },
    {
      "x": -9,
      "y": 19,
      "z": -9,
      "name": "Plant_Leaves_Oak",
      "support": 2
    },
    {
      "x": -9,
      "y": 20,
      "z": -9,
      "name": "Plant_Leaves_Oak",
      "support": 1
    },
    {
      "x": -9,
      "y": 9,
      "z": -8,
      "name": "Rock_Stone"
    },
    {
      "x": -9,
      "y": 10,
      "z": -8,
      "name": "Rock_Stone"
    },
    {
      "x": -9,
      "y": 11,
      "z": -8,
      "name": "Rock_Stone"
    },
    {
      "x": -9,
      "y": 12,
      "z": -8,
      "name": "Rock_Stone"
    },
    {
      "x": -9,
      "y": 13,
      "z": -8,
      "name": "Rock_Stone"
    },
    {
      "x": -9,
      "y": 14,
      "z": -8,
      "name": "Soil_Grass"
    },
    {
      "x": -9,
      "y": 15,
      "z": -8,
      "name": "Plant_Grass_Sharp_Tall",
      "support": 15
    },
    {
      "x": -9,
      "y": 16,
      "z": -8,
      "name": "Plant_Grass_Sharp_Tall",
      "filler": 1024
    },
    {
      "x": -9,
      "y": 20,
      "z": -8,
      "name": "Plant_Leaves_Oak",
      "support": 2
    },
    {
      "x": -9,
      "y": 22,
      "z": -8,
      "name": "Plant_Leaves_Oak",
      "support": 2
    },
    {
      "x": -9,
      "y": 25,
      "z": -8,
      "name": "Plant_Leaves_Oak",
      "support": 1
    },
    {
      "x": -9,
      "y": 8,
      "z": -7,
      "name": "Plant_Vine_Wall",
      "support": 15,
      "rotation": 3
    },
    {
      "x": -9,
      "y": 9,
      "z": -7,
      "name": "Rock_Stone"
    },
    {
      "x": -9,
      "y": 10,
      "z": -7,
      "name": "Rock_Stone"
    },
    {
      "x": -9,
      "y": 11,
      "z": -7,
      "name": "Rock_Stone"
    },
    {
      "x": -9,
      "y": 12,
      "z": -7,
      "name": "Rock_Stone"
    },
    {
      "x": -9,
      "y": 13,
      "z": -7,
      "name": "Rock_Stone"
    },
    {
      "x": -9,
      "y": 14,
      "z": -7,
      "name": "Soil_Grass"
    },
    {
      "x": -9,
      "y": 15,
      "z": -7,
      "name": "Plant_Grass_Sharp_Short",
      "support": 15
    },
    {
      "x": -9,
      "y": 22,
      "z": -7,
      "name": "Plant_Leaves_Oak",
      "support": 1
    },
    {
      "x": -9,
      "y": 9,
      "z": -6,
      "name": "Rock_Stone_Mossy"
    },
    {
      "x": -9,
      "y": 10,
      "z": -6,
      "name": "Rock_Stone"
    },
    {
      "x": -9,
      "y": 11,
      "z": -6,
      "name": "Rock_Stone"
    },
    {
      "x": -9,
      "y": 12,
      "z": -6,
      "name": "Rock_Stone"
    },
    {
      "x": -9,
      "y": 13,
      "z": -6,
      "name": "Rock_Stone"
    },
    {
      "x": -9,
      "y": 14,
      "z": -6,
      "name": "Soil_Grass"
    },
    {
      "x": -9,
      "y": 7,
      "z": -5,
      "name": "Rock_Stone"
    },
    {
      "x": -9,
      "y": 8,
      "z": -5,
      "name": "Rock_Stone"
    },
    {
      "x": -9,
      "y": 9,
      "z": -5,
      "name": "Rock_Stone"
    },
    {
      "x": -9,
      "y": 10,
      "z": -5,
      "name": "Rock_Stone"
    },
    {
      "x": -9,
      "y": 11,
      "z": -5,
      "name": "Rock_Stone"
    },
    {
      "x": -9,
      "y": 12,
      "z": -5,
      "name": "Rock_Stone"
    },
    {
      "x": -9,
      "y": 13,
      "z": -5,
      "name": "Rock_Stone"
    },
    {
      "x": -9,
      "y": 14,
      "z": -5,
      "name": "Soil_Grass"
    },
    {
      "x": -9,
      "y": 7,
      "z": -4,
      "name": "Rock_Stone"
    },
    {
      "x": -9,
      "y": 8,
      "z": -4,
      "name": "Rock_Stone"
    },
    {
      "x": -9,
      "y": 9,
      "z": -4,
      "name": "Rock_Stone"
    },
    {
      "x": -9,
      "y": 10,
      "z": -4,
      "name": "Rock_Stone"
    },
    {
      "x": -9,
      "y": 11,
      "z": -4,
      "name": "Rock_Stone"
    },
    {
      "x": -9,
      "y": 12,
      "z": -4,
      "name": "Rock_Stone"
    },
    {
      "x": -9,
      "y": 13,
      "z": -4,
      "name": "Rock_Stone"
    },
    {
      "x": -9,
      "y": 14,
      "z": -4,
      "name": "Soil_Grass"
    },
    {
      "x": -9,
      "y": 7,
      "z": -3,
      "name": "Rock_Stone"
    },
    {
      "x": -9,
      "y": 8,
      "z": -3,
      "name": "Rock_Stone"
    },
    {
      "x": -9,
      "y": 9,
      "z": -3,
      "name": "Rock_Stone"
    },
    {
      "x": -9,
      "y": 10,
      "z": -3,
      "name": "Rock_Stone"
    },
    {
      "x": -9,
      "y": 11,
      "z": -3,
      "name": "Rock_Stone"
    },
    {
      "x": -9,
      "y": 12,
      "z": -3,
      "name": "Rock_Stone"
    },
    {
      "x": -9,
      "y": 13,
      "z": -3,
      "name": "Rock_Stone"
    },
    {
      "x": -9,
      "y": 14,
      "z": -3,
      "name": "Soil_Grass"
    },
    {
      "x": -9,
      "y": 15,
      "z": -3,
      "name": "Plant_Grass_Sharp_Tall",
      "support": 15
    },
    {
      "x": -9,
      "y": 16,
      "z": -3,
      "name": "Plant_Grass_Sharp_Tall",
      "filler": 1024
    },
    {
      "x": -9,
      "y": 6,
      "z": -2,
      "name": "Rock_Stone_Stalactite_Small",
      "rotation": 8
    },
    {
      "x": -9,
      "y": 7,
      "z": -2,
      "name": "Rock_Stone"
    },
    {
      "x": -9,
      "y": 8,
      "z": -2,
      "name": "Rock_Stone"
    },
    {
      "x": -9,
      "y": 9,
      "z": -2,
      "name": "Rock_Stone"
    },
    {
      "x": -9,
      "y": 10,
      "z": -2,
      "name": "Rock_Stone"
    },
    {
      "x": -9,
      "y": 11,
      "z": -2,
      "name": "Rock_Stone"
    },
    {
      "x": -9,
      "y": 12,
      "z": -2,
      "name": "Rock_Stone"
    },
    {
      "x": -9,
      "y": 13,
      "z": -2,
      "name": "Rock_Stone"
    },
    {
      "x": -9,
      "y": 14,
      "z": -2,
      "name": "Soil_Grass"
    },
    {
      "x": -9,
      "y": 7,
      "z": -1,
      "name": "Rock_Stone"
    },
    {
      "x": -9,
      "y": 8,
      "z": -1,
      "name": "Rock_Stone"
    },
    {
      "x": -9,
      "y": 9,
      "z": -1,
      "name": "Rock_Stone"
    },
    {
      "x": -9,
      "y": 10,
      "z": -1,
      "name": "Rock_Stone"
    },
    {
      "x": -9,
      "y": 11,
      "z": -1,
      "name": "Rock_Stone"
    },
    {
      "x": -9,
      "y": 12,
      "z": -1,
      "name": "Rock_Stone"
    },
    {
      "x": -9,
      "y": 13,
      "z": -1,
      "name": "Rock_Stone"
    },
    {
      "x": -9,
      "y": 14,
      "z": -1,
      "name": "Soil_Grass"
    },
    {
      "x": -9,
      "y": 15,
      "z": -1,
      "name": "Plant_Grass_Sharp",
      "support": 15
    },
    {
      "x": -9,
      "y": 7,
      "z": 0,
      "name": "Rock_Stone"
    },
    {
      "x": -9,
      "y": 8,
      "z": 0,
      "name": "Rock_Stone"
    },
    {
      "x": -9,
      "y": 9,
      "z": 0,
      "name": "Rock_Stone"
    },
    {
      "x": -9,
      "y": 10,
      "z": 0,
      "name": "Rock_Stone"
    },
    {
      "x": -9,
      "y": 11,
      "z": 0,
      "name": "Rock_Stone"
    },
    {
      "x": -9,
      "y": 12,
      "z": 0,
      "name": "Rock_Stone"
    },
    {
      "x": -9,
      "y": 13,
      "z": 0,
      "name": "Rock_Stone"
    },
    {
      "x": -9,
      "y": 14,
      "z": 0,
      "name": "Soil_Grass"
    },
    {
      "x": -9,
      "y": 7,
      "z": 1,
      "name": "Rock_Stone"
    },
    {
      "x": -9,
      "y": 8,
      "z": 1,
      "name": "Rock_Stone"
    },
    {
      "x": -9,
      "y": 9,
      "z": 1,
      "name": "Rock_Stone"
    },
    {
      "x": -9,
      "y": 10,
      "z": 1,
      "name": "Rock_Stone"
    },
    {
      "x": -9,
      "y": 11,
      "z": 1,
      "name": "Rock_Stone"
    },
    {
      "x": -9,
      "y": 12,
      "z": 1,
      "name": "Rock_Stone"
    },
    {
      "x": -9,
      "y": 13,
      "z": 1,
      "name": "Rock_Stone"
    },
    {
      "x": -9,
      "y": 14,
      "z": 1,
      "name": "Rock_Stone"
    },
    {
      "x": -9,
      "y": 15,
      "z": 1,
      "name": "Rubble_Stone",
      "support": 15
    },
    {
      "x": -9,
      "y": 5,
      "z": 2,
      "name": "Plant_Vine_Wall",
      "support": 15,
      "rotation": 3
    },
    {
      "x": -9,
      "y": 6,
      "z": 2,
      "name": "Plant_Vine",
      "support": 15,
      "rotation": 3
    },
    {
      "x": -9,
      "y": 7,
      "z": 2,
      "name": "Rock_Stone"
    },
    {
      "x": -9,
      "y": 8,
      "z": 2,
      "name": "Rock_Stone"
    },
    {
      "x": -9,
      "y": 9,
      "z": 2,
      "name": "Rock_Stone"
    },
    {
      "x": -9,
      "y": 10,
      "z": 2,
      "name": "Rock_Stone"
    },
    {
      "x": -9,
      "y": 11,
      "z": 2,
      "name": "Rock_Stone"
    },
    {
      "x": -9,
      "y": 12,
      "z": 2,
      "name": "Rock_Stone"
    },
    {
      "x": -9,
      "y": 13,
      "z": 2,
      "name": "Rock_Stone"
    },
    {
      "x": -9,
      "y": 14,
      "z": 2,
      "name": "Rock_Stone"
    },
    {
      "x": -9,
      "y": 5,
      "z": 3,
      "name": "Rock_Stone_Stalactite_Large",
      "filler": 31744,
      "rotation": 8
    },
    {
      "x": -9,
      "y": 6,
      "z": 3,
      "name": "Rock_Stone_Stalactite_Large",
      "rotation": 8
    },
    {
      "x": -9,
      "y": 7,
      "z": 3,
      "name": "Rock_Stone"
    },
    {
      "x": -9,
      "y": 8,
      "z": 3,
      "name": "Rock_Stone"
    },
    {
      "x": -9,
      "y": 9,
      "z": 3,
      "name": "Rock_Stone"
    },
    {
      "x": -9,
      "y": 10,
      "z": 3,
      "name": "Rock_Stone"
    },
    {
      "x": -9,
      "y": 11,
      "z": 3,
      "name": "Rock_Stone"
    },
    {
      "x": -9,
      "y": 12,
      "z": 3,
      "name": "Rock_Stone"
    },
    {
      "x": -9,
      "y": 13,
      "z": 3,
      "name": "Rock_Stone"
    },
    {
      "x": -9,
      "y": 14,
      "z": 3,
      "name": "Rock_Stone"
    },
    {
      "x": -9,
      "y": 30,
      "z": 3,
      "name": "Rock_Crystal_Cyan_Small",
      "rotation": 7
    },
    {
      "x": -9,
      "y": 7,
      "z": 4,
      "name": "Rock_Stone_Mossy"
    },
    {
      "x": -9,
      "y": 8,
      "z": 4,
      "name": "Rock_Stone"
    },
    {
      "x": -9,
      "y": 9,
      "z": 4,
      "name": "Rock_Stone"
    },
    {
      "x": -9,
      "y": 10,
      "z": 4,
      "name": "Rock_Stone"
    },
    {
      "x": -9,
      "y": 11,
      "z": 4,
      "name": "Rock_Stone"
    },
    {
      "x": -9,
      "y": 12,
      "z": 4,
      "name": "Rock_Stone"
    },
    {
      "x": -9,
      "y": 13,
      "z": 4,
      "name": "Rock_Stone"
    },
    {
      "x": -9,
      "y": 14,
      "z": 4,
      "name": "Soil_Grass"
    },
    {
      "x": -9,
      "y": 15,
      "z": 4,
      "name": "Plant_Reeds_Marsh",
      "support": 15
    },
    {
      "x": -9,
      "y": 7,
      "z": 5,
      "name": "Rock_Stone"
    },
    {
      "x": -9,
      "y": 8,
      "z": 5,
      "name": "Rock_Stone"
    },
    {
      "x": -9,
      "y": 9,
      "z": 5,
      "name": "Rock_Stone"
    },
    {
      "x": -9,
      "y": 10,
      "z": 5,
      "name": "Rock_Stone"
    },
    {
      "x": -9,
      "y": 11,
      "z": 5,
      "name": "Rock_Stone"
    },
    {
      "x": -9,
      "y": 12,
      "z": 5,
      "name": "Rock_Stone"
    },
    {
      "x": -9,
      "y": 13,
      "z": 5,
      "name": "Rock_Stone"
    },
    {
      "x": -9,
      "y": 14,
      "z": 5,
      "name": "Soil_Grass"
    },
    {
      "x": -9,
      "y": 7,
      "z": 6,
      "name": "Plant_Vine_Wall",
      "support": 15
    },
    {
      "x": -9,
      "y": 8,
      "z": 6,
      "name": "Plant_Vine",
      "support": 15
    },
    {
      "x": -9,
      "y": 9,
      "z": 6,
      "name": "Rock_Stone"
    },
    {
      "x": -9,
      "y": 10,
      "z": 6,
      "name": "Rock_Stone"
    },
    {
      "x": -9,
      "y": 11,
      "z": 6,
      "name": "Rock_Stone"
    },
    {
      "x": -9,
      "y": 12,
      "z": 6,
      "name": "Rock_Stone"
    },
    {
      "x": -9,
      "y": 13,
      "z": 6,
      "name": "Rock_Stone"
    },
    {
      "x": -9,
      "y": 14,
      "z": 6,
      "name": "Soil_Grass"
    },
    {
      "x": -9,
      "y": 15,
      "z": 6,
      "name": "Plant_Grass_Sharp",
      "support": 15
    },
    {
      "x": -9,
      "y": 7,
      "z": 7,
      "name": "Rock_Stone_Stalactite_Large",
      "filler": 31744,
      "rotation": 8
    },
    {
      "x": -9,
      "y": 8,
      "z": 7,
      "name": "Rock_Stone_Stalactite_Large",
      "rotation": 8
    },
    {
      "x": -9,
      "y": 9,
      "z": 7,
      "name": "Rock_Stone"
    },
    {
      "x": -9,
      "y": 10,
      "z": 7,
      "name": "Rock_Stone"
    },
    {
      "x": -9,
      "y": 11,
      "z": 7,
      "name": "Rock_Stone"
    },
    {
      "x": -9,
      "y": 12,
      "z": 7,
      "name": "Rock_Stone"
    },
    {
      "x": -9,
      "y": 13,
      "z": 7,
      "name": "Rock_Stone"
    },
    {
      "x": -9,
      "y": 14,
      "z": 7,
      "name": "Soil_Grass"
    },
    {
      "x": -9,
      "y": 15,
      "z": 7,
      "name": "Plant_Grass_Sharp_Tall",
      "support": 15
    },
    {
      "x": -9,
      "y": 16,
      "z": 7,
      "name": "Plant_Grass_Sharp_Tall",
      "filler": 1024
    },
    {
      "x": -9,
      "y": 9,
      "z": 8,
      "name": "Rock_Stone"
    },
    {
      "x": -9,
      "y": 10,
      "z": 8,
      "name": "Rock_Stone"
    },
    {
      "x": -9,
      "y": 11,
      "z": 8,
      "name": "Rock_Stone"
    },
    {
      "x": -9,
      "y": 12,
      "z": 8,
      "name": "Rock_Stone"
    },
    {
      "x": -9,
      "y": 13,
      "z": 8,
      "name": "Rock_Stone"
    },
    {
      "x": -9,
      "y": 14,
      "z": 8,
      "name": "Soil_Grass"
    },
    {
      "x": -9,
      "y": 11,
      "z": 9,
      "name": "Rock_Stone"
    },
    {
      "x": -9,
      "y": 12,
      "z": 9,
      "name": "Rock_Stone"
    },
    {
      "x": -9,
      "y": 13,
      "z": 9,
      "name": "Rock_Stone"
    },
    {
      "x": -9,
      "y": 14,
      "z": 9,
      "name": "Soil_Grass"
    },
    {
      "x": -9,
      "y": 15,
      "z": 9,
      "name": "Plant_Grass_Sharp",
      "support": 15
    },
    {
      "x": -9,
      "y": 11,
      "z": 10,
      "name": "Rock_Stone"
    },
    {
      "x": -9,
      "y": 12,
      "z": 10,
      "name": "Rock_Stone"
    },
    {
      "x": -9,
      "y": 13,
      "z": 10,
      "name": "Rock_Stone"
    },
    {
      "x": -9,
      "y": 14,
      "z": 10,
      "name": "Soil_Grass"
    },
    {
      "x": -9,
      "y": 15,
      "z": 10,
      "name": "Plant_Reeds_Marsh",
      "support": 15
    },
    {
      "x": -9,
      "y": 11,
      "z": 11,
      "name": "Rock_Stone"
    },
    {
      "x": -9,
      "y": 12,
      "z": 11,
      "name": "Rock_Stone"
    },
    {
      "x": -9,
      "y": 13,
      "z": 11,
      "name": "Rock_Stone"
    },
    {
      "x": -9,
      "y": 14,
      "z": 11,
      "name": "Rock_Stone"
    },
    {
      "x": -9,
      "y": 11,
      "z": 12,
      "name": "Plant_Vine_Wall",
      "support": 15
    },
    {
      "x": -9,
      "y": 12,
      "z": 12,
      "name": "Plant_Vine",
      "support": 15
    },
    {
      "x": -9,
      "y": 13,
      "z": 12,
      "name": "Rock_Stone"
    },
    {
      "x": -9,
      "y": 14,
      "z": 12,
      "name": "Rock_Stone_Mossy"
    },
    {
      "x": -9,
      "y": 15,
      "z": 12,
      "name": "Rubble_Stone_Mossy",
      "support": 15
    },
    {
      "x": -9,
      "y": 13,
      "z": 13,
      "name": "Rock_Stone"
    },
    {
      "x": -9,
      "y": 14,
      "z": 13,
      "name": "Empty"
    },
    {
      "x": -9,
      "y": 0,
      "z": 14,
      "name": "Empty"
    },
    {
      "x": -9,
      "y": 1,
      "z": 14,
      "name": "Empty"
    },
    {
      "x": -9,
      "y": 2,
      "z": 14,
      "name": "Empty"
    },
    {
      "x": -9,
      "y": 3,
      "z": 14,
      "name": "Empty"
    },
    {
      "x": -9,
      "y": 4,
      "z": 14,
      "name": "Empty"
    },
    {
      "x": -9,
      "y": 5,
      "z": 14,
      "name": "Empty"
    },
    {
      "x": -9,
      "y": 6,
      "z": 14,
      "name": "Empty"
    },
    {
      "x": -9,
      "y": 7,
      "z": 14,
      "name": "Empty"
    },
    {
      "x": -9,
      "y": 8,
      "z": 14,
      "name": "Empty"
    },
    {
      "x": -9,
      "y": 9,
      "z": 14,
      "name": "Empty"
    },
    {
      "x": -9,
      "y": 10,
      "z": 14,
      "name": "Empty"
    },
    {
      "x": -9,
      "y": 11,
      "z": 14,
      "name": "Empty"
    },
    {
      "x": -9,
      "y": 12,
      "z": 14,
      "name": "Empty"
    },
    {
      "x": -9,
      "y": 13,
      "z": 14,
      "name": "Empty"
    },
    {
      "x": -9,
      "y": 14,
      "z": 14,
      "name": "Empty"
    },
    {
      "x": -8,
      "y": 11,
      "z": -14,
      "name": "Rock_Stone_Stalactite_Large",
      "filler": 31744,
      "rotation": 8
    },
    {
      "x": -8,
      "y": 12,
      "z": -14,
      "name": "Rock_Stone_Stalactite_Large",
      "rotation": 8
    },
    {
      "x": -8,
      "y": 13,
      "z": -14,
      "name": "Rock_Stone"
    },
    {
      "x": -8,
      "y": 14,
      "z": -14,
      "name": "Rock_Stone"
    },
    {
      "x": -8,
      "y": 24,
      "z": -14,
      "name": "Plant_Leaves_Oak",
      "support": 2
    },
    {
      "x": -8,
      "y": 13,
      "z": -13,
      "name": "Rock_Stone"
    },
    {
      "x": -8,
      "y": 14,
      "z": -13,
      "name": "Rock_Stone"
    },
    {
      "x": -8,
      "y": 22,
      "z": -13,
      "name": "Plant_Leaves_Oak",
      "support": 1
    },
    {
      "x": -8,
      "y": 23,
      "z": -13,
      "name": "Plant_Leaves_Oak"
    },
    {
      "x": -8,
      "y": 24,
      "z": -13,
      "name": "Plant_Leaves_Oak",
      "support": 1
    },
    {
      "x": -8,
      "y": 11,
      "z": -12,
      "name": "Plant_Vine_Wall",
      "support": 15,
      "rotation": 3
    },
    {
      "x": -8,
      "y": 12,
      "z": -12,
      "name": "Plant_Vine",
      "support": 15,
      "rotation": 3
    },
    {
      "x": -8,
      "y": 13,
      "z": -12,
      "name": "Rock_Stone"
    },
    {
      "x": -8,
      "y": 14,
      "z": -12,
      "name": "Soil_Grass"
    },
    {
      "x": -8,
      "y": 21,
      "z": -12,
      "name": "Plant_Leaves_Oak"
    },
    {
      "x": -8,
      "y": 22,
      "z": -12,
      "name": "Plant_Leaves_Oak",
      "support": 1
    },
    {
      "x": -8,
      "y": 10,
      "z": -11,
      "name": "Rock_Stone_Stalactite_Small",
      "rotation": 8
    },
    {
      "x": -8,
      "y": 11,
      "z": -11,
      "name": "Rock_Stone"
    },
    {
      "x": -8,
      "y": 12,
      "z": -11,
      "name": "Rock_Stone"
    },
    {
      "x": -8,
      "y": 13,
      "z": -11,
      "name": "Rock_Stone"
    },
    {
      "x": -8,
      "y": 14,
      "z": -11,
      "name": "Soil_Grass"
    },
    {
      "x": -8,
      "y": 15,
      "z": -11,
      "name": "Plant_Grass_Sharp_Short",
      "support": 15
    },
    {
      "x": -8,
      "y": 26,
      "z": -11,
      "name": "Plant_Leaves_Oak",
      "support": 1
    },
    {
      "x": -8,
      "y": 9,
      "z": -10,
      "name": "Plant_Vine_Wall",
      "support": 15,
      "rotation": 2
    },
    {
      "x": -8,
      "y": 10,
      "z": -10,
      "name": "Plant_Vine",
      "support": 15,
      "rotation": 2
    },
    {
      "x": -8,
      "y": 11,
      "z": -10,
      "name": "Rock_Stone"
    },
    {
      "x": -8,
      "y": 12,
      "z": -10,
      "name": "Rock_Stone"
    },
    {
      "x": -8,
      "y": 13,
      "z": -10,
      "name": "Rock_Stone"
    },
    {
      "x": -8,
      "y": 14,
      "z": -10,
      "name": "Soil_Grass"
    },
    {
      "x": -8,
      "y": 18,
      "z": -10,
      "name": "Wood_Oak_Branch_Corner",
      "rotation": 3
    },
    {
      "x": -8,
      "y": 19,
      "z": -10,
      "name": "Plant_Leaves_Oak"
    },
    {
      "x": -8,
      "y": 20,
      "z": -10,
      "name": "Plant_Leaves_Oak"
    },
    {
      "x": -8,
      "y": 21,
      "z": -10,
      "name": "Wood_Oak_Branch_Long",
      "rotation": 5
    },
    {
      "x": -8,
      "y": 24,
      "z": -10,
      "name": "Wood_Oak_Branch_Long",
      "rotation": 5
    },
    {
      "x": -8,
      "y": 26,
      "z": -10,
      "name": "Plant_Leaves_Oak"
    },
    {
      "x": -8,
      "y": 9,
      "z": -9,
      "name": "Rock_Stone"
    },
    {
      "x": -8,
      "y": 10,
      "z": -9,
      "name": "Rock_Stone"
    },
    {
      "x": -8,
      "y": 11,
      "z": -9,
      "name": "Rock_Stone"
    },
    {
      "x": -8,
      "y": 12,
      "z": -9,
      "name": "Rock_Stone"
    },
    {
      "x": -8,
      "y": 13,
      "z": -9,
      "name": "Rock_Stone"
    },
    {
      "x": -8,
      "y": 14,
      "z": -9,
      "name": "Soil_Grass"
    },
    {
      "x": -8,
      "y": 19,
      "z": -9,
      "name": "Plant_Leaves_Oak",
      "support": 1
    },
    {
      "x": -8,
      "y": 9,
      "z": -8,
      "name": "Rock_Stone"
    },
    {
      "x": -8,
      "y": 10,
      "z": -8,
      "name": "Rock_Stone"
    },
    {
      "x": -8,
      "y": 11,
      "z": -8,
      "name": "Rock_Stone"
    },
    {
      "x": -8,
      "y": 12,
      "z": -8,
      "name": "Rock_Stone"
    },
    {
      "x": -8,
      "y": 13,
      "z": -8,
      "name": "Rock_Stone"
    },
    {
      "x": -8,
      "y": 14,
      "z": -8,
      "name": "Soil_Grass"
    },
    {
      "x": -8,
      "y": 24,
      "z": -8,
      "name": "Plant_Leaves_Oak",
      "support": 1
    },
    {
      "x": -8,
      "y": 25,
      "z": -8,
      "name": "Plant_Leaves_Oak"
    },
    {
      "x": -8,
      "y": 26,
      "z": -8,
      "name": "Plant_Leaves_Oak",
      "support": 1
    },
    {
      "x": -8,
      "y": 7,
      "z": -7,
      "name": "Rock_Stone"
    },
    {
      "x": -8,
      "y": 8,
      "z": -7,
      "name": "Rock_Stone"
    },
    {
      "x": -8,
      "y": 9,
      "z": -7,
      "name": "Rock_Stone"
    },
    {
      "x": -8,
      "y": 10,
      "z": -7,
      "name": "Rock_Stone"
    },
    {
      "x": -8,
      "y": 11,
      "z": -7,
      "name": "Rock_Stone"
    },
    {
      "x": -8,
      "y": 12,
      "z": -7,
      "name": "Rock_Stone"
    },
    {
      "x": -8,
      "y": 13,
      "z": -7,
      "name": "Rock_Stone"
    },
    {
      "x": -8,
      "y": 14,
      "z": -7,
      "name": "Soil_Grass"
    },
    {
      "x": -8,
      "y": 21,
      "z": -7,
      "name": "Plant_Leaves_Oak",
      "support": 1
    },
    {
      "x": -8,
      "y": 22,
      "z": -7,
      "name": "Plant_Leaves_Oak"
    },
    {
      "x": -8,
      "y": 7,
      "z": -6,
      "name": "Rock_Stone_Mossy"
    },
    {
      "x": -8,
      "y": 8,
      "z": -6,
      "name": "Rock_Stone_Mossy"
    },
    {
      "x": -8,
      "y": 9,
      "z": -6,
      "name": "Rock_Stone"
    },
    {
      "x": -8,
      "y": 10,
      "z": -6,
      "name": "Rock_Stone"
    },
    {
      "x": -8,
      "y": 11,
      "z": -6,
      "name": "Rock_Stone"
    },
    {
      "x": -8,
      "y": 12,
      "z": -6,
      "name": "Rock_Stone"
    },
    {
      "x": -8,
      "y": 13,
      "z": -6,
      "name": "Rock_Stone"
    },
    {
      "x": -8,
      "y": 14,
      "z": -6,
      "name": "Soil_Grass"
    },
    {
      "x": -8,
      "y": 22,
      "z": -6,
      "name": "Plant_Leaves_Oak",
      "support": 1
    },
    {
      "x": -8,
      "y": 7,
      "z": -5,
      "name": "Rock_Stone_Mossy"
    },
    {
      "x": -8,
      "y": 8,
      "z": -5,
      "name": "Rock_Stone"
    },
    {
      "x": -8,
      "y": 9,
      "z": -5,
      "name": "Rock_Stone"
    },
    {
      "x": -8,
      "y": 10,
      "z": -5,
      "name": "Rock_Stone"
    },
    {
      "x": -8,
      "y": 11,
      "z": -5,
      "name": "Rock_Stone"
    },
    {
      "x": -8,
      "y": 12,
      "z": -5,
      "name": "Rock_Stone"
    },
    {
      "x": -8,
      "y": 13,
      "z": -5,
      "name": "Rock_Stone"
    },
    {
      "x": -8,
      "y": 14,
      "z": -5,
      "name": "Soil_Grass"
    },
    {
      "x": -8,
      "y": 15,
      "z": -5,
      "name": "Plant_Grass_Sharp",
      "support": 15
    },
    {
      "x": -8,
      "y": 6,
      "z": -4,
      "name": "Plant_Vine_Wall",
      "support": 15,
      "rotation": 3
    },
    {
      "x": -8,
      "y": 7,
      "z": -4,
      "name": "Rock_Stone"
    },
    {
      "x": -8,
      "y": 8,
      "z": -4,
      "name": "Rock_Stone"
    },
    {
      "x": -8,
      "y": 9,
      "z": -4,
      "name": "Rock_Stone"
    },
    {
      "x": -8,
      "y": 10,
      "z": -4,
      "name": "Rock_Stone"
    },
    {
      "x": -8,
      "y": 11,
      "z": -4,
      "name": "Rock_Stone"
    },
    {
      "x": -8,
      "y": 12,
      "z": -4,
      "name": "Rock_Stone"
    },
    {
      "x": -8,
      "y": 13,
      "z": -4,
      "name": "Rock_Stone"
    },
    {
      "x": -8,
      "y": 14,
      "z": -4,
      "name": "Soil_Grass"
    },
    {
      "x": -8,
      "y": 3,
      "z": -3,
      "name": "Rock_Stone_Stalactite_Large",
      "filler": 31744,
      "rotation": 8
    },
    {
      "x": -8,
      "y": 4,
      "z": -3,
      "name": "Rock_Stone_Stalactite_Large",
      "rotation": 8
    },
    {
      "x": -8,
      "y": 5,
      "z": -3,
      "name": "Rock_Stone"
    },
    {
      "x": -8,
      "y": 6,
      "z": -3,
      "name": "Rock_Stone"
    },
    {
      "x": -8,
      "y": 7,
      "z": -3,
      "name": "Rock_Stone"
    },
    {
      "x": -8,
      "y": 8,
      "z": -3,
      "name": "Rock_Stone"
    },
    {
      "x": -8,
      "y": 9,
      "z": -3,
      "name": "Rock_Stone"
    },
    {
      "x": -8,
      "y": 10,
      "z": -3,
      "name": "Rock_Stone"
    },
    {
      "x": -8,
      "y": 11,
      "z": -3,
      "name": "Rock_Stone"
    },
    {
      "x": -8,
      "y": 12,
      "z": -3,
      "name": "Rock_Stone"
    },
    {
      "x": -8,
      "y": 13,
      "z": -3,
      "name": "Rock_Stone"
    },
    {
      "x": -8,
      "y": 14,
      "z": -3,
      "name": "Soil_Grass"
    },
    {
      "x": -8,
      "y": 5,
      "z": -2,
      "name": "Rock_Stone"
    },
    {
      "x": -8,
      "y": 6,
      "z": -2,
      "name": "Rock_Stone"
    },
    {
      "x": -8,
      "y": 7,
      "z": -2,
      "name": "Rock_Stone"
    },
    {
      "x": -8,
      "y": 8,
      "z": -2,
      "name": "Rock_Stone"
    },
    {
      "x": -8,
      "y": 9,
      "z": -2,
      "name": "Rock_Stone"
    },
    {
      "x": -8,
      "y": 10,
      "z": -2,
      "name": "Rock_Stone"
    },
    {
      "x": -8,
      "y": 11,
      "z": -2,
      "name": "Rock_Stone"
    },
    {
      "x": -8,
      "y": 12,
      "z": -2,
      "name": "Rock_Stone"
    },
    {
      "x": -8,
      "y": 13,
      "z": -2,
      "name": "Rock_Stone"
    },
    {
      "x": -8,
      "y": 14,
      "z": -2,
      "name": "Soil_Grass"
    },
    {
      "x": -8,
      "y": 15,
      "z": -2,
      "name": "Plant_Grass_Sharp_Short",
      "support": 15
    },
    {
      "x": -8,
      "y": 5,
      "z": -1,
      "name": "Rock_Stone"
    },
    {
      "x": -8,
      "y": 6,
      "z": -1,
      "name": "Rock_Stone"
    },
    {
      "x": -8,
      "y": 7,
      "z": -1,
      "name": "Rock_Stone"
    },
    {
      "x": -8,
      "y": 8,
      "z": -1,
      "name": "Rock_Stone"
    },
    {
      "x": -8,
      "y": 9,
      "z": -1,
      "name": "Rock_Stone"
    },
    {
      "x": -8,
      "y": 10,
      "z": -1,
      "name": "Rock_Stone"
    },
    {
      "x": -8,
      "y": 11,
      "z": -1,
      "name": "Rock_Stone"
    },
    {
      "x": -8,
      "y": 12,
      "z": -1,
      "name": "Rock_Stone"
    },
    {
      "x": -8,
      "y": 13,
      "z": -1,
      "name": "Rock_Stone"
    },
    {
      "x": -8,
      "y": 14,
      "z": -1,
      "name": "Soil_Grass"
    },
    {
      "x": -8,
      "y": 15,
      "z": -1,
      "name": "Plant_Grass_Sharp",
      "support": 15
    },
    {
      "x": -8,
      "y": 5,
      "z": 0,
      "name": "Rock_Stone"
    },
    {
      "x": -8,
      "y": 6,
      "z": 0,
      "name": "Rock_Stone"
    },
    {
      "x": -8,
      "y": 7,
      "z": 0,
      "name": "Rock_Stone"
    },
    {
      "x": -8,
      "y": 8,
      "z": 0,
      "name": "Rock_Stone"
    },
    {
      "x": -8,
      "y": 9,
      "z": 0,
      "name": "Rock_Stone"
    },
    {
      "x": -8,
      "y": 10,
      "z": 0,
      "name": "Rock_Stone"
    },
    {
      "x": -8,
      "y": 11,
      "z": 0,
      "name": "Rock_Stone"
    },
    {
      "x": -8,
      "y": 12,
      "z": 0,
      "name": "Rock_Stone"
    },
    {
      "x": -8,
      "y": 13,
      "z": 0,
      "name": "Rock_Stone"
    },
    {
      "x": -8,
      "y": 14,
      "z": 0,
      "name": "Soil_Grass"
    },
    {
      "x": -8,
      "y": 4,
      "z": 1,
      "name": "Rock_Stone_Stalactite_Small",
      "rotation": 8
    },
    {
      "x": -8,
      "y": 5,
      "z": 1,
      "name": "Rock_Stone"
    },
    {
      "x": -8,
      "y": 6,
      "z": 1,
      "name": "Rock_Stone"
    },
    {
      "x": -8,
      "y": 7,
      "z": 1,
      "name": "Rock_Stone"
    },
    {
      "x": -8,
      "y": 8,
      "z": 1,
      "name": "Rock_Stone"
    },
    {
      "x": -8,
      "y": 9,
      "z": 1,
      "name": "Rock_Stone"
    },
    {
      "x": -8,
      "y": 10,
      "z": 1,
      "name": "Rock_Stone"
    },
    {
      "x": -8,
      "y": 11,
      "z": 1,
      "name": "Rock_Stone"
    },
    {
      "x": -8,
      "y": 12,
      "z": 1,
      "name": "Rock_Stone"
    },
    {
      "x": -8,
      "y": 13,
      "z": 1,
      "name": "Rock_Stone"
    },
    {
      "x": -8,
      "y": 14,
      "z": 1,
      "name": "Rock_Stone"
    },
    {
      "x": -8,
      "y": 31,
      "z": 1,
      "name": "Rock_Crystal_Cyan_Small",
      "rotation": 6
    },
    {
      "x": -8,
      "y": 5,
      "z": 2,
      "name": "Rock_Stone"
    },
    {
      "x": -8,
      "y": 6,
      "z": 2,
      "name": "Rock_Stone"
    },
    {
      "x": -8,
      "y": 7,
      "z": 2,
      "name": "Rock_Stone"
    },
    {
      "x": -8,
      "y": 8,
      "z": 2,
      "name": "Rock_Stone"
    },
    {
      "x": -8,
      "y": 9,
      "z": 2,
      "name": "Rock_Stone"
    },
    {
      "x": -8,
      "y": 10,
      "z": 2,
      "name": "Rock_Stone"
    },
    {
      "x": -8,
      "y": 11,
      "z": 2,
      "name": "Rock_Stone"
    },
    {
      "x": -8,
      "y": 12,
      "z": 2,
      "name": "Rock_Stone"
    },
    {
      "x": -8,
      "y": 13,
      "z": 2,
      "name": "Rock_Crystal_Cyan_Small"
    },
    {
      "x": -8,
      "y": 14,
      "z": 2,
      "name": "Empty"
    },
    {
      "x": -8,
      "y": 30,
      "z": 2,
      "name": "Rock_Stone"
    },
    {
      "x": -8,
      "y": 31,
      "z": 2,
      "name": "Rock_Stone_Mossy"
    },
    {
      "x": -8,
      "y": 32,
      "z": 2,
      "name": "Rubble_Stone_Mossy",
      "support": 15
    },
    {
      "x": -8,
      "y": 5,
      "z": 3,
      "name": "Rock_Stone_Mossy"
    },
    {
      "x": -8,
      "y": 6,
      "z": 3,
      "name": "Rock_Stone"
    },
    {
      "x": -8,
      "y": 7,
      "z": 3,
      "name": "Rock_Stone"
    },
    {
      "x": -8,
      "y": 8,
      "z": 3,
      "name": "Rock_Stone"
    },
    {
      "x": -8,
      "y": 9,
      "z": 3,
      "name": "Rock_Stone"
    },
    {
      "x": -8,
      "y": 10,
      "z": 3,
      "name": "Rock_Stone"
    },
    {
      "x": -8,
      "y": 11,
      "z": 3,
      "name": "Rock_Stone"
    },
    {
      "x": -8,
      "y": 12,
      "z": 3,
      "name": "Rock_Stone"
    },
    {
      "x": -8,
      "y": 13,
      "z": 3,
      "name": "Empty"
    },
    {
      "x": -8,
      "y": 14,
      "z": 3,
      "name": "Empty"
    },
    {
      "x": -8,
      "y": 30,
      "z": 3,
      "name": "Rock_Stone"
    },
    {
      "x": -8,
      "y": 31,
      "z": 3,
      "name": "Rock_Stone"
    },
    {
      "x": -8,
      "y": 7,
      "z": 4,
      "name": "Rock_Stone_Mossy"
    },
    {
      "x": -8,
      "y": 8,
      "z": 4,
      "name": "Rock_Stone"
    },
    {
      "x": -8,
      "y": 9,
      "z": 4,
      "name": "Rock_Stone"
    },
    {
      "x": -8,
      "y": 10,
      "z": 4,
      "name": "Rock_Stone"
    },
    {
      "x": -8,
      "y": 11,
      "z": 4,
      "name": "Rock_Stone"
    },
    {
      "x": -8,
      "y": 12,
      "z": 4,
      "name": "Rock_Stone"
    },
    {
      "x": -8,
      "y": 13,
      "z": 4,
      "name": "Rock_Stone"
    },
    {
      "x": -8,
      "y": 14,
      "z": 4,
      "name": "Rock_Stone"
    },
    {
      "x": -8,
      "y": 7,
      "z": 5,
      "name": "Rock_Stone"
    },
    {
      "x": -8,
      "y": 8,
      "z": 5,
      "name": "Rock_Stone"
    },
    {
      "x": -8,
      "y": 9,
      "z": 5,
      "name": "Rock_Stone"
    },
    {
      "x": -8,
      "y": 10,
      "z": 5,
      "name": "Rock_Stone"
    },
    {
      "x": -8,
      "y": 11,
      "z": 5,
      "name": "Rock_Stone"
    },
    {
      "x": -8,
      "y": 12,
      "z": 5,
      "name": "Rock_Stone"
    },
    {
      "x": -8,
      "y": 13,
      "z": 5,
      "name": "Rock_Stone"
    },
    {
      "x": -8,
      "y": 14,
      "z": 5,
      "name": "Soil_Grass"
    },
    {
      "x": -8,
      "y": 7,
      "z": 6,
      "name": "Rock_Stone"
    },
    {
      "x": -8,
      "y": 8,
      "z": 6,
      "name": "Rock_Stone"
    },
    {
      "x": -8,
      "y": 9,
      "z": 6,
      "name": "Rock_Stone"
    },
    {
      "x": -8,
      "y": 10,
      "z": 6,
      "name": "Rock_Stone"
    },
    {
      "x": -8,
      "y": 11,
      "z": 6,
      "name": "Rock_Stone"
    },
    {
      "x": -8,
      "y": 12,
      "z": 6,
      "name": "Rock_Stone"
    },
    {
      "x": -8,
      "y": 13,
      "z": 6,
      "name": "Rock_Stone"
    },
    {
      "x": -8,
      "y": 14,
      "z": 6,
      "name": "Soil_Grass"
    },
    {
      "x": -8,
      "y": 15,
      "z": 6,
      "name": "Plant_Grass_Sharp_Short",
      "support": 15
    },
    {
      "x": -8,
      "y": 7,
      "z": 7,
      "name": "Rock_Stone"
    },
    {
      "x": -8,
      "y": 8,
      "z": 7,
      "name": "Rock_Stone"
    },
    {
      "x": -8,
      "y": 9,
      "z": 7,
      "name": "Rock_Stone"
    },
    {
      "x": -8,
      "y": 10,
      "z": 7,
      "name": "Rock_Stone"
    },
    {
      "x": -8,
      "y": 11,
      "z": 7,
      "name": "Rock_Stone"
    },
    {
      "x": -8,
      "y": 12,
      "z": 7,
      "name": "Rock_Stone"
    },
    {
      "x": -8,
      "y": 13,
      "z": 7,
      "name": "Rock_Stone"
    },
    {
      "x": -8,
      "y": 14,
      "z": 7,
      "name": "Soil_Grass"
    },
    {
      "x": -8,
      "y": 9,
      "z": 8,
      "name": "Rock_Stone"
    },
    {
      "x": -8,
      "y": 10,
      "z": 8,
      "name": "Rock_Stone"
    },
    {
      "x": -8,
      "y": 11,
      "z": 8,
      "name": "Rock_Stone"
    },
    {
      "x": -8,
      "y": 12,
      "z": 8,
      "name": "Rock_Stone"
    },
    {
      "x": -8,
      "y": 13,
      "z": 8,
      "name": "Rock_Stone"
    },
    {
      "x": -8,
      "y": 14,
      "z": 8,
      "name": "Soil_Grass"
    },
    {
      "x": -8,
      "y": 15,
      "z": 8,
      "name": "Plant_Grass_Sharp",
      "support": 15
    },
    {
      "x": -8,
      "y": 9,
      "z": 9,
      "name": "Rock_Stone"
    },
    {
      "x": -8,
      "y": 10,
      "z": 9,
      "name": "Rock_Stone"
    },
    {
      "x": -8,
      "y": 11,
      "z": 9,
      "name": "Rock_Stone"
    },
    {
      "x": -8,
      "y": 12,
      "z": 9,
      "name": "Rock_Stone"
    },
    {
      "x": -8,
      "y": 13,
      "z": 9,
      "name": "Rock_Stone"
    },
    {
      "x": -8,
      "y": 14,
      "z": 9,
      "name": "Soil_Grass"
    },
    {
      "x": -8,
      "y": 10,
      "z": 10,
      "name": "Plant_Vine_Wall",
      "support": 15,
      "rotation": 3
    },
    {
      "x": -8,
      "y": 11,
      "z": 10,
      "name": "Rock_Stone"
    },
    {
      "x": -8,
      "y": 12,
      "z": 10,
      "name": "Rock_Stone"
    },
    {
      "x": -8,
      "y": 13,
      "z": 10,
      "name": "Rock_Stone"
    },
    {
      "x": -8,
      "y": 14,
      "z": 10,
      "name": "Rock_Stone_Mossy"
    },
    {
      "x": -8,
      "y": 11,
      "z": 11,
      "name": "Rock_Stone"
    },
    {
      "x": -8,
      "y": 12,
      "z": 11,
      "name": "Rock_Stone"
    },
    {
      "x": -8,
      "y": 13,
      "z": 11,
      "name": "Rock_Stone"
    },
    {
      "x": -8,
      "y": 14,
      "z": 11,
      "name": "Rock_Stone_Mossy"
    },
    {
      "x": -8,
      "y": 13,
      "z": 12,
      "name": "Rock_Stone"
    },
    {
      "x": -8,
      "y": 14,
      "z": 12,
      "name": "Empty"
    },
    {
      "x": -8,
      "y": 13,
      "z": 13,
      "name": "Rock_Stone"
    },
    {
      "x": -8,
      "y": 14,
      "z": 13,
      "name": "Rubble_Stone",
      "support": 15
    },
    {
      "x": -8,
      "y": 12,
      "z": 14,
      "name": "Rock_Stone_Stalactite_Small",
      "rotation": 8
    },
    {
      "x": -8,
      "y": 13,
      "z": 14,
      "name": "Rock_Stone"
    },
    {
      "x": -8,
      "y": 14,
      "z": 14,
      "name": "Empty"
    },
    {
      "x": -8,
      "y": 0,
      "z": 15,
      "name": "Empty"
    },
    {
      "x": -8,
      "y": 1,
      "z": 15,
      "name": "Empty"
    },
    {
      "x": -8,
      "y": 2,
      "z": 15,
      "name": "Empty"
    },
    {
      "x": -8,
      "y": 3,
      "z": 15,
      "name": "Empty"
    },
    {
      "x": -8,
      "y": 4,
      "z": 15,
      "name": "Empty"
    },
    {
      "x": -8,
      "y": 5,
      "z": 15,
      "name": "Empty"
    },
    {
      "x": -8,
      "y": 6,
      "z": 15,
      "name": "Empty"
    },
    {
      "x": -8,
      "y": 7,
      "z": 15,
      "name": "Empty"
    },
    {
      "x": -8,
      "y": 8,
      "z": 15,
      "name": "Empty"
    },
    {
      "x": -8,
      "y": 9,
      "z": 15,
      "name": "Empty"
    },
    {
      "x": -8,
      "y": 10,
      "z": 15,
      "name": "Empty"
    },
    {
      "x": -8,
      "y": 11,
      "z": 15,
      "name": "Empty"
    },
    {
      "x": -8,
      "y": 12,
      "z": 15,
      "name": "Empty"
    },
    {
      "x": -8,
      "y": 13,
      "z": 15,
      "name": "Empty"
    },
    {
      "x": -8,
      "y": 14,
      "z": 15,
      "name": "Empty"
    },
    {
      "x": -7,
      "y": 13,
      "z": -15,
      "name": "Plant_Vine_Wall",
      "support": 15,
      "rotation": 3
    },
    {
      "x": -7,
      "y": 14,
      "z": -15,
      "name": "Plant_Vine",
      "support": 15,
      "rotation": 3
    },
    {
      "x": -7,
      "y": 13,
      "z": -14,
      "name": "Rock_Stone"
    },
    {
      "x": -7,
      "y": 14,
